Workbook

Sheet INGEI
A1: Uso inicial | B1: Uso final | C1: 2010 | D1: 2011 | E1: 2012 | F1: 2013 | G1: 2014 | H1: 2015 | I1: 2016 | J1: 2017 | K1: 2018 | L1: 2019 | M1: 2020 | N1: 2021 | O1: 2022 | P1: 2023 | Q1: 2024 | R1: 2025 | S1: 2026 | T1: 2027 | U1: 2028 | V1: 2029 | W1: 2030 | X1: 2031 | Y1: 2032 | Z1: 2033 | AA1: 2034 | AB1: 2035
A2: Tierras Forestales | B2: Tierras Forestales | C2: -19217574 | D2: =+(C2+E2)/2 -> -20027829 | E2: -20838084 | F2: =+(E2+G2)/2 -> -22648214 | G2: -24458345 | H2: =+(G2+I2)/2 -> -22793711 | I2: -21129078 | J2: =+(I2+K2)/2 -> -22396710 | K2: -23664342 | L2: -24349408 | M2: -23879007 | N2: -21069337 | O2: -18652838
A3: Tierra de Cultivo | B3: Tierras Forestales | C3: -260988.34 | D3: =+(C3+E3)/2 -> -260988.34 | E3: -260988.34 | F3: =+(E3+G3)/2 -> -260988.34 | G3: -260988.34 | H3: =+(G3+I3)/2 -> -184466.62 | I3: -107944.91 | J3: =+(I3+K3)/2 -> -142695.7 | K3: -177446.49 | L3: -39273.68 | M3: -39273.68 | N3: -47774.42 | O3: -47774.42
A4: Pastizales | B4: Tierras Forestales | C4: -37381.303 | D4: =+(C4+E4)/2 -> -37381.303 | E4: -37381.303 | F4: =+(E4+G4)/2 -> -37381.303 | G4: -37381.303 | H4: =+(G4+I4)/2 -> -50955.234 | I4: -64529.165 | J4: =+(I4+K4)/2 -> -77357.533 | K4: -90185.901 | L4: -4884.119 | M4: -4884.119 | N4: -1165.9996 | O4: -1165.9996
A5: Humedales | B5: Tierras Forestales | C5: -763.30476 | D5: =+(C5+E5)/2 -> -763.30476 | E5: -763.30476 | F5: =+(E5+G5)/2 -> -763.30476 | G5: -763.30476 | H5: =+(G5+I5)/2 -> -807.24636 | I5: -851.18795 | J5: =+(I5+K5)/2 -> -610.33436 | K5: -369.48076 | L5: -412.39087 | M5: -412.39087 | N5: -250.65278 | O5: -250.65278
A6: Asentamientos | B6: Tierras Forestales | C6: 0 | D6: =+(C6+E6)/2 -> 0 | E6: 0 | F6: =+(E6+G6)/2 -> 0 | G6: 0 | H6: =+(G6+I6)/2 -> 0 | I6: 0 | J6: =+(I6+K6)/2 -> -1820.4818 | K6: -3640.9637 | L6: -1102.8722 | M6: -1102.8722 | N6: 0 | O6: 0
A7: Otras Tierras | B7: Tierras Forestales | C7: -165.03887 | D7: =+(C7+E7)/2 -> -165.03887 | E7: -165.03887 | F7: =+(E7+G7)/2 -> -165.03887 | G7: -165.03887 | H7: =+(G7+I7)/2 -> -321.61949 | I7: -478.20012 | J7: =+(I7+K7)/2 -> -2141.7919 | K7: -3805.3837 | L7: -152.24835 | M7: -152.24835 | N7: -788.16566 | O7: -788.16566
A8: Tierras de Cultivo | B8: Tierras de Cultivo | C8: 0 | D8: =+(C8+E8)/2 -> 0 | E8: 0 | F8: =+(E8+G8)/2 -> 0 | G8: 0 | H8: =+(G8+I8)/2 -> 0 | I8: 0 | J8: =+(I8+K8)/2 -> 0 | K8: 0 | L8: 0 | M8: 0 | N8: 0 | O8: 0
A9: Tierras Forestales | B9: Tierras de Cultivo | C9: 37427636 | D9: =+(C9+E9)/2 -> 37427636 | E9: 37427636 | F9: =+(E9+G9)/2 -> 37427636 | G9: 37427636 | H9: =+(G9+I9)/2 -> 38419762 | I9: 39411887 | J9: =+(I9+K9)/2 -> 36724892 | K9: 34037898 | L9: 33489304 | M9: 33489304 | N9: 37228401 | O9: 37228401
A10: Pastizales | B10: Tierras de Cultivo | C10: -64379.014 | D10: =+(C10+E10)/2 -> -64379.014 | E10: -64379.014 | F10: =+(E10+G10)/2 -> -64379.014 | G10: -64379.014 | H10: =+(G10+I10)/2 -> -102872.37 | I10: -141365.72 | J10: =+(I10+K10)/2 -> -90297.332 | K10: -39228.948 | L10: -85642.682 | M10: -85642.682 | N10: -61290.346 | O10: -61290.346
A11: Humedales | B11: Tierras de Cultivo | C11: -79317.238 | D11: =+(C11+E11)/2 -> -79317.238 | E11: -79317.238 | F11: =+(E11+G11)/2 -> -79317.238 | G11: -79317.238 | H11: =+(G11+I11)/2 -> -88356.983 | I11: -97396.728 | J11: =+(I11+K11)/2 -> -80781.796 | K11: -64166.865 | L11: -7582.6227 | M11: -7582.6227 | N11: -24433.695 | O11: -24433.695
A12: Asentamientos | B12: Tierras de Cultivo | C12: 0 | D12: =+(C12+E12)/2 -> 0 | E12: 0 | F12: =+(E12+G12)/2 -> 0 | G12: 0 | H12: =+(G12+I12)/2 -> 0 | I12: 0 | J12: =+(I12+K12)/2 -> 0 | K12: 0 | L12: 0 | M12: 0 | N12: -2501.07 | O12: -2501.07
A13: Otras Tierras | B13: Tierras de Cultivo | C13: -12207.624 | D13: =+(C13+E13)/2 -> -12207.624 | E13: -12207.624 | F13: =+(E13+G13)/2 -> -12207.624 | G13: -12207.624 | H13: =+(G13+I13)/2 -> -50096.26 | I13: -87984.897 | J13: =+(I13+K13)/2 -> -51382.641 | K13: -14780.385 | L13: -5803.1307 | M13: -5803.1307 | N13: -32062.173 | O13: -32062.173
A14: Pastizales | B14: Pastizales | C14: NE | D14: NE | E14: NE | F14: NE | G14: NE | H14: NE | I14: NE | J14: NE | K14: NE | L14: NE | M14: NE | N14: NE | O14: NE
A15: Tierras Forestales | B15: Pastizales | C15: 1034352.7 | D15: =+(C15+E15)/2 -> 1034352.7 | E15: 1034352.7 | F15: =+(E15+G15)/2 -> 1034352.7 | G15: 1034352.7 | H15: =+(G15+I15)/2 -> 551831.98 | I15: 69311.211 | J15: =+(I15+K15)/2 -> 1692292.3 | K15: 3315273.3 | L15: 1577555.2 | M15: 1577555.2 | N15: 466865.19 | O15: 466865.19
A16: Tierras de Cultivo | B16: Pastizales | C16: -14.666667 | D16: =+(C16+E16)/2 -> -14.666667 | E16: -14.666667 | F16: =+(E16+G16)/2 -> -14.666667 | G16: -14.666667 | H16: =+(G16+I16)/2 -> -14.666667 | I16: -14.666667 | J16: =+(I16+K16)/2 -> -14.666667 | K16: -14.666667 | L16: -14.666667 | M16: -14.666667 | N16: -14.666667 | O16: -14.666667
A17: Humedales | B17: Pastizales | C17: -14.666667 | D17: =+(C17+E17)/2 -> -14.666667 | E17: -14.666667 | F17: =+(E17+G17)/2 -> -14.666667 | G17: -14.666667 | H17: =+(G17+I17)/2 -> -14.666667 | I17: -14.666667 | J17: =+(I17+K17)/2 -> -14.666667 | K17: -14.666667 | L17: -14.666667 | M17: -14.666667 | N17: -14.666667 | O17: -14.666667
A18: Asentamientos | B18: Pastizales | C18: 0 | D18: =+(C18+E18)/2 -> 0 | E18: 0 | F18: =+(E18+G18)/2 -> 0 | G18: 0 | H18: =+(G18+I18)/2 -> 0 | I18: 0 | J18: =+(I18+K18)/2 -> 0 | K18: 0 | L18: 0 | M18: 0 | N18: 0 | O18: 0
A19: Otras Tierras | B19: Pastizales | C19: -14.666667 | D19: =+(C19+E19)/2 -> -14.666667 | E19: -14.666667 | F19: =+(E19+G19)/2 -> -14.666667 | G19: -14.666667 | H19: =+(G19+I19)/2 -> -14.666667 | I19: -14.666667 | J19: =+(I19+K19)/2 -> -14.666667 | K19: -14.666667 | L19: -14.666667 | M19: -14.666667 | N19: -14.666667 | O19: -14.666667
A20: Humedales | B20: Humedales | C20: NE | D20: NE | E20: NE | F20: NE | G20: NE | H20: NE | I20: NE | J20: NE | K20: NE | L20: NE | M20: NE | N20: NE | O20: NE
A21: Tierras Forestales | B21: Humedales | C21: 257830.16 | D21: =+(C21+E21)/2 -> 257830.16 | E21: 257830.16 | F21: =+(E21+G21)/2 -> 257830.16 | G21: 257830.16 | H21: =+(G21+I21)/2 -> 317097.99 | I21: 376365.83 | J21: =+(I21+K21)/2 -> 359780.13 | K21: 343194.43 | L21: 2678956.2 | M21: 2678956.2 | N21: 3822773.4 | O21: 3822773.4
A22: Tierras de Cultivo | B22: Humedales | C22: 280075.86 | D22: =+(C22+E22)/2 -> 280075.86 | E22: 280075.86 | F22: =+(E22+G22)/2 -> 280075.86 | G22: 280075.86 | H22: =+(G22+I22)/2 -> 276337.79 | I22: 272599.73 | J22: =+(I22+K22)/2 -> 287145.21 | K22: 301690.7 | L22: 256322.55 | M22: 256322.55 | N22: 54708.061 | O22: 54708.061
A23: Pastizales | B23: Humedales | C23: 2896.9578 | D23: =+(C23+E23)/2 -> 2896.9578 | E23: 2896.9578 | F23: =+(E23+G23)/2 -> 2896.9578 | G23: 2896.9578 | H23: =+(G23+I23)/2 -> 4512.8068 | I23: 6128.6559 | J23: =+(I23+K23)/2 -> 3655.8793 | K23: 1183.1028 | L23: 7290.3204 | M23: 7290.3204 | N23: 947.69547 | O23: 947.69547
A24: Asentamientos | B24: Humedales | C24: 0 | D24: =+(C24+E24)/2 -> 0 | E24: 0 | F24: =+(E24+G24)/2 -> 0 | G24: 0 | H24: =+(G24+I24)/2 -> 0 | I24: 0 | J24: =+(I24+K24)/2 -> 0 | K24: 0 | L24: 0 | M24: 0 | N24: 0 | O24: 0
A25: Otras Tierras | B25: Humedales | C25: 0 | D25: =+(C25+E25)/2 -> 0 | E25: 0 | F25: =+(E25+G25)/2 -> 0 | G25: 0 | H25: =+(G25+I25)/2 -> 0 | I25: 0 | J25: =+(I25+K25)/2 -> 0 | K25: 0 | L25: 0 | M25: 0 | N25: 0 | O25: 0
A26: Asentamientos | B26: Asentamientos | C26: NE | D26: NE | E26: NE | F26: NE | G26: NE | H26: NE | I26: NE | J26: NE | K26: NE | L26: NE | M26: NE | N26: NE | O26: NE
A27: Tierras Forestales | B27: Asentamientos | C27: 163507.27 | D27: =+(C27+E27)/2 -> 163507.27 | E27: 163507.27 | F27: =+(E27+G27)/2 -> 163507.27 | G27: 163507.27 | H27: =+(G27+I27)/2 -> 153956.31 | I27: 144405.35 | J27: =+(I27+K27)/2 -> 202538.19 | K27: 260671.02 | L27: 973099.72 | M27: 973099.72 | N27: 710135.94 | O27: 710135.94
A28: Tierras de Cultivo | B28: Asentamientos | C28: 350768.68 | D28: =+(C28+E28)/2 -> 350768.68 | E28: 350768.68 | F28: =+(E28+G28)/2 -> 350768.68 | G28: 350768.68 | H28: =+(G28+I28)/2 -> 217366.73 | I28: 83964.781 | J28: =+(I28+K28)/2 -> 299275.2 | K28: 514585.61 | L28: 114868.15 | M28: 114868.15 | N28: 434189.52 | O28: 434189.52
A29: Pastizales | B29: Asentamientos | C29: 4236.7116 | D29: =+(C29+E29)/2 -> 4236.7116 | E29: 4236.7116 | F29: =+(E29+G29)/2 -> 4236.7116 | G29: 4236.7116 | H29: =+(G29+I29)/2 -> 3321.7939 | I29: 2406.8763 | J29: =+(I29+K29)/2 -> 2170.1937 | K29: 1933.5111 | L29: 1592.2911 | M29: 1592.2911 | N29: 13344.184 | O29: 13344.184
A30: Humedales | B30: Asentamientos | C30: 0 | D30: =+(C30+E30)/2 -> 0 | E30: 0 | F30: =+(E30+G30)/2 -> 0 | G30: 0 | H30: =+(G30+I30)/2 -> 0 | I30: 0 | J30: =+(I30+K30)/2 -> 0 | K30: 0 | L30: 0 | M30: 0 | N30: 0 | O30: 0
A31: Otras Tierras | B31: Asentamientos | C31: 0 | D31: =+(C31+E31)/2 -> 0 | E31: 0 | F31: =+(E31+G31)/2 -> 0 | G31: 0 | H31: =+(G31+I31)/2 -> 0 | I31: 0 | J31: =+(I31+K31)/2 -> 0 | K31: 0 | L31: 0 | M31: 0 | N31: 0 | O31: 0
A32: Otras Tierras | B32: Otras Tierras | C32: NA | D32: NA | E32: NA | F32: NA | G32: NA | H32: NA | I32: NA | J32: NA | K32: NA | L32: NA | M32: NA | N32: NA | O32: NA
A33: Tierras Forestales | B33: Otras Tierras | C33: 236927.22 | D33: =+(C33+E33)/2 -> 236927.22 | E33: 236927.22 | F33: =+(E33+G33)/2 -> 236927.22 | G33: 236927.22 | H33: =+(G33+I33)/2 -> 549772.32 | I33: 862617.41 | J33: =+(I33+K33)/2 -> 843084.1 | K33: 823550.78 | L33: 706285.94 | M33: 706285.94 | N33: 286005.97 | O33: 286005.97
A34: tierras de Cultivo | B34: Otras Tierras | C34: 122388.25 | D34: =+(C34+E34)/2 -> 122388.25 | E34: 122388.25 | F34: =+(E34+G34)/2 -> 122388.25 | G34: 122388.25 | H34: =+(G34+I34)/2 -> 99837.172 | I34: 77286.097 | J34: =+(I34+K34)/2 -> 134836.07 | K34: 192386.04 | L34: 7108.8017 | M34: 7108.8017 | N34: 84797.151 | O34: 84797.151
A35: Pastizales | B35: Otras Tierras | C35: 7995.2327 | D35: =+(C35+E35)/2 -> 7995.2327 | E35: 7995.2327 | F35: =+(E35+G35)/2 -> 7995.2327 | G35: 7995.2327 | H35: =+(G35+I35)/2 -> 12347.27 | I35: 16699.307 | J35: =+(I35+K35)/2 -> 11708.361 | K35: 6717.4155 | L35: 3198.7824 | M35: 3198.7824 | N35: 3210.2943 | O35: 3210.2943
A36: humedales | B36: Otras Tierras | C36: 0 | D36: =+(C36+E36)/2 -> 0 | E36: 0 | F36: =+(E36+G36)/2 -> 0 | G36: 0 | H36: =+(G36+I36)/2 -> 0 | I36: 0 | J36: =+(I36+K36)/2 -> 0 | K36: 0 | L36: 0 | M36: 0 | N36: 0 | O36: 0
A37: Asentamientos | B37: Otras Tierras | C37: 0 | D37: =+(C37+E37)/2 -> 0 | E37: 0 | F37: =+(E37+G37)/2 -> 0 | G37: 0 | H37: =+(G37+I37)/2 -> 0 | I37: 0 | J37: =+(I37+K37)/2 -> 0 | K37: 0 | L37: 0 | M37: 0 | N37: 0 | O37: 0
A38: Total (ton CO2e) | C38: =+SUM(C2:C37) -> 20215795 | D38: =+SUM(D2:D37) -> 19405541 | E38: =+SUM(E2:E37) -> 18595286 | F38: =+SUM(F2:F37) -> 16785155 | G38: =+SUM(G2:G37) -> 14975025 | H38: =+SUM(H2:H37) -> 17334512 | I38: =+SUM(I2:I37) -> 19693999 | J38: =+SUM(J2:J37) -> 17717536 | ... O38: =+SUM(O2:O37) -> 24282230 | P38: 22678.28 | Q38: 22302.116 | R38: 21807.316 | S38: 21358.544 | T38: 21046.288 | U38: 20606.864 | V38: 20099.052 | W38: 19743.605 | X38: 19451.863 | Y38: 18973.818 | Z38: 18651.84 | AA38: 18208.766 | AB38: 17847.33

Sheet INGEI_diffs
A1: Uso inicial | B1: Uso final | C1: 2010 | D1: 2011 | E1: 2012 | F1: 2013 | G1: 2014 | H1: 2015 | I1: 2016 | J1: 2017 | K1: 2018 | L1: 2019 | M1: 2020 | N1: 2021 | O1: 2022
A2: Tierras Forestales | B2: Tierras Forestales | C2: =+INGEI!C2 -> -19217574 | D2: =+INGEI!D2 -> -20027829 | E2: =+INGEI!E2 -> -20838084 | F2: =+INGEI!F2 -> -22648214 | G2: =+INGEI!G2 -> -24458345 | H2: =+INGEI!H2 -> -22793711 | I2: =+INGEI!I2 -> -21129078 | J2: =+INGEI!J2 -> -22396710 | ... O2: =+INGEI!O2 -> -18652838
C3: =+C2/1000000 -> -19.217574 | D3: =+D2/1000000 -> -20.027829 | E3: =+E2/1000000 -> -20.838084 | F3: =+F2/1000000 -> -22.648214 | G3: =+G2/1000000 -> -24.458345 | H3: =+H2/1000000 -> -22.793711 | I3: =+I2/1000000 -> -21.129078 | J3: =+J2/1000000 -> -22.39671 | ... O3: =+O2/1000000 -> -18.652838
A4: Tierra de Cultivo | B4: Tierras Forestales | C4: =+INGEI!C3 -> -260988.34 | D4: =+INGEI!D3 -> -260988.34 | E4: =+INGEI!E3 -> -260988.34 | F4: =+INGEI!F3 -> -260988.34 | G4: =+INGEI!G3 -> -260988.34 | H4: =+INGEI!H3 -> -184466.62 | I4: =+INGEI!I3 -> -107944.91 | J4: =+INGEI!J3 -> -142695.7 | ... O4: =+INGEI!O3 -> -47774.42
A5: Pastizales | B5: Tierras Forestales | C5: =+INGEI!C4 -> -37381.303 | D5: =+INGEI!D4 -> -37381.303 | E5: =+INGEI!E4 -> -37381.303 | F5: =+INGEI!F4 -> -37381.303 | G5: =+INGEI!G4 -> -37381.303 | H5: =+INGEI!H4 -> -50955.234 | I5: =+INGEI!I4 -> -64529.165 | J5: =+INGEI!J4 -> -77357.533 | ... O5: =+INGEI!O4 -> -1165.9996
A6: Humedales | B6: Tierras Forestales | C6: =+INGEI!C5 -> -763.30476 | D6: =+INGEI!D5 -> -763.30476 | E6: =+INGEI!E5 -> -763.30476 | F6: =+INGEI!F5 -> -763.30476 | G6: =+INGEI!G5 -> -763.30476 | H6: =+INGEI!H5 -> -807.24636 | I6: =+INGEI!I5 -> -851.18795 | J6: =+INGEI!J5 -> -610.33436 | ... O6: =+INGEI!O5 -> -250.65278
A7: Asentamientos | B7: Tierras Forestales | C7: =+INGEI!C6 -> 0 | D7: =+INGEI!D6 -> 0 | E7: =+INGEI!E6 -> 0 | F7: =+INGEI!F6 -> 0 | G7: =+INGEI!G6 -> 0 | H7: =+INGEI!H6 -> 0 | I7: =+INGEI!I6 -> 0 | J7: =+INGEI!J6 -> -1820.4818 | ... O7: =+INGEI!O6 -> 0
A8: Otras Tierras | B8: Tierras Forestales | C8: =+INGEI!C7 -> -165.03887 | D8: =+INGEI!D7 -> -165.03887 | E8: =+INGEI!E7 -> -165.03887 | F8: =+INGEI!F7 -> -165.03887 | G8: =+INGEI!G7 -> -165.03887 | H8: =+INGEI!H7 -> -321.61949 | I8: =+INGEI!I7 -> -478.20012 | J8: =+INGEI!J7 -> -2141.7919 | ... O8: =+INGEI!O7 -> -788.16566
C9: =+SUM(C4:C8)/1000 -> -299.29798 | D9: =+SUM(D4:D8)/1000 -> -299.29798 | E9: =+SUM(E4:E8)/1000 -> -299.29798 | F9: =+SUM(F4:F8)/1000 -> -299.29798 | G9: =+SUM(G4:G8)/1000 -> -299.29798 | H9: =+SUM(H4:H8)/1000 -> -236.55072 | I9: =+SUM(I4:I8)/1000 -> -173.80346 | J9: =+SUM(J4:J8)/1000 -> -224.62584 | ... O9: =+SUM(O4:O8)/1000 -> -49.979238
A10: Tierras de Cultivo | B10: Tierras de Cultivo | C10: =+INGEI!C8 -> 0 | D10: =+INGEI!D8 -> 0 | E10: =+INGEI!E8 -> 0 | F10: =+INGEI!F8 -> 0 | G10: =+INGEI!G8 -> 0 | H10: =+INGEI!H8 -> 0 | I10: =+INGEI!I8 -> 0 | J10: =+INGEI!J8 -> 0 | ... O10: =+INGEI!O8 -> 0
A11: Tierras Forestales | B11: Tierras de Cultivo | C11: =+INGEI!C9 -> 37427636 | D11: =+INGEI!D9 -> 37427636 | E11: =+INGEI!E9 -> 37427636 | F11: =+INGEI!F9 -> 37427636 | G11: =+INGEI!G9 -> 37427636 | H11: =+INGEI!H9 -> 38419762 | I11: =+INGEI!I9 -> 39411887 | J11: =+INGEI!J9 -> 36724892 | ... O11: =+INGEI!O9 -> 37228401
A12: Pastizales | B12: Tierras de Cultivo | C12: =+INGEI!C10 -> -64379.014 | D12: =+INGEI!D10 -> -64379.014 | E12: =+INGEI!E10 -> -64379.014 | F12: =+INGEI!F10 -> -64379.014 | G12: =+INGEI!G10 -> -64379.014 | H12: =+INGEI!H10 -> -102872.37 | I12: =+INGEI!I10 -> -141365.72 | J12: =+INGEI!J10 -> -90297.332 | ... O12: =+INGEI!O10 -> -61290.346
A13: Humedales | B13: Tierras de Cultivo | C13: =+INGEI!C11 -> -79317.238 | D13: =+INGEI!D11 -> -79317.238 | E13: =+INGEI!E11 -> -79317.238 | F13: =+INGEI!F11 -> -79317.238 | G13: =+INGEI!G11 -> -79317.238 | H13: =+INGEI!H11 -> -88356.983 | I13: =+INGEI!I11 -> -97396.728 | J13: =+INGEI!J11 -> -80781.796 | ... O13: =+INGEI!O11 -> -24433.695
A14: Asentamientos | B14: Tierras de Cultivo | C14: =+INGEI!C12 -> 0 | D14: =+INGEI!D12 -> 0 | E14: =+INGEI!E12 -> 0 | F14: =+INGEI!F12 -> 0 | G14: =+INGEI!G12 -> 0 | H14: =+INGEI!H12 -> 0 | I14: =+INGEI!I12 -> 0 | J14: =+INGEI!J12 -> 0 | ... O14: =+INGEI!O12 -> -2501.07
A15: Otras Tierras | B15: Tierras de Cultivo | C15: =+INGEI!C13 -> -12207.624 | D15: =+INGEI!D13 -> -12207.624 | E15: =+INGEI!E13 -> -12207.624 | F15: =+INGEI!F13 -> -12207.624 | G15: =+INGEI!G13 -> -12207.624 | H15: =+INGEI!H13 -> -50096.26 | I15: =+INGEI!I13 -> -87984.897 | J15: =+INGEI!J13 -> -51382.641 | ... O15: =+INGEI!O13 -> -32062.173
C16: =+SUM(C11:C15)/1000 -> 37271.732 | D16: =+SUM(D11:D15)/1000 -> 37271.732 | E16: =+SUM(E11:E15)/1000 -> 37271.732 | F16: =+SUM(F11:F15)/1000 -> 37271.732 | G16: =+SUM(G11:G15)/1000 -> 37271.732 | H16: =+SUM(H11:H15)/1000 -> 38178.436 | I16: =+SUM(I11:I15)/1000 -> 39085.14 | J16: =+SUM(J11:J15)/1000 -> 36502.43 | ... O16: =+SUM(O11:O15)/1000 -> 37108.114
A17: Pastizales | B17: Pastizales | C17: =+INGEI!C14 -> NE | D17: =+INGEI!D14 -> NE | E17: =+INGEI!E14 -> NE | F17: =+INGEI!F14 -> NE | G17: =+INGEI!G14 -> NE | H17: =+INGEI!H14 -> NE | I17: =+INGEI!I14 -> NE | J17: =+INGEI!J14 -> NE | ... O17: =+INGEI!O14 -> NE
A18: Tierras Forestales | B18: Pastizales | C18: =+INGEI!C15 -> 1034352.7 | D18: =+INGEI!D15 -> 1034352.7 | E18: =+INGEI!E15 -> 1034352.7 | F18: =+INGEI!F15 -> 1034352.7 | G18: =+INGEI!G15 -> 1034352.7 | H18: =+INGEI!H15 -> 551831.98 | I18: =+INGEI!I15 -> 69311.211 | J18: =+INGEI!J15 -> 1692292.3 | ... O18: =+INGEI!O15 -> 466865.19
A19: Tierras de Cultivo | B19: Pastizales | C19: =+INGEI!C16 -> -14.666667 | D19: =+INGEI!D16 -> -14.666667 | E19: =+INGEI!E16 -> -14.666667 | F19: =+INGEI!F16 -> -14.666667 | G19: =+INGEI!G16 -> -14.666667 | H19: =+INGEI!H16 -> -14.666667 | I19: =+INGEI!I16 -> -14.666667 | J19: =+INGEI!J16 -> -14.666667 | ... O19: =+INGEI!O16 -> -14.666667
A20: Humedales | B20: Pastizales | C20: =+INGEI!C17 -> -14.666667 | D20: =+INGEI!D17 -> -14.666667 | E20: =+INGEI!E17 -> -14.666667 | F20: =+INGEI!F17 -> -14.666667 | G20: =+INGEI!G17 -> -14.666667 | H20: =+INGEI!H17 -> -14.666667 | I20: =+INGEI!I17 -> -14.666667 | J20: =+INGEI!J17 -> -14.666667 | ... O20: =+INGEI!O17 -> -14.666667
A21: Asentamientos | B21: Pastizales | C21: =+INGEI!C18 -> 0 | D21: =+INGEI!D18 -> 0 | E21: =+INGEI!E18 -> 0 | F21: =+INGEI!F18 -> 0 | G21: =+INGEI!G18 -> 0 | H21: =+INGEI!H18 -> 0 | I21: =+INGEI!I18 -> 0 | J21: =+INGEI!J18 -> 0 | ... O21: =+INGEI!O18 -> 0
A22: Otras Tierras | B22: Pastizales | C22: =+INGEI!C19 -> -14.666667 | D22: =+INGEI!D19 -> -14.666667 | E22: =+INGEI!E19 -> -14.666667 | F22: =+INGEI!F19 -> -14.666667 | G22: =+INGEI!G19 -> -14.666667 | H22: =+INGEI!H19 -> -14.666667 | I22: =+INGEI!I19 -> -14.666667 | J22: =+INGEI!J19 -> -14.666667 | ... O22: =+INGEI!O19 -> -14.666667
B23: =+C18/1000 -> 1034.3527 | C23: =+SUM(C18:C22)/1000 -> 1034.3087 | D23: =+SUM(D18:D22)/1000 -> 1034.3087 | E23: =+SUM(E18:E22)/1000 -> 1034.3087 | F23: =+SUM(F18:F22)/1000 -> 1034.3087 | G23: =+SUM(G18:G22)/1000 -> 1034.3087 | H23: =+SUM(H18:H22)/1000 -> 551.78798 | I23: =+SUM(I18:I22)/1000 -> 69.267211 | J23: =+SUM(J18:J22)/1000 -> 1692.2483 | ... O23: =+SUM(O18:O22)/1000 -> 466.82119
A24: Humedales | B24: Humedales | C24: =+INGEI!C20 -> NE | D24: =+INGEI!D20 -> NE | E24: =+INGEI!E20 -> NE | F24: =+INGEI!F20 -> NE | G24: =+INGEI!G20 -> NE | H24: =+INGEI!H20 -> NE | I24: =+INGEI!I20 -> NE | J24: =+INGEI!J20 -> NE | ... O24: =+INGEI!O20 -> NE
A25: Tierras Forestales | B25: Humedales | C25: =+INGEI!C21 -> 257830.16 | D25: =+INGEI!D21 -> 257830.16 | E25: =+INGEI!E21 -> 257830.16 | F25: =+INGEI!F21 -> 257830.16 | G25: =+INGEI!G21 -> 257830.16 | H25: =+INGEI!H21 -> 317097.99 | I25: =+INGEI!I21 -> 376365.83 | J25: =+INGEI!J21 -> 359780.13 | ... O25: =+INGEI!O21 -> 3822773.4
A26: Tierras de Cultivo | B26: Humedales | C26: =+INGEI!C22 -> 280075.86 | D26: =+INGEI!D22 -> 280075.86 | E26: =+INGEI!E22 -> 280075.86 | F26: =+INGEI!F22 -> 280075.86 | G26: =+INGEI!G22 -> 280075.86 | H26: =+INGEI!H22 -> 276337.79 | I26: =+INGEI!I22 -> 272599.73 | J26: =+INGEI!J22 -> 287145.21 | ... O26: =+INGEI!O22 -> 54708.061
A27: Pastizales | B27: Humedales | C27: =+INGEI!C23 -> 2896.9578 | D27: =+INGEI!D23 -> 2896.9578 | E27: =+INGEI!E23 -> 2896.9578 | F27: =+INGEI!F23 -> 2896.9578 | G27: =+INGEI!G23 -> 2896.9578 | H27: =+INGEI!H23 -> 4512.8068 | I27: =+INGEI!I23 -> 6128.6559 | J27: =+INGEI!J23 -> 3655.8793 | ... O27: =+INGEI!O23 -> 947.69547
A28: Asentamientos | B28: Humedales | C28: =+INGEI!C24 -> 0 | D28: =+INGEI!D24 -> 0 | E28: =+INGEI!E24 -> 0 | F28: =+INGEI!F24 -> 0 | G28: =+INGEI!G24 -> 0 | H28: =+INGEI!H24 -> 0 | I28: =+INGEI!I24 -> 0 | J28: =+INGEI!J24 -> 0 | ... O28: =+INGEI!O24 -> 0
A29: Otras Tierras | B29: Humedales | C29: =+INGEI!C25 -> 0 | D29: =+INGEI!D25 -> 0 | E29: =+INGEI!E25 -> 0 | F29: =+INGEI!F25 -> 0 | G29: =+INGEI!G25 -> 0 | H29: =+INGEI!H25 -> 0 | I29: =+INGEI!I25 -> 0 | J29: =+INGEI!J25 -> 0 | ... O29: =+INGEI!O25 -> 0
C30: =+SUM(C25:C29)/1000 -> 540.80297 | D30: =+SUM(D25:D29)/1000 -> 540.80297 | E30: =+SUM(E25:E29)/1000 -> 540.80297 | F30: =+SUM(F25:F29)/1000 -> 540.80297 | G30: =+SUM(G25:G29)/1000 -> 540.80297 | H30: =+SUM(H25:H29)/1000 -> 597.94859 | I30: =+SUM(I25:I29)/1000 -> 655.09421 | J30: =+SUM(J25:J29)/1000 -> 650.58122 | ... O30: =+SUM(O25:O29)/1000 -> 3878.4292
A31: Asentamientos | B31: Asentamientos | C31: =+INGEI!C26 -> NE | D31: =+INGEI!D26 -> NE | E31: =+INGEI!E26 -> NE | F31: =+INGEI!F26 -> NE | G31: =+INGEI!G26 -> NE | H31: =+INGEI!H26 -> NE | I31: =+INGEI!I26 -> NE | J31: =+INGEI!J26 -> NE | ... O31: =+INGEI!O26 -> NE
A32: Tierras Forestales | B32: Asentamientos | C32: =+INGEI!C27 -> 163507.27 | D32: =+INGEI!D27 -> 163507.27 | E32: =+INGEI!E27 -> 163507.27 | F32: =+INGEI!F27 -> 163507.27 | G32: =+INGEI!G27 -> 163507.27 | H32: =+INGEI!H27 -> 153956.31 | I32: =+INGEI!I27 -> 144405.35 | J32: =+INGEI!J27 -> 202538.19 | ... O32: =+INGEI!O27 -> 710135.94
A33: Tierras de Cultivo | B33: Asentamientos | C33: =+INGEI!C28 -> 350768.68 | D33: =+INGEI!D28 -> 350768.68 | E33: =+INGEI!E28 -> 350768.68 | F33: =+INGEI!F28 -> 350768.68 | G33: =+INGEI!G28 -> 350768.68 | H33: =+INGEI!H28 -> 217366.73 | I33: =+INGEI!I28 -> 83964.781 | J33: =+INGEI!J28 -> 299275.2 | ... O33: =+INGEI!O28 -> 434189.52
A34: Pastizales | B34: Asentamientos | C34: =+INGEI!C29 -> 4236.7116 | D34: =+INGEI!D29 -> 4236.7116 | E34: =+INGEI!E29 -> 4236.7116 | F34: =+INGEI!F29 -> 4236.7116 | G34: =+INGEI!G29 -> 4236.7116 | H34: =+INGEI!H29 -> 3321.7939 | I34: =+INGEI!I29 -> 2406.8763 | J34: =+INGEI!J29 -> 2170.1937 | ... O34: =+INGEI!O29 -> 13344.184
A35: Humedales | B35: Asentamientos | C35: =+INGEI!C30 -> 0 | D35: =+INGEI!D30 -> 0 | E35: =+INGEI!E30 -> 0 | F35: =+INGEI!F30 -> 0 | G35: =+INGEI!G30 -> 0 | H35: =+INGEI!H30 -> 0 | I35: =+INGEI!I30 -> 0 | J35: =+INGEI!J30 -> 0 | ... O35: =+INGEI!O30 -> 0
A36: Otras Tierras | B36: Asentamientos | C36: =+INGEI!C31 -> 0 | D36: =+INGEI!D31 -> 0 | E36: =+INGEI!E31 -> 0 | F36: =+INGEI!F31 -> 0 | G36: =+INGEI!G31 -> 0 | H36: =+INGEI!H31 -> 0 | I36: =+INGEI!I31 -> 0 | J36: =+INGEI!J31 -> 0 | ... O36: =+INGEI!O31 -> 0
C37: =+SUM(C32:C36)/1000 -> 518.51266 | D37: =+SUM(D32:D36)/1000 -> 518.51266 | E37: =+SUM(E32:E36)/1000 -> 518.51266 | F37: =+SUM(F32:F36)/1000 -> 518.51266 | G37: =+SUM(G32:G36)/1000 -> 518.51266 | H37: =+SUM(H32:H36)/1000 -> 374.64484 | I37: =+SUM(I32:I36)/1000 -> 230.77701 | J37: =+SUM(J32:J36)/1000 -> 503.98358 | ... O37: =+SUM(O32:O36)/1000 -> 1157.6696
A38: Otras Tierras | B38: Otras Tierras | C38: =+INGEI!C32 -> NA | D38: =+INGEI!D32 -> NA | E38: =+INGEI!E32 -> NA | F38: =+INGEI!F32 -> NA | G38: =+INGEI!G32 -> NA | H38: =+INGEI!H32 -> NA | I38: =+INGEI!I32 -> NA | J38: =+INGEI!J32 -> NA | ... O38: =+INGEI!O32 -> NA
A39: Tierras Forestales | B39: Otras Tierras | C39: =+INGEI!C33 -> 236927.22 | D39: =+INGEI!D33 -> 236927.22 | E39: =+INGEI!E33 -> 236927.22 | F39: =+INGEI!F33 -> 236927.22 | G39: =+INGEI!G33 -> 236927.22 | H39: =+INGEI!H33 -> 549772.32 | I39: =+INGEI!I33 -> 862617.41 | J39: =+INGEI!J33 -> 843084.1 | ... O39: =+INGEI!O33 -> 286005.97
A40: tierras de Cultivo | B40: Otras Tierras | C40: =+INGEI!C34 -> 122388.25 | D40: =+INGEI!D34 -> 122388.25 | E40: =+INGEI!E34 -> 122388.25 | F40: =+INGEI!F34 -> 122388.25 | G40: =+INGEI!G34 -> 122388.25 | H40: =+INGEI!H34 -> 99837.172 | I40: =+INGEI!I34 -> 77286.097 | J40: =+INGEI!J34 -> 134836.07 | ... O40: =+INGEI!O34 -> 84797.151
...

Sheet Pastizales
A1: Emisiones | B1: =+INGEI_diffs!C18/1000 -> 1034.3527 | C1: =+INGEI_diffs!D18/1000 -> 1034.3527 | D1: =+INGEI_diffs!E18/1000 -> 1034.3527 | E1: =+INGEI_diffs!F18/1000 -> 1034.3527 | F1: =+INGEI_diffs!G18/1000 -> 1034.3527 | G1: =+INGEI_diffs!H18/1000 -> 551.83198 | H1: =+INGEI_diffs!I18/1000 -> 69.311211 | I1: =+INGEI_diffs!J18/1000 -> 1692.2923 | ... N1: =+INGEI_diffs!O18/1000 -> 466.86519
A2: Emisiones(miles de tonCO2e) | B2: 2010 | C2: 2011 | D2: 2012 | E2: 2013 | F2: 2014 | G2: 2015 | H2: 2016 | I2: 2017 | J2: 2018 | K2: 2019 | L2: 2020 | M2: 2021 | N2: 2022
A3: B. Seco Andino | B3: =+'5ta'!$R87*B$1 -> 2.5353085 | C3: =+'5ta'!$R87*C$1 -> 2.5353085 | D3: =+'5ta'!$R87*D$1 -> 2.5353085 | E3: =+'5ta'!$R87*E$1 -> 2.5353085 | F3: =+'5ta'!$R87*F$1 -> 2.5353085 | G3: =+'5ta'!$R87*G$1 -> 1.3525988 | H3: =+'5ta'!$R87*H$1 -> 0.16988914 | I3: =+'5ta'!$R87*I$1 -> 4.1479881 | ... N3: =+'5ta'!$R87*N$1 -> 1.1443362
A4: B. Seco Pluvioestacional | B4: =+'5ta'!$R88*B$1 -> 24.757758 | C4: =+'5ta'!$R88*C$1 -> 24.757758 | D4: =+'5ta'!$R88*D$1 -> 24.757758 | E4: =+'5ta'!$R88*E$1 -> 24.757758 | F4: =+'5ta'!$R88*F$1 -> 24.757758 | G4: =+'5ta'!$R88*G$1 -> 13.208379 | H4: =+'5ta'!$R88*H$1 -> 1.658999 | I4: =+'5ta'!$R88*I$1 -> 40.505875 | ... N4: =+'5ta'!$R88*N$1 -> 11.174655
A5: B. Siempre verde andino Montano | B5: =+'5ta'!$R89*B$1 -> 236.73611 | C5: =+'5ta'!$R89*C$1 -> 236.73611 | D5: =+'5ta'!$R89*D$1 -> 236.73611 | E5: =+'5ta'!$R89*E$1 -> 236.73611 | F5: =+'5ta'!$R89*F$1 -> 236.73611 | G5: =+'5ta'!$R89*G$1 -> 126.29981 | H5: =+'5ta'!$R89*H$1 -> 15.863511 | I5: =+'5ta'!$R89*I$1 -> 387.32114 | ... N5: =+'5ta'!$R89*N$1 -> 106.85315
A6: B. Siempre verde andino Pie montano | B6: =+'5ta'!$R90*B$1 -> 96.231701 | C6: =+'5ta'!$R90*C$1 -> 96.231701 | D6: =+'5ta'!$R90*D$1 -> 96.231701 | E6: =+'5ta'!$R90*E$1 -> 96.231701 | F6: =+'5ta'!$R90*F$1 -> 96.231701 | G6: =+'5ta'!$R90*G$1 -> 51.340058 | H6: =+'5ta'!$R90*H$1 -> 6.448415 | I6: =+'5ta'!$R90*I$1 -> 157.44354 | ... N6: =+'5ta'!$R90*N$1 -> 43.435116
A7: B. Siempre verde andino de Ceja Andina | B7: =+'5ta'!$R91*B$1 -> 66.272281 | C7: =+'5ta'!$R91*C$1 -> 66.272281 | D7: =+'5ta'!$R91*D$1 -> 66.272281 | E7: =+'5ta'!$R91*E$1 -> 66.272281 | F7: =+'5ta'!$R91*F$1 -> 66.272281 | G7: =+'5ta'!$R91*G$1 -> 35.356569 | H7: =+'5ta'!$R91*H$1 -> 4.4408564 | I7: =+'5ta'!$R91*I$1 -> 108.42729 | ... N7: =+'5ta'!$R91*N$1 -> 29.912639
A8: B. Siempre verde de tierras bajas de la Amazonía | B8: =+'5ta'!$R92*B$1 -> 484.94723 | C8: =+'5ta'!$R92*C$1 -> 484.94723 | D8: =+'5ta'!$R92*D$1 -> 484.94723 | E8: =+'5ta'!$R92*E$1 -> 484.94723 | F8: =+'5ta'!$R92*F$1 -> 484.94723 | G8: =+'5ta'!$R92*G$1 -> 258.72159 | H8: =+'5ta'!$R92*H$1 -> 32.495954 | I8: =+'5ta'!$R92*I$1 -> 793.4164 | ... N8: =+'5ta'!$R92*N$1 -> 218.88565
A9: B. Siempre verde de tierras bajas del Chocó | B9: =+'5ta'!$R93*B$1 -> 53.72836 | C9: =+'5ta'!$R93*C$1 -> 53.72836 | D9: =+'5ta'!$R93*D$1 -> 53.72836 | E9: =+'5ta'!$R93*E$1 -> 53.72836 | F9: =+'5ta'!$R93*F$1 -> 53.72836 | G9: =+'5ta'!$R93*G$1 -> 28.664329 | H9: =+'5ta'!$R93*H$1 -> 3.6002976 | I9: =+'5ta'!$R93*I$1 -> 87.904333 | ... N9: =+'5ta'!$R93*N$1 -> 24.250819
A10: Manglar | B10: =+'5ta'!$R94*B$1 -> 13.343553 | C10: =+'5ta'!$R94*C$1 -> 13.343553 | D10: =+'5ta'!$R94*D$1 -> 13.343553 | E10: =+'5ta'!$R94*E$1 -> 13.343553 | F10: =+'5ta'!$R94*F$1 -> 13.343553 | G10: =+'5ta'!$R94*G$1 -> 7.1188471 | H10: =+'5ta'!$R94*H$1 -> 0.89414157 | I10: =+'5ta'!$R94*I$1 -> 21.831228 | ... N10: =+'5ta'!$R94*N$1 -> 6.0227425
A11: Moretal | B11: =+'5ta'!$R95*B$1 -> 55.800453 | C11: =+'5ta'!$R95*C$1 -> 55.800453 | D11: =+'5ta'!$R95*D$1 -> 55.800453 | E11: =+'5ta'!$R95*E$1 -> 55.800453 | F11: =+'5ta'!$R95*F$1 -> 55.800453 | G11: =+'5ta'!$R95*G$1 -> 29.7698 | H11: =+'5ta'!$R95*H$1 -> 3.739147 | I11: =+'5ta'!$R95*I$1 -> 91.29446 | ... N11: =+'5ta'!$R95*N$1 -> 25.186078
A12: Total | B12: =+SUM(B3:B11) -> 1034.3527 | C12: =+SUM(C3:C11) -> 1034.3527 | D12: =+SUM(D3:D11) -> 1034.3527 | E12: =+SUM(E3:E11) -> 1034.3527 | F12: =+SUM(F3:F11) -> 1034.3527 | G12: =+SUM(G3:G11) -> 551.83198 | H12: =+SUM(H3:H11) -> 69.311211 | I12: =+SUM(I3:I11) -> 1692.2923 | ... N12: =+SUM(N3:N11) -> 466.86519
A14: Cobertura
A15: B. Seco Andino | B15: 0 | C15: 0 | D15: 0 | E15: 0 | F15: 0 | G15: 0 | H15: 0 | I15: 0.08 | J15: 0.16 | K15: 0.02 | L15: 0.02394 | M15: 0 | N15: 0
A16: B. Seco Pluvioestacional | B16: 0 | C16: 0 | D16: 0 | E16: 0 | F16: 0 | G16: 0 | H16: 0 | I16: 0.3 | J16: 0.61 | K16: 0.19 | L16: 0.19 | M16: 0.47 | N16: 0.47
A17: B. Siempre verde andino Montano | B17: 0 | C17: 0 | D17: 0 | E17: 0 | F17: 0 | G17: 0 | H17: 0 | I17: 0.2 | J17: 0.39 | K17: 0.85 | L17: 0.85 | M17: 0.08 | N17: 0.08
A18: B. Siempre verde andino Pie montano | B18: 0 | C18: 0 | D18: 0 | E18: 0 | F18: 0 | G18: 0 | H18: 0 | I18: 0.03 | J18: 0.07 | K18: 0.15 | L18: 0.15 | M18: 0.02 | N18: 0.02
A19: B. Siempre verde andino de Ceja Andina | B19: 0 | C19: 0 | D19: 0 | E19: 0 | F19: 0 | G19: 0 | H19: 0 | I19: 0.19121 | J19: 0.38241 | K19: 1.33529 | L19: 1.33529 | M19: 0.04046 | N19: 0.04046
A20: B. Siempre verde de tierras bajas de la Amazonía | B20: 0 | C20: 0 | D20: 0 | E20: 0 | F20: 0 | G20: 0 | H20: 0 | I20: 0.02032 | J20: 0.04064 | K20: 0.34286 | L20: 0.34286 | M20: 0.01976 | N20: 0.01976
A21: B. Siempre verde de tierras bajas del Chocó | B21: 0 | C21: 0 | D21: 0 | E21: 0 | F21: 0 | G21: 0 | H21: 0 | I21: 0.07 | J21: 0.13046 | K21: 0.58 | L21: 0.58 | M21: 0.04 | N21: 0.04
A22: Manglar | B22: 0 | C22: 0 | D22: 0 | E22: 0 | F22: 0 | G22: 0 | H22: 0 | I22: 0.01 | J22: 0.02 | K22: 0.1 | L22: 0.1 | M22: 0.14 | N22: 0.14
A23: Moretal | B23: 0 | C23: 0 | D23: 0 | E23: 0 | F23: 0 | G23: 0 | H23: 0 | I23: 0 | J23: 0 | K23: 0.02 | L23: 0.02 | M23: 0.00036 | N23: 0.00036
A25: EAR
A26: B. Seco Andino | B26: 0 | C26: 0 | D26: 0 | E26: 0 | F26: 0 | G26: 0 | H26: 0 | I26: =+I3/I15 -> 51.849851 | J26: =+J3/J15 -> 50.788044 | K26: =+K3/K15 -> 193.33776 | L26: =+L3/L15 -> 161.5186 | M26: 0 | N26: 0
A27: B. Seco Pluvioestacional | B27: 0 | C27: 0 | D27: 0 | E27: 0 | F27: 0 | G27: 0 | H27: 0 | I27: =+I4/I16 -> 135.01958 | J27: =+J4/J16 -> 130.08648 | K27: =+K4/K16 -> 198.73465 | L27: =+L4/L16 -> 198.73465 | M27: =+M4/M16 -> 23.775863 | N27: =+N4/N16 -> 23.775863
A28: B. Siempre verde andino Montano | B28: 0 | C28: 0 | D28: 0 | E28: 0 | F28: 0 | G28: 0 | H28: 0 | I28: =+I5/I17 -> 1936.6057 | J28: =+J5/J17 -> 1945.5866 | K28: =+K5/K17 -> 424.77745 | L28: =+L5/L17 -> 424.77745 | M28: =+M5/M17 -> 1335.6644 | N28: =+N5/N17 -> 1335.6644
A29: B. Siempre verde andino Pie montano | B29: 0 | C29: 0 | D29: 0 | E29: 0 | F29: 0 | G29: 0 | H29: 0 | I29: =+I6/I18 -> 5248.1182 | J29: =+J6/J18 -> 4406.2668 | K29: =+K6/K18 -> 978.45934 | L29: =+L6/L18 -> 978.45934 | M29: =+M6/M18 -> 2171.7558 | N29: =+N6/N18 -> 2171.7558
A30: B. Siempre verde andino de Ceja Andina | B30: 0 | C30: 0 | D30: 0 | E30: 0 | F30: 0 | G30: 0 | H30: 0 | I30: =+I7/I19 -> 567.05869 | J30: =+J7/J19 -> 555.46071 | K30: =+K7/K19 -> 75.695873 | L30: =+L7/L19 -> 75.695873 | M30: =+M7/M19 -> 739.31388 | N30: =+N7/N19 -> 739.31388
A31: B. Siempre verde de tierras bajas de la Amazonía | B31: 0 | C31: 0 | D31: 0 | E31: 0 | F31: 0 | G31: 0 | H31: 0 | I31: =+I8/I20 -> 39046.083 | J31: =+J8/J20 -> 38246.478 | K31: =+K8/K20 -> 2157.2155 | L31: =+L8/L20 -> 2157.2155 | M31: =+M8/M20 -> 11077.209 | N31: =+N8/N20 -> 11077.209
A32: B. Siempre verde de tierras bajas del Chocó | B32: 0 | C32: 0 | D32: 0 | E32: 0 | F32: 0 | G32: 0 | H32: 0 | I32: =+I9/I21 -> 1255.7762 | J32: =+J9/J21 -> 1320.009 | K32: =+K9/K21 -> 141.28351 | L32: =+L9/L21 -> 141.28351 | M32: =+M9/M21 -> 606.27047 | N32: =+N9/N21 -> 606.27047
A33: Manglar | B33: 0 | C33: 0 | D33: 0 | E33: 0 | F33: 0 | G33: 0 | H33: 0 | I33: =+I10/I22 -> 2183.1228 | J33: =+J10/J22 -> 2138.4157 | K33: =+K10/K22 -> 203.51075 | L33: =+L10/L22 -> 203.51075 | M33: =+M10/M22 -> 43.019589 | N33: =+N10/N22 -> 43.019589
A34: Moretal | B34: 0 | C34: 0 | D34: 0 | E34: 0 | F34: 0 | G34: 0 | H34: 0 | I34: 0 | J34: 0 | K34: =+K11/K23 -> 4255.2356 | L34: =+L11/L23 -> 4255.2356 | M34: =+M11/M23 -> 69961.328 | N34: =+N11/N23 -> 69961.328
B36: =+B15*B26 -> 0 | C36: =+C15*C26 -> 0 | D36: =+D15*D26 -> 0 | E36: =+E15*E26 -> 0 | F36: =+F15*F26 -> 0 | G36: =+G15*G26 -> 0 | H36: =+H15*H26 -> 0 | I36: =+I15*I26 -> 4.1479881 | ... N36: =+N15*N26 -> 0
B37: =+B16*B27 -> 0 | C37: =+C16*C27 -> 0 | D37: =+D16*D27 -> 0 | E37: =+E16*E27 -> 0 | F37: =+F16*F27 -> 0 | G37: =+G16*G27 -> 0 | H37: =+H16*H27 -> 0 | I37: =+I16*I27 -> 40.505875 | ... N37: =+N16*N27 -> 11.174655
B38: =+B17*B28 -> 0 | C38: =+C17*C28 -> 0 | D38: =+D17*D28 -> 0 | E38: =+E17*E28 -> 0 | F38: =+F17*F28 -> 0 | G38: =+G17*G28 -> 0 | H38: =+H17*H28 -> 0 | I38: =+I17*I28 -> 387.32114 | ... N38: =+N17*N28 -> 106.85315
B39: =+B18*B29 -> 0 | C39: =+C18*C29 -> 0 | D39: =+D18*D29 -> 0 | E39: =+E18*E29 -> 0 | F39: =+F18*F29 -> 0 | G39: =+G18*G29 -> 0 | H39: =+H18*H29 -> 0 | I39: =+I18*I29 -> 157.44354 | ... N39: =+N18*N29 -> 43.435116
B40: =+B19*B30 -> 0 | C40: =+C19*C30 -> 0 | D40: =+D19*D30 -> 0 | E40: =+E19*E30 -> 0 | F40: =+F19*F30 -> 0 | G40: =+G19*G30 -> 0 | H40: =+H19*H30 -> 0 | I40: =+I19*I30 -> 108.42729 | ... N40: =+N19*N30 -> 29.912639
B41: =+B20*B31 -> 0 | C41: =+C20*C31 -> 0 | D41: =+D20*D31 -> 0 | E41: =+E20*E31 -> 0 | F41: =+F20*F31 -> 0 | G41: =+G20*G31 -> 0 | H41: =+H20*H31 -> 0 | I41: =+I20*I31 -> 793.4164 | ... N41: =+N20*N31 -> 218.88565
B42: =+B21*B32 -> 0 | C42: =+C21*C32 -> 0 | D42: =+D21*D32 -> 0 | E42: =+E21*E32 -> 0 | F42: =+F21*F32 -> 0 | G42: =+G21*G32 -> 0 | H42: =+H21*H32 -> 0 | I42: =+I21*I32 -> 87.904333 | ... N42: =+N21*N32 -> 24.250819
B43: =+B22*B33 -> 0 | C43: =+C22*C33 -> 0 | D43: =+D22*D33 -> 0 | E43: =+E22*E33 -> 0 | F43: =+F22*F33 -> 0 | G43: =+G22*G33 -> 0 | H43: =+H22*H33 -> 0 | I43: =+I22*I33 -> 21.831228 | ... N43: =+N22*N33 -> 6.0227425
...

Sheet Emisiones Tierras forestales
A1: CROP a FOR | B1: =INGEI_diffs!C4/1000 -> -260.98834 | C1: =INGEI_diffs!D4/1000 -> -260.98834 | D1: =INGEI_diffs!E4/1000 -> -260.98834 | E1: =INGEI_diffs!F4/1000 -> -260.98834 | F1: =INGEI_diffs!G4/1000 -> -260.98834 | G1: =INGEI_diffs!H4/1000 -> -184.46662 | H1: =INGEI_diffs!I4/1000 -> -107.94491 | I1: =INGEI_diffs!J4/1000 -> -142.6957 | ... N1: =INGEI_diffs!O4/1000 -> -47.77442
A2: Emisiones(miles de tonCO2e) | B2: 2010 | C2: 2011 | D2: 2012 | E2: 2013 | F2: 2014 | G2: 2015 | H2: 2016 | I2: 2017 | J2: 2018 | K2: 2019 | L2: 2020 | M2: 2021 | N2: 2022
A3: B. Seco Andino | B3: =+'5ta'!$R87*'Emisiones Tierras forestales'!B$1 -> -0.63971014 | C3: =+'5ta'!$R87*'Emisiones Tierras forestales'!C$1 -> -0.63971014 | D3: =+'5ta'!$R87*'Emisiones Tierras forestales'!D$1 -> -0.63971014 | E3: =+'5ta'!$R87*'Emisiones Tierras forestales'!E$1 -> -0.63971014 | F3: =+'5ta'!$R87*'Emisiones Tierras forestales'!F$1 -> -0.63971014 | G3: =+'5ta'!$R87*'Emisiones Tierras forestales'!G$1 -> -0.45214729 | H3: =+'5ta'!$R87*'Emisiones Tierras forestales'!H$1 -> -0.26458444 | I3: =+'5ta'!$R87*'Emisiones Tierras forestales'!I$1 -> -0.34976232 | ... N3: =+'5ta'!$R87*'Emisiones Tierras forestales'!N$1 -> -0.11710018
A4: B. Seco Pluvioestacional | B4: =+'5ta'!$R88*'Emisiones Tierras forestales'!B$1 -> -6.2468884 | C4: =+'5ta'!$R88*'Emisiones Tierras forestales'!C$1 -> -6.2468884 | D4: =+'5ta'!$R88*'Emisiones Tierras forestales'!D$1 -> -6.2468884 | E4: =+'5ta'!$R88*'Emisiones Tierras forestales'!E$1 -> -6.2468884 | F4: =+'5ta'!$R88*'Emisiones Tierras forestales'!F$1 -> -6.2468884 | G4: =+'5ta'!$R88*'Emisiones Tierras forestales'!G$1 -> -4.4153023 | H4: =+'5ta'!$R88*'Emisiones Tierras forestales'!H$1 -> -2.5837162 | I4: =+'5ta'!$R88*'Emisiones Tierras forestales'!I$1 -> -3.415494 | ... N4: =+'5ta'!$R88*'Emisiones Tierras forestales'!N$1 -> -1.143505
A5: B. Siempre verde andino Montano | B5: =+'5ta'!$R89*'Emisiones Tierras forestales'!B$1 -> -59.733358 | C5: =+'5ta'!$R89*'Emisiones Tierras forestales'!C$1 -> -59.733358 | D5: =+'5ta'!$R89*'Emisiones Tierras forestales'!D$1 -> -59.733358 | E5: =+'5ta'!$R89*'Emisiones Tierras forestales'!E$1 -> -59.733358 | F5: =+'5ta'!$R89*'Emisiones Tierras forestales'!F$1 -> -59.733358 | G5: =+'5ta'!$R89*'Emisiones Tierras forestales'!G$1 -> -42.219553 | H5: =+'5ta'!$R89*'Emisiones Tierras forestales'!H$1 -> -24.705747 | I5: =+'5ta'!$R89*'Emisiones Tierras forestales'!I$1 -> -32.659288 | ... N5: =+'5ta'!$R89*'Emisiones Tierras forestales'!N$1 -> -10.934307
A6: B. Siempre verde andino Pie montano | B6: =+'5ta'!$R90*'Emisiones Tierras forestales'!B$1 -> -24.281225 | C6: =+'5ta'!$R90*'Emisiones Tierras forestales'!C$1 -> -24.281225 | D6: =+'5ta'!$R90*'Emisiones Tierras forestales'!D$1 -> -24.281225 | E6: =+'5ta'!$R90*'Emisiones Tierras forestales'!E$1 -> -24.281225 | F6: =+'5ta'!$R90*'Emisiones Tierras forestales'!F$1 -> -24.281225 | G6: =+'5ta'!$R90*'Emisiones Tierras forestales'!G$1 -> -17.161976 | H6: =+'5ta'!$R90*'Emisiones Tierras forestales'!H$1 -> -10.042727 | I6: =+'5ta'!$R90*'Emisiones Tierras forestales'!I$1 -> -13.27579 | ... N6: =+'5ta'!$R90*'Emisiones Tierras forestales'!N$1 -> -4.4447251
A7: B. Siempre verde andino de Ceja Andina | B7: =+'5ta'!$R91*'Emisiones Tierras forestales'!B$1 -> -16.721851 | C7: =+'5ta'!$R91*'Emisiones Tierras forestales'!C$1 -> -16.721851 | D7: =+'5ta'!$R91*'Emisiones Tierras forestales'!D$1 -> -16.721851 | E7: =+'5ta'!$R91*'Emisiones Tierras forestales'!E$1 -> -16.721851 | F7: =+'5ta'!$R91*'Emisiones Tierras forestales'!F$1 -> -16.721851 | G7: =+'5ta'!$R91*'Emisiones Tierras forestales'!G$1 -> -11.819008 | H7: =+'5ta'!$R91*'Emisiones Tierras forestales'!H$1 -> -6.916166 | I7: =+'5ta'!$R91*'Emisiones Tierras forestales'!I$1 -> -9.1426928 | ... N7: =+'5ta'!$R91*'Emisiones Tierras forestales'!N$1 -> -3.0609671
A8: B. Siempre verde de tierras bajas de la Amazonía | B8: =+'5ta'!$R92*'Emisiones Tierras forestales'!B$1 -> -122.3621 | C8: =+'5ta'!$R92*'Emisiones Tierras forestales'!C$1 -> -122.3621 | D8: =+'5ta'!$R92*'Emisiones Tierras forestales'!D$1 -> -122.3621 | E8: =+'5ta'!$R92*'Emisiones Tierras forestales'!E$1 -> -122.3621 | F8: =+'5ta'!$R92*'Emisiones Tierras forestales'!F$1 -> -122.3621 | G8: =+'5ta'!$R92*'Emisiones Tierras forestales'!G$1 -> -86.48556 | H8: =+'5ta'!$R92*'Emisiones Tierras forestales'!H$1 -> -50.609025 | I8: =+'5ta'!$R92*'Emisiones Tierras forestales'!I$1 -> -66.901628 | ... N8: =+'5ta'!$R92*'Emisiones Tierras forestales'!N$1 -> -22.398618
A9: B. Siempre verde de tierras bajas del Chocó | B9: =+'5ta'!$R93*'Emisiones Tierras forestales'!B$1 -> -13.556763 | C9: =+'5ta'!$R93*'Emisiones Tierras forestales'!C$1 -> -13.556763 | D9: =+'5ta'!$R93*'Emisiones Tierras forestales'!D$1 -> -13.556763 | E9: =+'5ta'!$R93*'Emisiones Tierras forestales'!E$1 -> -13.556763 | F9: =+'5ta'!$R93*'Emisiones Tierras forestales'!F$1 -> -13.556763 | G9: =+'5ta'!$R93*'Emisiones Tierras forestales'!G$1 -> -9.5819238 | H9: =+'5ta'!$R93*'Emisiones Tierras forestales'!H$1 -> -5.6070842 | I9: =+'5ta'!$R93*'Emisiones Tierras forestales'!I$1 -> -7.4121772 | ... N9: =+'5ta'!$R93*'Emisiones Tierras forestales'!N$1 -> -2.4815917
A10: Manglar | B10: =+'5ta'!$R94*'Emisiones Tierras forestales'!B$1 -> -3.366851 | C10: =+'5ta'!$R94*'Emisiones Tierras forestales'!C$1 -> -3.366851 | D10: =+'5ta'!$R94*'Emisiones Tierras forestales'!D$1 -> -3.366851 | E10: =+'5ta'!$R94*'Emisiones Tierras forestales'!E$1 -> -3.366851 | F10: =+'5ta'!$R94*'Emisiones Tierras forestales'!F$1 -> -3.366851 | G10: =+'5ta'!$R94*'Emisiones Tierras forestales'!G$1 -> -2.3796912 | H10: =+'5ta'!$R94*'Emisiones Tierras forestales'!H$1 -> -1.3925313 | I10: =+'5ta'!$R94*'Emisiones Tierras forestales'!I$1 -> -1.84083 | ... N10: =+'5ta'!$R94*'Emisiones Tierras forestales'!N$1 -> -0.61630859
A11: Moretal | B11: =+'5ta'!$R95*'Emisiones Tierras forestales'!B$1 -> -14.079595 | C11: =+'5ta'!$R95*'Emisiones Tierras forestales'!C$1 -> -14.079595 | D11: =+'5ta'!$R95*'Emisiones Tierras forestales'!D$1 -> -14.079595 | E11: =+'5ta'!$R95*'Emisiones Tierras forestales'!E$1 -> -14.079595 | F11: =+'5ta'!$R95*'Emisiones Tierras forestales'!F$1 -> -14.079595 | G11: =+'5ta'!$R95*'Emisiones Tierras forestales'!G$1 -> -9.9514611 | H11: =+'5ta'!$R95*'Emisiones Tierras forestales'!H$1 -> -5.8233275 | I11: =+'5ta'!$R95*'Emisiones Tierras forestales'!I$1 -> -7.6980359 | ... N11: =+'5ta'!$R95*'Emisiones Tierras forestales'!N$1 -> -2.577297
A12: Total | B12: =+SUM(B3:B11) -> -260.98834 | C12: =+SUM(C3:C11) -> -260.98834 | D12: =+SUM(D3:D11) -> -260.98834 | E12: =+SUM(E3:E11) -> -260.98834 | F12: =+SUM(F3:F11) -> -260.98834 | G12: =+SUM(G3:G11) -> -184.46662 | H12: =+SUM(H3:H11) -> -107.94491 | I12: =+SUM(I3:I11) -> -142.6957 | ... N12: =+SUM(N3:N11) -> -47.77442
A14: Cobertura
B15: 2010 | C15: 2011 | D15: 2012 | E15: 2013 | F15: 2014 | G15: 2015 | H15: 2016 | I15: 2017 | J15: 2018 | K15: 2019 | L15: 2020 | M15: 2021 | N15: 2022
A16: B. Seco Andino | B16: =+'Cambio uso de suelo (BAU)'!D96 -> 0.031008945 | C16: =+'Cambio uso de suelo (BAU)'!E96 -> 0.031008945 | D16: =+'Cambio uso de suelo (BAU)'!F96 -> 0.031008945 | E16: =+'Cambio uso de suelo (BAU)'!G96 -> 0.031008945 | F16: =+'Cambio uso de suelo (BAU)'!H96 -> 0.031008945 | G16: =+'Cambio uso de suelo (BAU)'!I96 -> 0.02191713 | H16: =+'Cambio uso de suelo (BAU)'!J96 -> 0.012825315 | I16: =+'Cambio uso de suelo (BAU)'!K96 -> 0.016954179 | ... N16: =+'Cambio uso de suelo (BAU)'!P96 -> 0.0056762473
A17: B. Seco Pluvioestacional | B17: =+'Cambio uso de suelo (BAU)'!D97 -> 0.30280811 | C17: =+'Cambio uso de suelo (BAU)'!E97 -> 0.30280811 | D17: =+'Cambio uso de suelo (BAU)'!F97 -> 0.30280811 | E17: =+'Cambio uso de suelo (BAU)'!G97 -> 0.30280811 | F17: =+'Cambio uso de suelo (BAU)'!H97 -> 0.30280811 | G17: =+'Cambio uso de suelo (BAU)'!I97 -> 0.21402485 | H17: =+'Cambio uso de suelo (BAU)'!J97 -> 0.12524159 | I17: =+'Cambio uso de suelo (BAU)'!K97 -> 0.16556071 | ... N17: =+'Cambio uso de suelo (BAU)'!P97 -> 0.05542961
A18: B. Siempre verde andino Montano | B18: =+'Cambio uso de suelo (BAU)'!D98 -> 2.8954808 | C18: =+'Cambio uso de suelo (BAU)'!E98 -> 2.8954808 | D18: =+'Cambio uso de suelo (BAU)'!F98 -> 2.8954808 | E18: =+'Cambio uso de suelo (BAU)'!G98 -> 2.8954808 | F18: =+'Cambio uso de suelo (BAU)'!H98 -> 2.8954808 | G18: =+'Cambio uso de suelo (BAU)'!I98 -> 2.0465265 | H18: =+'Cambio uso de suelo (BAU)'!J98 -> 1.1975723 | I18: =+'Cambio uso de suelo (BAU)'!K98 -> 1.5831077 | ... N18: =+'Cambio uso de suelo (BAU)'!P98 -> 0.53002335
A19: B. Siempre verde andino Pie montano | B19: =+'Cambio uso de suelo (BAU)'!D99 -> 1.1769943 | C19: =+'Cambio uso de suelo (BAU)'!E99 -> 1.1769943 | D19: =+'Cambio uso de suelo (BAU)'!F99 -> 1.1769943 | E19: =+'Cambio uso de suelo (BAU)'!G99 -> 1.1769943 | F19: =+'Cambio uso de suelo (BAU)'!H99 -> 1.1769943 | G19: =+'Cambio uso de suelo (BAU)'!I99 -> 0.83189984 | H19: =+'Cambio uso de suelo (BAU)'!J99 -> 0.48680542 | I19: =+'Cambio uso de suelo (BAU)'!K99 -> 0.64352308 | ... N19: =+'Cambio uso de suelo (BAU)'!P99 -> 0.21545107
A20: B. Siempre verde andino de Ceja Andina | B20: =+'Cambio uso de suelo (BAU)'!D100 -> 0.81056547 | C20: =+'Cambio uso de suelo (BAU)'!E100 -> 0.81056547 | D20: =+'Cambio uso de suelo (BAU)'!F100 -> 0.81056547 | E20: =+'Cambio uso de suelo (BAU)'!G100 -> 0.81056547 | F20: =+'Cambio uso de suelo (BAU)'!H100 -> 0.81056547 | G20: =+'Cambio uso de suelo (BAU)'!I100 -> 0.57290788 | H20: =+'Cambio uso de suelo (BAU)'!J100 -> 0.33525029 | I20: =+'Cambio uso de suelo (BAU)'!K100 -> 0.44317768 | ... N20: =+'Cambio uso de suelo (BAU)'!P100 -> 0.14837558
A21: B. Siempre verde de tierras bajas de la Amazonía | B21: =+'Cambio uso de suelo (BAU)'!D101 -> 5.9313105 | C21: =+'Cambio uso de suelo (BAU)'!E101 -> 5.9313105 | D21: =+'Cambio uso de suelo (BAU)'!F101 -> 5.9313105 | E21: =+'Cambio uso de suelo (BAU)'!G101 -> 5.9313105 | F21: =+'Cambio uso de suelo (BAU)'!H101 -> 5.9313105 | G21: =+'Cambio uso de suelo (BAU)'!I101 -> 4.1922518 | H21: =+'Cambio uso de suelo (BAU)'!J101 -> 2.453193 | I21: =+'Cambio uso de suelo (BAU)'!K101 -> 3.2429514 | ... N21: =+'Cambio uso de suelo (BAU)'!P101 -> 1.0857379
A22: B. Siempre verde de tierras bajas del Chocó | B22: =+'Cambio uso de suelo (BAU)'!D102 -> 0.65714282 | C22: =+'Cambio uso de suelo (BAU)'!E102 -> 0.65714282 | D22: =+'Cambio uso de suelo (BAU)'!F102 -> 0.65714282 | E22: =+'Cambio uso de suelo (BAU)'!G102 -> 0.65714282 | F22: =+'Cambio uso de suelo (BAU)'!H102 -> 0.65714282 | G22: =+'Cambio uso de suelo (BAU)'!I102 -> 0.46446871 | H22: =+'Cambio uso de suelo (BAU)'!J102 -> 0.2717946 | I22: =+'Cambio uso de suelo (BAU)'!K102 -> 0.35929366 | ... N22: =+'Cambio uso de suelo (BAU)'!P102 -> 0.12029126
A23: Manglar | B23: =+'Cambio uso de suelo (BAU)'!D103 -> 0.16320282 | C23: =+'Cambio uso de suelo (BAU)'!E103 -> 0.16320282 | D23: =+'Cambio uso de suelo (BAU)'!F103 -> 0.16320282 | E23: =+'Cambio uso de suelo (BAU)'!G103 -> 0.16320282 | F23: =+'Cambio uso de suelo (BAU)'!H103 -> 0.16320282 | G23: =+'Cambio uso de suelo (BAU)'!I103 -> 0.11535179 | H23: =+'Cambio uso de suelo (BAU)'!J103 -> 0.067500769 | I23: =+'Cambio uso de suelo (BAU)'!K103 -> 0.089231345 | ... N23: =+'Cambio uso de suelo (BAU)'!P103 -> 0.029874591
A24: Moretal | B24: =+'Cambio uso de suelo (BAU)'!D104 -> 0.68248625 | C24: =+'Cambio uso de suelo (BAU)'!E104 -> 0.68248625 | D24: =+'Cambio uso de suelo (BAU)'!F104 -> 0.68248625 | E24: =+'Cambio uso de suelo (BAU)'!G104 -> 0.68248625 | F24: =+'Cambio uso de suelo (BAU)'!H104 -> 0.68248625 | G24: =+'Cambio uso de suelo (BAU)'!I104 -> 0.48238146 | H24: =+'Cambio uso de suelo (BAU)'!J104 -> 0.28227666 | I24: =+'Cambio uso de suelo (BAU)'!K104 -> 0.37315021 | ... N24: =+'Cambio uso de suelo (BAU)'!P104 -> 0.12493043
A26: EAR | B26: 2010 | C26: 2011 | D26: 2012 | E26: 2013 | F26: 2014 | G26: 2015 | H26: 2016 | I26: 2017 | J26: 2018 | K26: 2019 | L26: 2020 | M26: 2021 | N26: 2022
A27: SUPCAMCROAND | B27: =+B3/B16 -> -20.629858 | C27: =+C3/C16 -> -20.629858 | D27: =+D3/D16 -> -20.629858 | E27: =+E3/E16 -> -20.629858 | F27: =+F3/F16 -> -20.629858 | G27: =+G3/G16 -> -20.629858 | H27: =+H3/H16 -> -20.629858 | I27: =+I3/I16 -> -20.629858 | ... N27: =+N3/N16 -> -20.629858
A28: SUPCAMCROPLU | B28: =+B4/B17 -> -20.629858 | C28: =+C4/C17 -> -20.629858 | D28: =+D4/D17 -> -20.629858 | E28: =+E4/E17 -> -20.629858 | F28: =+F4/F17 -> -20.629858 | G28: =+G4/G17 -> -20.629858 | H28: =+H4/H17 -> -20.629858 | I28: =+I4/I17 -> -20.629858 | ... N28: =+N4/N17 -> -20.629858
A29: SUPCAMCROMON | B29: =+B5/B18 -> -20.629858 | C29: =+C5/C18 -> -20.629858 | D29: =+D5/D18 -> -20.629858 | E29: =+E5/E18 -> -20.629858 | F29: =+F5/F18 -> -20.629858 | G29: =+G5/G18 -> -20.629858 | H29: =+H5/H18 -> -20.629858 | I29: =+I5/I18 -> -20.629858 | ... N29: =+N5/N18 -> -20.629858
A30: SUPCAMCROPIE | B30: =+B6/B19 -> -20.629858 | C30: =+C6/C19 -> -20.629858 | D30: =+D6/D19 -> -20.629858 | E30: =+E6/E19 -> -20.629858 | F30: =+F6/F19 -> -20.629858 | G30: =+G6/G19 -> -20.629858 | H30: =+H6/H19 -> -20.629858 | I30: =+I6/I19 -> -20.629858 | ... N30: =+N6/N19 -> -20.629858
A31: SUPCAMCROCEJ | B31: =+B7/B20 -> -20.629858 | C31: =+C7/C20 -> -20.629858 | D31: =+D7/D20 -> -20.629858 | E31: =+E7/E20 -> -20.629858 | F31: =+F7/F20 -> -20.629858 | G31: =+G7/G20 -> -20.629858 | H31: =+H7/H20 -> -20.629858 | I31: =+I7/I20 -> -20.629858 | ... N31: =+N7/N20 -> -20.629858
A32: SUPCAMCROAMA | B32: =+B8/B21 -> -20.629858 | C32: =+C8/C21 -> -20.629858 | D32: =+D8/D21 -> -20.629858 | E32: =+E8/E21 -> -20.629858 | F32: =+F8/F21 -> -20.629858 | G32: =+G8/G21 -> -20.629858 | H32: =+H8/H21 -> -20.629858 | I32: =+I8/I21 -> -20.629858 | ... N32: =+N8/N21 -> -20.629858
A33: SUPCAMCROCHO | B33: =+B9/B22 -> -20.629858 | C33: =+C9/C22 -> -20.629858 | D33: =+D9/D22 -> -20.629858 | E33: =+E9/E22 -> -20.629858 | F33: =+F9/F22 -> -20.629858 | G33: =+G9/G22 -> -20.629858 | H33: =+H9/H22 -> -20.629858 | I33: =+I9/I22 -> -20.629858 | ... N33: =+N9/N22 -> -20.629858
A34: SUPCAMCROMAN | B34: =+B10/B23 -> -20.629858 | C34: =+C10/C23 -> -20.629858 | D34: =+D10/D23 -> -20.629858 | E34: =+E10/E23 -> -20.629858 | F34: =+F10/F23 -> -20.629858 | G34: =+G10/G23 -> -20.629858 | H34: =+H10/H23 -> -20.629858 | I34: =+I10/I23 -> -20.629858 | ... N34: =+N10/N23 -> -20.629858
A35: SUPCAMCROMOR | B35: =+B11/B24 -> -20.629858 | C35: =+C11/C24 -> -20.629858 | D35: =+D11/D24 -> -20.629858 | E35: =+E11/E24 -> -20.629858 | F35: =+F11/F24 -> -20.629858 | G35: =+G11/G24 -> -20.629858 | H35: =+H11/H24 -> -20.629858 | I35: =+I11/I24 -> -20.629858 | ... N35: =+N11/N24 -> -20.629858
A38: HUM a FOR | B38: =+INGEI_diffs!C6/1000 -> -0.76330476 | C38: =+INGEI_diffs!D6/1000 -> -0.76330476 | D38: =+INGEI_diffs!E6/1000 -> -0.76330476 | E38: =+INGEI_diffs!F6/1000 -> -0.76330476 | F38: =+INGEI_diffs!G6/1000 -> -0.76330476 | G38: =+INGEI_diffs!H6/1000 -> -0.80724636 | H38: =+INGEI_diffs!I6/1000 -> -0.85118795 | I38: =+INGEI_diffs!J6/1000 -> -0.61033436 | ... N38: =+INGEI_diffs!O6/1000 -> -0.25065278
A39: Emisiones(miles de tonCO2e) | B39: 2010 | C39: 2011 | D39: 2012 | E39: 2013 | F39: 2014 | G39: 2015 | H39: 2016 | I39: 2017 | J39: 2018 | K39: 2019 | L39: 2020 | M39: 2021 | N39: 2022
A40: B. Seco Andino | B40: =+'5ta'!$R87*'Emisiones Tierras forestales'!B$38 -> -0.0018709411 | C40: =+'5ta'!$R87*'Emisiones Tierras forestales'!C$38 -> -0.0018709411 | D40: =+'5ta'!$R87*'Emisiones Tierras forestales'!D$38 -> -0.0018709411 | E40: =+'5ta'!$R87*'Emisiones Tierras forestales'!E$38 -> -0.0018709411 | F40: =+'5ta'!$R87*'Emisiones Tierras forestales'!F$38 -> -0.0018709411 | G40: =+'5ta'!$R87*'Emisiones Tierras forestales'!G$38 -> -0.0019786466 | H40: =+'5ta'!$R87*'Emisiones Tierras forestales'!H$38 -> -0.0020863521 | I40: =+'5ta'!$R87*'Emisiones Tierras forestales'!I$38 -> -0.0014959944 | ... N40: =+'5ta'!$R87*'Emisiones Tierras forestales'!N$38 -> -0.00061437659
A41: B. Seco Pluvioestacional | B41: =+'5ta'!$R88*'Emisiones Tierras forestales'!B$38 -> -0.018270087 | C41: =+'5ta'!$R88*'Emisiones Tierras forestales'!C$38 -> -0.018270087 | D41: =+'5ta'!$R88*'Emisiones Tierras forestales'!D$38 -> -0.018270087 | E41: =+'5ta'!$R88*'Emisiones Tierras forestales'!E$38 -> -0.018270087 | F41: =+'5ta'!$R88*'Emisiones Tierras forestales'!F$38 -> -0.018270087 | G41: =+'5ta'!$R88*'Emisiones Tierras forestales'!G$38 -> -0.019321852 | H41: =+'5ta'!$R88*'Emisiones Tierras forestales'!H$38 -> -0.020373616 | I41: =+'5ta'!$R88*'Emisiones Tierras forestales'!I$38 -> -0.014608663 | ... N41: =+'5ta'!$R88*'Emisiones Tierras forestales'!N$38 -> -0.0059995016
A42: B. Siempre verde andino Montano | B42: =+'5ta'!$R89*'Emisiones Tierras forestales'!B$38 -> -0.17470036 | C42: =+'5ta'!$R89*'Emisiones Tierras forestales'!C$38 -> -0.17470036 | D42: =+'5ta'!$R89*'Emisiones Tierras forestales'!D$38 -> -0.17470036 | E42: =+'5ta'!$R89*'Emisiones Tierras forestales'!E$38 -> -0.17470036 | F42: =+'5ta'!$R89*'Emisiones Tierras forestales'!F$38 -> -0.17470036 | G42: =+'5ta'!$R89*'Emisiones Tierras forestales'!G$38 -> -0.18475743 | H42: =+'5ta'!$R89*'Emisiones Tierras forestales'!H$38 -> -0.19481451 | I42: =+'5ta'!$R89*'Emisiones Tierras forestales'!I$38 -> -0.13968946 | ... N42: =+'5ta'!$R89*'Emisiones Tierras forestales'!N$38 -> -0.057367821
A43: B. Siempre verde andino Pie montano | B43: =+'5ta'!$R90*'Emisiones Tierras forestales'!B$38 -> -0.07101457 | C43: =+'5ta'!$R90*'Emisiones Tierras forestales'!C$38 -> -0.07101457 | D43: =+'5ta'!$R90*'Emisiones Tierras forestales'!D$38 -> -0.07101457 | E43: =+'5ta'!$R90*'Emisiones Tierras forestales'!E$38 -> -0.07101457 | F43: =+'5ta'!$R90*'Emisiones Tierras forestales'!F$38 -> -0.07101457 | G43: =+'5ta'!$R90*'Emisiones Tierras forestales'!G$38 -> -0.075102706 | H43: =+'5ta'!$R90*'Emisiones Tierras forestales'!H$38 -> -0.079190842 | I43: =+'5ta'!$R90*'Emisiones Tierras forestales'!I$38 -> -0.056782866 | ... N43: =+'5ta'!$R90*'Emisiones Tierras forestales'!N$38 -> -0.023319649
A44: B. Siempre verde andino de Ceja Andina | B44: =+'5ta'!$R91*'Emisiones Tierras forestales'!B$38 -> -0.048905895 | C44: =+'5ta'!$R91*'Emisiones Tierras forestales'!C$38 -> -0.048905895 | D44: =+'5ta'!$R91*'Emisiones Tierras forestales'!D$38 -> -0.048905895 | E44: =+'5ta'!$R91*'Emisiones Tierras forestales'!E$38 -> -0.048905895 | F44: =+'5ta'!$R91*'Emisiones Tierras forestales'!F$38 -> -0.048905895 | G44: =+'5ta'!$R91*'Emisiones Tierras forestales'!G$38 -> -0.051721289 | H44: =+'5ta'!$R91*'Emisiones Tierras forestales'!H$38 -> -0.054536682 | I44: =+'5ta'!$R91*'Emisiones Tierras forestales'!I$38 -> -0.03910489 | ... N44: =+'5ta'!$R91*'Emisiones Tierras forestales'!N$38 -> -0.016059639
...

Sheet Forestales
A1: Emisiones | B1: =+INGEI_diffs!C2/1000 -> -19217.574 | C1: =+INGEI_diffs!D2/1000 -> -20027.829 | D1: =+INGEI_diffs!E2/1000 -> -20838.084 | E1: =+INGEI_diffs!F2/1000 -> -22648.214 | F1: =+INGEI_diffs!G2/1000 -> -24458.345 | G1: =+INGEI_diffs!H2/1000 -> -22793.711 | H1: =+INGEI_diffs!I2/1000 -> -21129.078 | I1: =+INGEI_diffs!J2/1000 -> -22396.71 | ... N1: =+INGEI_diffs!O2/1000 -> -18652.838
A2: Emisiones(miles de tonCO2e) | B2: 2010 | C2: 2011 | D2: 2012 | E2: 2013 | F2: 2014 | G2: 2015 | H2: 2016 | I2: 2017 | J2: 2018 | K2: 2019 | L2: 2020 | M2: 2021 | N2: 2022
A3: B. Seco Andino | B3: =+B$1*'5ta'!$R87 -> -47.104315 | C3: =+C$1*'5ta'!$R87 -> -49.090336 | D3: =+D$1*'5ta'!$R87 -> -51.076357 | E3: =+E$1*'5ta'!$R87 -> -55.513179 | F3: =+F$1*'5ta'!$R87 -> -59.950001 | G3: =+G$1*'5ta'!$R87 -> -55.869808 | H3: =+H$1*'5ta'!$R87 -> -51.789615 | I3: =+I$1*'5ta'!$R87 -> -54.896715 | ... N3: =+N$1*'5ta'!$R87 -> -45.720089
A4: B. Seco Pluvioestacional | B4: =+B$1*'5ta'!$R88 -> -459.98239 | C4: =+C$1*'5ta'!$R88 -> -479.37626 | D4: =+D$1*'5ta'!$R88 -> -498.77012 | E4: =+E$1*'5ta'!$R88 -> -542.09651 | F4: =+F$1*'5ta'!$R88 -> -585.4229 | G4: =+G$1*'5ta'!$R88 -> -545.57906 | H4: =+H$1*'5ta'!$R88 -> -505.73522 | I4: =+I$1*'5ta'!$R88 -> -536.07663 | ... N4: =+N$1*'5ta'!$R88 -> -446.46516
A5: B. Siempre verde andino Montano | B5: =+B$1*'5ta'!$R89 -> -4398.3966 | C5: =+C$1*'5ta'!$R89 -> -4583.8426 | D5: =+D$1*'5ta'!$R89 -> -4769.2886 | E5: =+E$1*'5ta'!$R89 -> -5183.5799 | F5: =+F$1*'5ta'!$R89 -> -5597.8711 | G5: =+G$1*'5ta'!$R89 -> -5216.8803 | H5: =+H$1*'5ta'!$R89 -> -4835.8896 | I5: =+I$1*'5ta'!$R89 -> -5126.0172 | ... N5: =+N$1*'5ta'!$R89 -> -4269.1436
A6: B. Siempre verde andino Pie montano | B6: =+B$1*'5ta'!$R90 -> -1787.9199 | C6: =+C$1*'5ta'!$R90 -> -1863.3025 | D6: =+D$1*'5ta'!$R90 -> -1938.6851 | E6: =+E$1*'5ta'!$R90 -> -2107.0918 | F6: =+F$1*'5ta'!$R90 -> -2275.4985 | G6: =+G$1*'5ta'!$R90 -> -2120.6282 | H6: =+H$1*'5ta'!$R90 -> -1965.7579 | I6: =+I$1*'5ta'!$R90 -> -2083.6929 | ... N6: =+N$1*'5ta'!$R90 -> -1735.3793
A7: B. Siempre verde andino de Ceja Andina | B7: =+B$1*'5ta'!$R91 -> -1231.2941 | C7: =+C$1*'5ta'!$R91 -> -1283.2082 | D7: =+D$1*'5ta'!$R91 -> -1335.1222 | E7: =+E$1*'5ta'!$R91 -> -1451.0995 | F7: =+F$1*'5ta'!$R91 -> -1567.0769 | G7: =+G$1*'5ta'!$R91 -> -1460.4217 | H7: =+H$1*'5ta'!$R91 -> -1353.7666 | I7: =+I$1*'5ta'!$R91 -> -1434.9854 | ... N7: =+N$1*'5ta'!$R91 -> -1195.1108
A8: B. Siempre verde de tierras bajas de la Amazonía | B8: =+B$1*'5ta'!$R92 -> -9009.9912 | C8: =+C$1*'5ta'!$R92 -> -9389.8721 | D8: =+D$1*'5ta'!$R92 -> -9769.753 | E8: =+E$1*'5ta'!$R92 -> -10618.417 | F8: =+F$1*'5ta'!$R92 -> -11467.081 | G8: =+G$1*'5ta'!$R92 -> -10686.632 | H8: =+H$1*'5ta'!$R92 -> -9906.1832 | I8: =+I$1*'5ta'!$R92 -> -10500.501 | ... N8: =+N$1*'5ta'!$R92 -> -8745.2199
A9: B. Siempre verde de tierras bajas del Chocó | B9: =+B$1*'5ta'!$R93 -> -998.23657 | C9: =+C$1*'5ta'!$R93 -> -1040.3244 | D9: =+D$1*'5ta'!$R93 -> -1082.4122 | E9: =+E$1*'5ta'!$R93 -> -1176.4375 | F9: =+F$1*'5ta'!$R93 -> -1270.4629 | G9: =+G$1*'5ta'!$R93 -> -1183.9952 | H9: =+H$1*'5ta'!$R93 -> -1097.5276 | I9: =+I$1*'5ta'!$R93 -> -1163.3734 | ... N9: =+N$1*'5ta'!$R93 -> -968.90198
A10: Manglar | B10: =+B$1*'5ta'!$R94 -> -247.91418 | C10: =+C$1*'5ta'!$R94 -> -258.36678 | D10: =+D$1*'5ta'!$R94 -> -268.81938 | E10: =+E$1*'5ta'!$R94 -> -292.17077 | F10: =+F$1*'5ta'!$R94 -> -315.52216 | G10: =+G$1*'5ta'!$R94 -> -294.04774 | H10: =+H$1*'5ta'!$R94 -> -272.57332 | I10: =+I$1*'5ta'!$R94 -> -288.92627 | ... N10: =+N$1*'5ta'!$R94 -> -240.62887
A11: Moretal | B11: =+B$1*'5ta'!$R95 -> -1036.7346 | C11: =+C$1*'5ta'!$R95 -> -1080.4456 | D11: =+D$1*'5ta'!$R95 -> -1124.1566 | E11: =+E$1*'5ta'!$R95 -> -1221.8081 | F11: =+F$1*'5ta'!$R95 -> -1319.4597 | G11: =+G$1*'5ta'!$R95 -> -1229.6573 | H11: =+H$1*'5ta'!$R95 -> -1139.855 | I11: =+I$1*'5ta'!$R95 -> -1208.2402 | ... N11: =+N$1*'5ta'!$R95 -> -1006.2687
A12: Total | B12: =+SUM(B3:B11) -> -19217.574 | C12: =+SUM(C3:C11) -> -20027.829 | D12: =+SUM(D3:D11) -> -20838.084 | E12: =+SUM(E3:E11) -> -22648.214 | F12: =+SUM(F3:F11) -> -24458.345 | G12: =+SUM(G3:G11) -> -22793.711 | H12: =+SUM(H3:H11) -> -21129.078 | I12: =+SUM(I3:I11) -> -22396.71 | ... N12: =+SUM(N3:N11) -> -18652.838
A14: Cobertura
A15: B. Seco Andino | B15: 12.34832 | C15: 13.402625 | D15: 14.45693 | E15: 14.58446 | F15: 14.71199 | G15: 14.75553 | H15: 14.79907 | I15: 14.779865 | J15: 14.76066 | K15: 14.76066 | L15: 14.76066 | M15: 13.635 | N15: 13.635
A16: B. Seco Pluvioestacional | B16: 120.58364 | C16: 126.21503 | D16: 131.84642 | E16: 136.0105 | F16: 140.17458 | G16: 140.00463 | H16: 139.83467 | I16: 139.85384 | J16: 139.87301 | K16: 139.87301 | L16: 139.87301 | M16: 139.386 | N16: 139.386
A17: B. Siempre verde andino Montano | B17: 1153.0326 | C17: 1158.7426 | D17: 1164.4526 | E17: 1198.6502 | F17: 1232.8479 | G17: 1233.7965 | H17: 1234.7451 | I17: 1245.5305 | J17: 1256.3159 | K17: 1256.3159 | L17: 1256.3159 | M17: 1257.518 | N17: 1257.518
A18: B. Siempre verde andino Pie montano | B18: 468.7003 | C18: 469.70792 | D18: 470.71555 | E18: 488.97563 | F18: 507.23571 | G18: 506.69036 | H18: 506.14502 | I18: 514.64234 | J18: 523.13965 | K18: 523.13965 | L18: 523.13965 | M18: 515.144 | N18: 515.144
A19: B. Siempre verde andino de Ceja Andina | B19: 322.78176 | C19: 325.37089 | D19: 327.96002 | E19: 333.55776 | F19: 339.1555 | G19: 340.20731 | H19: 341.25912 | I19: 357.94489 | J19: 374.63066 | K19: 374.63066 | L19: 374.63066 | M19: 375.109 | N19: 375.109
A20: B. Siempre verde de tierras bajas de la Amazonía | B20: 2361.9546 | C20: 2536.3038 | D20: 2710.653 | E20: 2768.5834 | F20: 2826.5138 | G20: 2858.7582 | H20: 2891.0026 | I20: 2955.7263 | J20: 3020.45 | K20: 3020.45 | L20: 3020.45 | M20: 2928.882 | N20: 2928.882
A21: B. Siempre verde de tierras bajas del Chocó | B21: 261.6861 | C21: 263.6224 | D21: 265.5587 | E21: 269.70002 | F21: 273.84134 | G21: 268.73808 | H21: 263.63481 | I21: 262.9087 | J21: 262.1826 | K21: 262.1826 | L21: 262.1826 | M21: 240.487 | N21: 240.487
A22: Manglar | B22: 64.9903 | C22: 65.335185 | D22: 65.68007 | E22: 64.106675 | F22: 62.53328 | G22: 65.73885 | H22: 68.94442 | I22: 68.62894 | J22: 68.31346 | K22: 68.31346 | L22: 68.31346 | M22: 98.087 | N22: 98.087
A23: Moretal | B23: 271.77831 | C23: 272.68514 | D23: 273.59197 | E23: 278.16317 | F23: 282.73438 | G23: 289.39154 | H23: 296.0487 | I23: 298.13771 | J23: 300.22673 | K23: 300.22673 | L23: 300.22673 | M23: 272.847 | N23: 272.847
A25: EAR
A26: B. Seco Andino | B26: =+B3/B15 -> -3.8146335 | C26: =+C3/C15 -> -3.6627404 | D26: =+D3/D15 -> -3.5330016 | E26: =+E3/E15 -> -3.8063239 | F26: =+F3/F15 -> -4.0749077 | G26: =+G3/G15 -> -3.786364 | H26: =+H3/H15 -> -3.4995182 | I26: =+I3/I15 -> -3.7142907 | ... N26: =+N3/N15 -> -3.3531418
A27: B. Seco Pluvioestacional | B27: =+B4/B16 -> -3.8146335 | C27: =+C4/C16 -> -3.7980917 | D27: =+D4/D16 -> -3.7829629 | E27: =+E4/E16 -> -3.985696 | F27: =+F4/F16 -> -4.1763842 | G27: =+G4/G16 -> -3.8968646 | H27: =+H4/H16 -> -3.6166654 | I27: =+I4/I16 -> -3.8331206 | ... N27: =+N4/N16 -> -3.2030847
A28: B. Siempre verde andino Montano | B28: =+B5/B17 -> -3.8146335 | C28: =+C5/C17 -> -3.9558766 | D28: =+D5/D17 -> -4.0957346 | E28: =+E5/E17 -> -4.3245141 | F28: =+F5/F17 -> -4.5406015 | G28: =+G5/G17 -> -4.228315 | H28: =+H5/H17 -> -3.9165084 | I28: =+I5/I17 -> -4.1155292 | ... N28: =+N5/N17 -> -3.3948966
A29: B. Siempre verde andino Pie montano | B29: =+B6/B18 -> -3.8146335 | C29: =+C6/C18 -> -3.9669385 | D29: =+D6/D18 -> -4.1185915 | E29: =+E6/E18 -> -4.3091959 | F29: =+F6/F18 -> -4.4860771 | G29: =+G6/G18 -> -4.1852547 | H29: =+H6/H18 -> -3.883784 | I29: =+I6/I18 -> -4.0488175 | ... N29: =+N6/N18 -> -3.3687267
A30: B. Siempre verde andino de Ceja Andina | B30: =+B7/B19 -> -3.8146335 | C30: =+C7/C19 -> -3.9438321 | D30: =+D7/D19 -> -4.0709908 | E30: =+E7/E19 -> -4.3503696 | F30: =+F7/F19 -> -4.6205262 | G30: =+G7/G19 -> -4.2927406 | H30: =+H7/H19 -> -3.9669756 | I30: =+I7/I19 -> -4.0089561 | ... N30: =+N7/N19 -> -3.1860361
