Workbook

Sheet Calibración-UTCUTS_Osemosys
B1: Referencia | F1: Ecuador | G1: 2008 | H1: 2009 | I1: 2010 | J1: 2011 | K1: 2012 | L1: 2013 | M1: 2014 | N1: 2015 | O1: 2016 | P1: 2017 | Q1: 2018 | R1: 2019 | S1: 2020 | T1: 2021 | U1: 2022 | V1: 2023 | W1: 2024 | X1: 2025 | Y1: 2026 | Z1: 2027 | AA1: 2028 | AB1: 2029 | AC1: 2030 | AD1: 2031 | AE1: 2032 | AF1: 2033 | AG1: 2034 | AH1: 2035 | AI1: 2036 | AJ1: 2037 | AK1: 2038 | AL1: 2039 | AM1: 2040 | AN1: 2041 | AO1: 2042 | AP1: 2043 | AQ1: 2044 | AR1: 2045 | AS1: 2046 | AT1: 2047 | AU1: 2048 | AV1: 2049 | AW1: 2050
D3: DATOS PARA CALIBRAR PROYECCIONES
E6: GRÁFICO UTCUTS-1 | F6: TABLA UTCUTS - 1: Cobertura uso de suelos
F7: Uso de suelos [ha]
B8: ESPAC | F8: Montes y bosques [ha] | I8: 3504127 | J8: 3536454 | K8: 3583056 | L8: 3538424 | M8: 5758859 | N8: 5729799 | O8: 5773290 | P8: 5675402 | Q8: 5740641 | R8: 6040896 | S8: 6112324 | T8: 5900560 | U8: 5900560 | V8: 5900560 | W8: 5900560 | X8: 5900560 | Y8: 5900560 | Z8: 5900560 | AA8: 5900560 | AB8: 5900560 | AC8: 5900560 | AD8: 5900560 | AE8: 5900560 | AF8: 5900560 | AG8: 5900560 | AH8: 5900560 | AI8: 5900560 | AJ8: 5900560 | AK8: 5900560 | AL8: 5900560 | AM8: 5900560 | AN8: 5900560 | AO8: 5900560 | AP8: 5900560 | AQ8: 5900560 | AR8: 5900560 | AS8: 5900560 | AT8: 5900560 | AU8: 5900560 | AV8: 5900560 | AW8: 5900560
F9: Cultivos permanentes [ha] | I9: 1391379 | J9: 1379473 | K9: 1382918 | L9: 1469363 | M9: 1417104 | N9: 1483366 | O9: 1439117 | P9: 1430497 | Q9: 1385805 | R9: 1439504 | S9: 1442973 | T9: 1423372 | U9: 1423372 | V9: 1423372 | W9: 1423372 | X9: 1423372 | Y9: 1423372 | Z9: 1423372 | AA9: 1423372 | AB9: 1423372 | AC9: 1423372 | AD9: 1423372 | AE9: 1423372 | AF9: 1423372 | AG9: 1423372 | AH9: 1423372 | AI9: 1423372 | AJ9: 1423372 | AK9: 1423372 | AL9: 1423372 | AM9: 1423372 | AN9: 1423372 | AO9: 1423372 | AP9: 1423372 | AQ9: 1423372 | AR9: 1423372 | AS9: 1423372 | AT9: 1423372 | AU9: 1423372 | AV9: 1423372 | AW9: 1423372
F10: Cultivos transitorios y barbechos [ha] | I10: 992369 | J10: 982312 | K10: 1020870 | L10: 1003271 | M10: 876498 | N10: 950649 | O10: 849685 | P10: 904224 | Q10: 799494 | R10: 769708 | S10: 822516 | T10: 841994 | U10: 841994 | V10: 841994 | W10: 841994 | X10: 841994 | Y10: 841994 | Z10: 841994 | AA10: 841994 | AB10: 841994 | AC10: 841994 | AD10: 841994 | AE10: 841994 | AF10: 841994 | AG10: 841994 | AH10: 841994 | AI10: 841994 | AJ10: 841994 | AK10: 841994 | AL10: 841994 | AM10: 841994 | AN10: 841994 | AO10: 841994 | AP10: 841994 | AQ10: 841994 | AR10: 841994 | AS10: 841994 | AT10: 841994 | AU10: 841994 | AV10: 841994 | AW10: 841994
F11: Descanso [ha] | I11: 193957 | J11: 173442 | K11: 126982 | L11: 191159 | M11: 93574 | N11: 117390 | O11: 125946 | P11: 129268 | Q11: 168446 | R11: 219492 | S11: 215014 | T11: 163017 | U11: 163017 | V11: 163017 | W11: 163017 | X11: 163017 | Y11: 163017 | Z11: 163017 | AA11: 163017 | AB11: 163017 | AC11: 163017 | AD11: 163017 | AE11: 163017 | AF11: 163017 | AG11: 163017 | AH11: 163017 | AI11: 163017 | AJ11: 163017 | AK11: 163017 | AL11: 163017 | AM11: 163017 | AN11: 163017 | AO11: 163017 | AP11: 163017 | AQ11: 163017 | AR11: 163017 | AS11: 163017 | AT11: 163017 | AU11: 163017 | AV11: 163017 | AW11: 163017
F12: Otros usos [ha] | I12: 217058 | J12: 210584 | K12: 205657 | L12: 216225 | M12: 468180 | N12: 612090 | O12: 719109 | P12: 757791 | Q12: 796518 | R12: 662305 | S12: 681476 | T12: 712757 | U12: 712757 | V12: 712757 | W12: 712757 | X12: 712757 | Y12: 712757 | Z12: 712757 | AA12: 712757 | AB12: 712757 | AC12: 712757 | AD12: 712757 | AE12: 712757 | AF12: 712757 | AG12: 712757 | AH12: 712757 | AI12: 712757 | AJ12: 712757 | AK12: 712757 | AL12: 712757 | AM12: 712757 | AN12: 712757 | AO12: 712757 | AP12: 712757 | AQ12: 712757 | AR12: 712757 | AS12: 712757 | AT12: 712757 | AU12: 712757 | AV12: 712757 | AW12: 712757
F13: Páramos [ha] | I13: 539475 | J13: 565857 | K13: 608272 | L13: 491891 | M13: 499258 | N13: 454347 | O13: 377791 | P13: 332418 | Q13: 252612 | R13: 270986 | S13: 249139 | T13: 233074 | U13: 233074 | V13: 233074 | W13: 233074 | X13: 233074 | Y13: 233074 | Z13: 233074 | AA13: 233074 | AB13: 233074 | AC13: 233074 | AD13: 233074 | AE13: 233074 | AF13: 233074 | AG13: 233074 | AH13: 233074 | AI13: 233074 | AJ13: 233074 | AK13: 233074 | AL13: 233074 | AM13: 233074 | AN13: 233074 | AO13: 233074 | AP13: 233074 | AQ13: 233074 | AR13: 233074 | AS13: 233074 | AT13: 233074 | AU13: 233074 | AV13: 233074 | AW13: 233074
F14: Pastos cultivados [ha] | I14: 3409952 | J14: 3425412 | K14: 3553008 | L14: 3227321 | M14: 2259447 | N14: 2531442 | O14: 2300539 | P14: 2447634 | Q14: 2379042 | R14: 1985494 | S14: 2067795 | T14: 2376551 | U14: 2376551 | V14: 2376551 | W14: 2376551 | X14: 2376551 | Y14: 2376551 | Z14: 2376551 | AA14: 2376551 | AB14: 2376551 | AC14: 2376551 | AD14: 2376551 | AE14: 2376551 | AF14: 2376551 | AG14: 2376551 | AH14: 2376551 | AI14: 2376551 | AJ14: 2376551 | AK14: 2376551 | AL14: 2376551 | AM14: 2376551 | AN14: 2376551 | AO14: 2376551 | AP14: 2376551 | AQ14: 2376551 | AR14: 2376551 | AS14: 2376551 | AT14: 2376551 | AU14: 2376551 | AV14: 2376551 | AW14: 2376551
F15: Pastos permanentes [ha] | I15: 1509972 | J15: 1385547 | K15: 1423114 | L15: 1623359 | M15: 828333 | N15: 706777 | O15: 800496 | P15: 677911 | Q15: 715273 | R15: 915843 | S15: 841320 | T15: 646139 | U15: 646139 | V15: 646139 | W15: 646139 | X15: 646139 | Y15: 646139 | Z15: 646139 | AA15: 646139 | AB15: 646139 | AC15: 646139 | AD15: 646139 | AE15: 646139 | AF15: 646139 | AG15: 646139 | AH15: 646139 | AI15: 646139 | AJ15: 646139 | AK15: 646139 | AL15: 646139 | AM15: 646139 | AN15: 646139 | AO15: 646139 | AP15: 646139 | AQ15: 646139 | AR15: 646139 | AS15: 646139 | AT15: 646139 | AU15: 646139 | AV15: 646139 | AW15: 646139
F16: Uso de suelos [Mha]
B17: ESPAC | F17: Montes y bosques [Mha] | I17: =I8/1000000 -> 3.504127 | J17: =J8/1000000 -> 3.536454 | K17: =K8/1000000 -> 3.583056 | L17: =L8/1000000 -> 3.538424 | M17: =M8/1000000 -> 5.758859 | N17: =N8/1000000 -> 5.729799 | O17: =O8/1000000 -> 5.77329 | P17: =P8/1000000 -> 5.675402 | ... AW17: =AW8/1000000 -> 5.90056
F18: Cultivos permanentes [Mha] | I18: =I9/1000000 -> 1.391379 | J18: =J9/1000000 -> 1.379473 | K18: =K9/1000000 -> 1.382918 | L18: =L9/1000000 -> 1.469363 | M18: =M9/1000000 -> 1.417104 | N18: =N9/1000000 -> 1.483366 | O18: =O9/1000000 -> 1.439117 | P18: =P9/1000000 -> 1.430497 | ... AW18: =AW9/1000000 -> 1.423372
F19: Cultivos transitorios y barbechos [Mha] | I19: =I10/1000000 -> 0.992369 | J19: =J10/1000000 -> 0.982312 | K19: =K10/1000000 -> 1.02087 | L19: =L10/1000000 -> 1.003271 | M19: =M10/1000000 -> 0.876498 | N19: =N10/1000000 -> 0.950649 | O19: =O10/1000000 -> 0.849685 | P19: =P10/1000000 -> 0.904224 | ... AW19: =AW10/1000000 -> 0.841994
F20: Descanso [Mha] | I20: =I11/1000000 -> 0.193957 | J20: =J11/1000000 -> 0.173442 | K20: =K11/1000000 -> 0.126982 | L20: =L11/1000000 -> 0.191159 | M20: =M11/1000000 -> 0.093574 | N20: =N11/1000000 -> 0.11739 | O20: =O11/1000000 -> 0.125946 | P20: =P11/1000000 -> 0.129268 | ... AW20: =AW11/1000000 -> 0.163017
F21: Otros usos [Mha] | I21: =I12/1000000 -> 0.217058 | J21: =J12/1000000 -> 0.210584 | K21: =K12/1000000 -> 0.205657 | L21: =L12/1000000 -> 0.216225 | M21: =M12/1000000 -> 0.46818 | N21: =N12/1000000 -> 0.61209 | O21: =O12/1000000 -> 0.719109 | P21: =P12/1000000 -> 0.757791 | ... AW21: =AW12/1000000 -> 0.712757
F22: Páramos [Mha] | I22: =I13/1000000 -> 0.539475 | J22: =J13/1000000 -> 0.565857 | K22: =K13/1000000 -> 0.608272 | L22: =L13/1000000 -> 0.491891 | M22: =M13/1000000 -> 0.499258 | N22: =N13/1000000 -> 0.454347 | O22: =O13/1000000 -> 0.377791 | P22: =P13/1000000 -> 0.332418 | ... AW22: =AW13/1000000 -> 0.233074
F23: Pastos cultivados [Mha] | I23: =I14/1000000 -> 3.409952 | J23: =J14/1000000 -> 3.425412 | K23: =K14/1000000 -> 3.553008 | L23: =L14/1000000 -> 3.227321 | M23: =M14/1000000 -> 2.259447 | N23: =N14/1000000 -> 2.531442 | O23: =O14/1000000 -> 2.300539 | P23: =P14/1000000 -> 2.447634 | ... AW23: =AW14/1000000 -> 2.376551
F24: Pastos permanentes [Mha] | I24: =I15/1000000 -> 1.509972 | J24: =J15/1000000 -> 1.385547 | K24: =K15/1000000 -> 1.423114 | L24: =L15/1000000 -> 1.623359 | M24: =M15/1000000 -> 0.828333 | N24: =N15/1000000 -> 0.706777 | O24: =O15/1000000 -> 0.800496 | P24: =P15/1000000 -> 0.677911 | ... AW24: =AW15/1000000 -> 0.646139
F25: TOTAL COBERTURAS [Mha] | I25: =SUM(I17:I24) -> 11.758289 | J25: =SUM(J17:J24) -> 11.659081 | K25: =SUM(K17:K24) -> 11.903877 | L25: =SUM(L17:L24) -> 11.761013 | M25: =SUM(M17:M24) -> 12.201253 | N25: =SUM(N17:N24) -> 12.58586 | O25: =SUM(O17:O24) -> 12.385973 | P25: =SUM(P17:P24) -> 12.355145 | ... AW25: =SUM(AW17:AW24) -> 12.297464
D28: DATOS ÁREAS PROTEGIDAS
E31: GRÁFICO UTCUTS-1 | F31: TABLA UTCUTS - 2: Cobertura áreas protegidas
F32: Áreas protegidas [Mha]
B33: SNAP | F33: Galápagos [Mha] | I33: 0.79579217 | J33: 0.79579217 | K33: 0.79579217 | L33: 0.79579217 | M33: 0.79579217 | N33: 0.79579217 | O33: 0.79579217 | P33: 0.79579217 | Q33: 0.79579217 | R33: 0.79579217 | S33: 0.79579217 | T33: 0.79579217 | U33: 0.79579217 | V33: 0.79579217 | W33: 0.79579217 | X33: 0.79579217 | Y33: 0.79579217 | Z33: 0.79579217 | AA33: 0.79579217 | AB33: 0.79579217 | AC33: 0.79579217 | AD33: 0.79579217 | AE33: 0.79579217 | AF33: 0.79579217 | AG33: 0.79579217 | AH33: 0.79579217 | AI33: 0.79579217 | AJ33: 0.79579217 | AK33: 0.79579217 | AL33: 0.79579217 | AM33: 0.79579217 | AN33: 0.79579217 | AO33: 0.79579217 | AP33: 0.79579217 | AQ33: 0.79579217 | AR33: 0.79579217 | AS33: 0.79579217 | AT33: 0.79579217 | AU33: 0.79579217 | AV33: 0.79579217 | AW33: 0.79579217
F34: Bosques protegidos/Protected forest [Mha] | I34: 2.2633933 | J34: 2.2794224 | K34: 2.2794224 | L34: 2.2794224 | M34: 2.3725857 | N34: 2.3725857 | O34: 2.3747312 | P34: 2.3747312 | Q34: 2.4084734 | R34: 2.4088211 | S34: 2.4088211 | T34: 2.4117235 | U34: 2.4117235 | V34: 2.4117235 | W34: 2.4117235 | X34: 2.4117235 | Y34: 2.4117235 | Z34: 2.4117235 | AA34: 2.4117235 | AB34: 2.4117235 | AC34: 2.4117235 | AD34: 2.4117235 | AE34: 2.4117235 | AF34: 2.4117235 | AG34: 2.4117235 | AH34: 2.4117235 | AI34: 2.4117235 | AJ34: 2.4117235 | AK34: 2.4117235 | AL34: 2.4117235 | AM34: 2.4117235 | AN34: 2.4117235 | AO34: 2.4117235 | AP34: 2.4117235 | AQ34: 2.4117235 | AR34: 2.4117235 | AS34: 2.4117235 | AT34: 2.4117235 | AU34: 2.4117235 | AV34: 2.4117235 | AW34: 2.4117235
F35: Pradera protegida/Protected grassland [Mha] | I35: 1.8351789 | J35: 1.8351789 | K35: 1.838396 | L35: 1.838396 | M35: 1.838396 | N35: 1.838396 | O35: 1.838396 | P35: 1.8914899 | Q35: 1.8934445 | R35: 1.922489 | S35: 1.9272792 | T35: 1.95791 | U35: 1.95791 | V35: 1.95791 | W35: 1.95791 | X35: 1.95791 | Y35: 1.95791 | Z35: 1.95791 | AA35: 1.95791 | AB35: 1.95791 | AC35: 1.95791 | AD35: 1.95791 | AE35: 1.95791 | AF35: 1.95791 | AG35: 1.95791 | AH35: 1.95791 | AI35: 1.95791 | AJ35: 1.95791 | AK35: 1.95791 | AL35: 1.95791 | AM35: 1.95791 | AN35: 1.95791 | AO35: 1.95791 | AP35: 1.95791 | AQ35: 1.95791 | AR35: 1.95791 | AS35: 1.95791 | AT35: 1.95791 | AU35: 1.95791 | AV35: 1.95791 | AW35: 1.95791
F36: Manglares [Mha] | I36: 0.37320953 | J36: 0.37568766 | K36: 0.38884296 | L36: 0.38884296 | M36: 0.38884296 | N36: 0.53110941 | O36: 0.57106191 | P36: 0.57106191 | Q36: 0.57106191 | R36: 0.57106191 | S36: 0.57106191 | T36: 0.57106191 | U36: 0.57106191 | V36: 0.57106191 | W36: 0.57106191 | X36: 0.57106191 | Y36: 0.57106191 | Z36: 0.57106191 | AA36: 0.57106191 | AB36: 0.57106191 | AC36: 0.57106191 | AD36: 0.57106191 | AE36: 0.57106191 | AF36: 0.57106191 | AG36: 0.57106191 | AH36: 0.57106191 | AI36: 0.57106191 | AJ36: 0.57106191 | AK36: 0.57106191 | AL36: 0.57106191 | AM36: 0.57106191 | AN36: 0.57106191 | AO36: 0.57106191 | AP36: 0.57106191 | AQ36: 0.57106191 | AR36: 0.57106191 | AS36: 0.57106191 | AT36: 0.57106191 | AU36: 0.57106191 | AV36: 0.57106191 | AW36: 0.57106191
D39: DATOS PARA MODELO OSEMOSYS
A41: Drivers
E42: GRÁFICO UTCUTS-1 | F42: TABLA UTCUTS - 3: Coberturas generales - MAG + MAATE
F43: Coberturas generales [ha]
B44: MAG+MAATE | D44: Bosque | F44: Bosque nativo [ha] | G44: 13038367 | M44: 12753387 | O44: 12631198 | Q44: 12514340
F45: Plantación forestal [ha] | G45: 62196.93 | M45: 130072.41 | O45: 123719.94 | Q45: 121995.27
D46: Tierra agropecuaria | F46: Cultivo anual [ha] | G46: 611941.95 | M46: 1094904.6 | O46: 8933864.5 | Q46: 8999553.2
F47: Cultivo semipermanente [ha] | G47: 260389.08 | M47: 480131.91
F48: Cultivo permanente [ha] | G48: 167305.59 | M48: 917407.35
F49: Pastizal [ha] | G49: 1454890.3 | M49: 4959938.7
F50: Mosaico agropecuario [ha] | G50: 6337045.3 | M50: 1266774.3
...

Sheet Calibración-UTCUTS2
B1: Referencia | F1: Ecuador | G1: 2008 | H1: 2009 | I1: 2010 | J1: 2011 | K1: 2012 | L1: 2013 | M1: 2014 | N1: 2015 | O1: 2016 | P1: 2017 | Q1: 2018 | R1: 2019 | S1: 2020 | T1: 2021 | U1: 2022 | V1: 2023 | W1: 2024 | X1: 2025 | Y1: 2026 | Z1: 2027 | AA1: 2028 | AB1: 2029 | AC1: 2030 | AD1: 2031 | AE1: 2032 | AF1: 2033 | AG1: 2034 | AH1: 2035 | AI1: 2036 | AJ1: 2037 | AK1: 2038 | AL1: 2039 | AM1: 2040 | AN1: 2041 | AO1: 2042 | AP1: 2043 | AQ1: 2044 | AR1: 2045 | AS1: 2046 | AT1: 2047 | AU1: 2048 | AV1: 2049 | AW1: 2050
D3: DATOS PARA CALIBRAR PROYECCIONES
E6: GRÁFICO UTCUTS-1 | F6: TABLA UTCUTS - 1: Cobertura uso de suelos
F7: Uso de suelos [ha]
B8: ESPAC | F8: Montes y bosques [ha] | I8: 3504127 | J8: 3536454 | K8: 3583056 | L8: 3538424 | M8: 5758859 | N8: 5729799 | O8: 5773290 | P8: 5675402 | Q8: 5740641 | R8: 6040896 | S8: 6112324 | T8: 5900560 | U8: 5900560 | V8: 5900560 | W8: 5900560 | X8: 5900560 | Y8: 5900560 | Z8: 5900560 | AA8: 5900560 | AB8: 5900560 | AC8: 5900560 | AD8: 5900560 | AE8: 5900560 | AF8: 5900560 | AG8: 5900560 | AH8: 5900560 | AI8: 5900560 | AJ8: 5900560 | AK8: 5900560 | AL8: 5900560 | AM8: 5900560 | AN8: 5900560 | AO8: 5900560 | AP8: 5900560 | AQ8: 5900560 | AR8: 5900560 | AS8: 5900560 | AT8: 5900560 | AU8: 5900560 | AV8: 5900560 | AW8: 5900560
F9: Cultivos permanentes [ha] | I9: 1391379 | J9: 1379473 | K9: 1382918 | L9: 1469363 | M9: 1417104 | N9: 1483366 | O9: 1439117 | P9: 1430497 | Q9: 1385805 | R9: 1439504 | S9: 1442973 | T9: 1423372 | U9: 1423372 | V9: 1423372 | W9: 1423372 | X9: 1423372 | Y9: 1423372 | Z9: 1423372 | AA9: 1423372 | AB9: 1423372 | AC9: 1423372 | AD9: 1423372 | AE9: 1423372 | AF9: 1423372 | AG9: 1423372 | AH9: 1423372 | AI9: 1423372 | AJ9: 1423372 | AK9: 1423372 | AL9: 1423372 | AM9: 1423372 | AN9: 1423372 | AO9: 1423372 | AP9: 1423372 | AQ9: 1423372 | AR9: 1423372 | AS9: 1423372 | AT9: 1423372 | AU9: 1423372 | AV9: 1423372 | AW9: 1423372
F10: Cultivos transitorios y barbechos [ha] | I10: 992369 | J10: 982312 | K10: 1020870 | L10: 1003271 | M10: 876498 | N10: 950649 | O10: 849685 | P10: 904224 | Q10: 799494 | R10: 769708 | S10: 822516 | T10: 841994 | U10: 841994 | V10: 841994 | W10: 841994 | X10: 841994 | Y10: 841994 | Z10: 841994 | AA10: 841994 | AB10: 841994 | AC10: 841994 | AD10: 841994 | AE10: 841994 | AF10: 841994 | AG10: 841994 | AH10: 841994 | AI10: 841994 | AJ10: 841994 | AK10: 841994 | AL10: 841994 | AM10: 841994 | AN10: 841994 | AO10: 841994 | AP10: 841994 | AQ10: 841994 | AR10: 841994 | AS10: 841994 | AT10: 841994 | AU10: 841994 | AV10: 841994 | AW10: 841994
F11: Descanso [ha] | I11: 193957 | J11: 173442 | K11: 126982 | L11: 191159 | M11: 93574 | N11: 117390 | O11: 125946 | P11: 129268 | Q11: 168446 | R11: 219492 | S11: 215014 | T11: 163017 | U11: 163017 | V11: 163017 | W11: 163017 | X11: 163017 | Y11: 163017 | Z11: 163017 | AA11: 163017 | AB11: 163017 | AC11: 163017 | AD11: 163017 | AE11: 163017 | AF11: 163017 | AG11: 163017 | AH11: 163017 | AI11: 163017 | AJ11: 163017 | AK11: 163017 | AL11: 163017 | AM11: 163017 | AN11: 163017 | AO11: 163017 | AP11: 163017 | AQ11: 163017 | AR11: 163017 | AS11: 163017 | AT11: 163017 | AU11: 163017 | AV11: 163017 | AW11: 163017
F12: Otros usos [ha] | I12: 217058 | J12: 210584 | K12: 205657 | L12: 216225 | M12: 468180 | N12: 612090 | O12: 719109 | P12: 757791 | Q12: 796518 | R12: 662305 | S12: 681476 | T12: 712757 | U12: 712757 | V12: 712757 | W12: 712757 | X12: 712757 | Y12: 712757 | Z12: 712757 | AA12: 712757 | AB12: 712757 | AC12: 712757 | AD12: 712757 | AE12: 712757 | AF12: 712757 | AG12: 712757 | AH12: 712757 | AI12: 712757 | AJ12: 712757 | AK12: 712757 | AL12: 712757 | AM12: 712757 | AN12: 712757 | AO12: 712757 | AP12: 712757 | AQ12: 712757 | AR12: 712757 | AS12: 712757 | AT12: 712757 | AU12: 712757 | AV12: 712757 | AW12: 712757
F13: Páramos [ha] | I13: 539475 | J13: 565857 | K13: 608272 | L13: 491891 | M13: 499258 | N13: 454347 | O13: 377791 | P13: 332418 | Q13: 252612 | R13: 270986 | S13: 249139 | T13: 233074 | U13: 233074 | V13: 233074 | W13: 233074 | X13: 233074 | Y13: 233074 | Z13: 233074 | AA13: 233074 | AB13: 233074 | AC13: 233074 | AD13: 233074 | AE13: 233074 | AF13: 233074 | AG13: 233074 | AH13: 233074 | AI13: 233074 | AJ13: 233074 | AK13: 233074 | AL13: 233074 | AM13: 233074 | AN13: 233074 | AO13: 233074 | AP13: 233074 | AQ13: 233074 | AR13: 233074 | AS13: 233074 | AT13: 233074 | AU13: 233074 | AV13: 233074 | AW13: 233074
F14: Pastos cultivados [ha] | I14: 3409952 | J14: 3425412 | K14: 3553008 | L14: 3227321 | M14: 2259447 | N14: 2531442 | O14: 2300539 | P14: 2447634 | Q14: 2379042 | R14: 1985494 | S14: 2067795 | T14: 2376551 | U14: 2376551 | V14: 2376551 | W14: 2376551 | X14: 2376551 | Y14: 2376551 | Z14: 2376551 | AA14: 2376551 | AB14: 2376551 | AC14: 2376551 | AD14: 2376551 | AE14: 2376551 | AF14: 2376551 | AG14: 2376551 | AH14: 2376551 | AI14: 2376551 | AJ14: 2376551 | AK14: 2376551 | AL14: 2376551 | AM14: 2376551 | AN14: 2376551 | AO14: 2376551 | AP14: 2376551 | AQ14: 2376551 | AR14: 2376551 | AS14: 2376551 | AT14: 2376551 | AU14: 2376551 | AV14: 2376551 | AW14: 2376551
F15: Pastos permanentes [ha] | I15: 1509972 | J15: 1385547 | K15: 1423114 | L15: 1623359 | M15: 828333 | N15: 706777 | O15: 800496 | P15: 677911 | Q15: 715273 | R15: 915843 | S15: 841320 | T15: 646139 | U15: 646139 | V15: 646139 | W15: 646139 | X15: 646139 | Y15: 646139 | Z15: 646139 | AA15: 646139 | AB15: 646139 | AC15: 646139 | AD15: 646139 | AE15: 646139 | AF15: 646139 | AG15: 646139 | AH15: 646139 | AI15: 646139 | AJ15: 646139 | AK15: 646139 | AL15: 646139 | AM15: 646139 | AN15: 646139 | AO15: 646139 | AP15: 646139 | AQ15: 646139 | AR15: 646139 | AS15: 646139 | AT15: 646139 | AU15: 646139 | AV15: 646139 | AW15: 646139
F16: Uso de suelos [Mha]
B17: ESPAC | F17: Montes y bosques [Mha] | I17: =I8/1000000 -> 3.504127 | J17: =J8/1000000 -> 3.536454 | K17: =K8/1000000 -> 3.583056 | L17: =L8/1000000 -> 3.538424 | M17: =M8/1000000 -> 5.758859 | N17: =N8/1000000 -> 5.729799 | O17: =O8/1000000 -> 5.77329 | P17: =P8/1000000 -> 5.675402 | ... AW17: =AW8/1000000 -> 5.90056
F18: Cultivos permanentes [Mha] | I18: =I9/1000000 -> 1.391379 | J18: =J9/1000000 -> 1.379473 | K18: =K9/1000000 -> 1.382918 | L18: =L9/1000000 -> 1.469363 | M18: =M9/1000000 -> 1.417104 | N18: =N9/1000000 -> 1.483366 | O18: =O9/1000000 -> 1.439117 | P18: =P9/1000000 -> 1.430497 | ... AW18: =AW9/1000000 -> 1.423372
F19: Cultivos transitorios y barbechos [Mha] | I19: =I10/1000000 -> 0.992369 | J19: =J10/1000000 -> 0.982312 | K19: =K10/1000000 -> 1.02087 | L19: =L10/1000000 -> 1.003271 | M19: =M10/1000000 -> 0.876498 | N19: =N10/1000000 -> 0.950649 | O19: =O10/1000000 -> 0.849685 | P19: =P10/1000000 -> 0.904224 | ... AW19: =AW10/1000000 -> 0.841994
F20: Descanso [Mha] | I20: =I11/1000000 -> 0.193957 | J20: =J11/1000000 -> 0.173442 | K20: =K11/1000000 -> 0.126982 | L20: =L11/1000000 -> 0.191159 | M20: =M11/1000000 -> 0.093574 | N20: =N11/1000000 -> 0.11739 | O20: =O11/1000000 -> 0.125946 | P20: =P11/1000000 -> 0.129268 | ... AW20: =AW11/1000000 -> 0.163017
F21: Otros usos [Mha] | I21: =I12/1000000 -> 0.217058 | J21: =J12/1000000 -> 0.210584 | K21: =K12/1000000 -> 0.205657 | L21: =L12/1000000 -> 0.216225 | M21: =M12/1000000 -> 0.46818 | N21: =N12/1000000 -> 0.61209 | O21: =O12/1000000 -> 0.719109 | P21: =P12/1000000 -> 0.757791 | ... AW21: =AW12/1000000 -> 0.712757
F22: Páramos [Mha] | I22: =I13/1000000 -> 0.539475 | J22: =J13/1000000 -> 0.565857 | K22: =K13/1000000 -> 0.608272 | L22: =L13/1000000 -> 0.491891 | M22: =M13/1000000 -> 0.499258 | N22: =N13/1000000 -> 0.454347 | O22: =O13/1000000 -> 0.377791 | P22: =P13/1000000 -> 0.332418 | ... AW22: =AW13/1000000 -> 0.233074
F23: Pastos cultivados [Mha] | I23: =I14/1000000 -> 3.409952 | J23: =J14/1000000 -> 3.425412 | K23: =K14/1000000 -> 3.553008 | L23: =L14/1000000 -> 3.227321 | M23: =M14/1000000 -> 2.259447 | N23: =N14/1000000 -> 2.531442 | O23: =O14/1000000 -> 2.300539 | P23: =P14/1000000 -> 2.447634 | ... AW23: =AW14/1000000 -> 2.376551
F24: Pastos permanentes [Mha] | I24: =I15/1000000 -> 1.509972 | J24: =J15/1000000 -> 1.385547 | K24: =K15/1000000 -> 1.423114 | L24: =L15/1000000 -> 1.623359 | M24: =M15/1000000 -> 0.828333 | N24: =N15/1000000 -> 0.706777 | O24: =O15/1000000 -> 0.800496 | P24: =P15/1000000 -> 0.677911 | ... AW24: =AW15/1000000 -> 0.646139
F25: TOTAL COBERTURAS [Mha] | I25: =SUM(I17:I24) -> 11.758289 | J25: =SUM(J17:J24) -> 11.659081 | K25: =SUM(K17:K24) -> 11.903877 | L25: =SUM(L17:L24) -> 11.761013 | M25: =SUM(M17:M24) -> 12.201253 | N25: =SUM(N17:N24) -> 12.58586 | O25: =SUM(O17:O24) -> 12.385973 | P25: =SUM(P17:P24) -> 12.355145 | ... AW25: =SUM(AW17:AW24) -> 12.297464
D28: DATOS ÁREAS PROTEGIDAS
E31: GRÁFICO UTCUTS-2 | F31: TABLA UTCUTS - 2: Cobertura áreas protegidas
F32: Áreas protegidas [Mha]
B33: SNAP | F33: Galápagos [Mha] | I33: 0.79579217 | J33: 0.79579217 | K33: 0.79579217 | L33: 0.79579217 | M33: 0.79579217 | N33: 0.79579217 | O33: 0.79579217 | P33: 0.79579217 | Q33: 0.79579217 | R33: 0.79579217 | S33: 0.79579217 | T33: 0.79579217 | U33: 0.79579217 | V33: 0.79579217 | W33: 0.79579217 | X33: 0.79579217 | Y33: 0.79579217 | Z33: 0.79579217 | AA33: 0.79579217 | AB33: 0.79579217 | AC33: 0.79579217 | AD33: 0.79579217 | AE33: 0.79579217 | AF33: 0.79579217 | AG33: 0.79579217 | AH33: 0.79579217 | AI33: 0.79579217 | AJ33: 0.79579217 | AK33: 0.79579217 | AL33: 0.79579217 | AM33: 0.79579217 | AN33: 0.79579217 | AO33: 0.79579217 | AP33: 0.79579217 | AQ33: 0.79579217 | AR33: 0.79579217 | AS33: 0.79579217 | AT33: 0.79579217 | AU33: 0.79579217 | AV33: 0.79579217 | AW33: 0.79579217
F34: Bosques protegidos/Protected forest [Mha] | I34: 2.2633933 | J34: 2.2794224 | K34: 2.2794224 | L34: 2.2794224 | M34: 2.3725857 | N34: 2.3725857 | O34: 2.3747312 | P34: 2.3747312 | Q34: 2.4084734 | R34: 2.4088211 | S34: 2.4088211 | T34: 2.4117235 | U34: 2.4117235 | V34: 2.4117235 | W34: 2.4117235 | X34: 2.4117235 | Y34: 2.4117235 | Z34: 2.4117235 | AA34: 2.4117235 | AB34: 2.4117235 | AC34: 2.4117235 | AD34: 2.4117235 | AE34: 2.4117235 | AF34: 2.4117235 | AG34: 2.4117235 | AH34: 2.4117235 | AI34: 2.4117235 | AJ34: 2.4117235 | AK34: 2.4117235 | AL34: 2.4117235 | AM34: 2.4117235 | AN34: 2.4117235 | AO34: 2.4117235 | AP34: 2.4117235 | AQ34: 2.4117235 | AR34: 2.4117235 | AS34: 2.4117235 | AT34: 2.4117235 | AU34: 2.4117235 | AV34: 2.4117235 | AW34: 2.4117235
F35: Pradera protegida/Protected grassland [Mha] | I35: 1.8351789 | J35: 1.8351789 | K35: 1.838396 | L35: 1.838396 | M35: 1.838396 | N35: 1.838396 | O35: 1.838396 | P35: 1.8914899 | Q35: 1.8934445 | R35: 1.922489 | S35: 1.9272792 | T35: 1.95791 | U35: 1.95791 | V35: 1.95791 | W35: 1.95791 | X35: 1.95791 | Y35: 1.95791 | Z35: 1.95791 | AA35: 1.95791 | AB35: 1.95791 | AC35: 1.95791 | AD35: 1.95791 | AE35: 1.95791 | AF35: 1.95791 | AG35: 1.95791 | AH35: 1.95791 | AI35: 1.95791 | AJ35: 1.95791 | AK35: 1.95791 | AL35: 1.95791 | AM35: 1.95791 | AN35: 1.95791 | AO35: 1.95791 | AP35: 1.95791 | AQ35: 1.95791 | AR35: 1.95791 | AS35: 1.95791 | AT35: 1.95791 | AU35: 1.95791 | AV35: 1.95791 | AW35: 1.95791
F36: Manglares [Mha] | I36: 0.37320953 | J36: 0.37568766 | K36: 0.38884296 | L36: 0.38884296 | M36: 0.38884296 | N36: 0.53110941 | O36: 0.57106191 | P36: 0.57106191 | Q36: 0.57106191 | R36: 0.57106191 | S36: 0.57106191 | T36: 0.57106191 | U36: 0.57106191 | V36: 0.57106191 | W36: 0.57106191 | X36: 0.57106191 | Y36: 0.57106191 | Z36: 0.57106191 | AA36: 0.57106191 | AB36: 0.57106191 | AC36: 0.57106191 | AD36: 0.57106191 | AE36: 0.57106191 | AF36: 0.57106191 | AG36: 0.57106191 | AH36: 0.57106191 | AI36: 0.57106191 | AJ36: 0.57106191 | AK36: 0.57106191 | AL36: 0.57106191 | AM36: 0.57106191 | AN36: 0.57106191 | AO36: 0.57106191 | AP36: 0.57106191 | AQ36: 0.57106191 | AR36: 0.57106191 | AS36: 0.57106191 | AT36: 0.57106191 | AU36: 0.57106191 | AV36: 0.57106191 | AW36: 0.57106191
D39: DATOS PARA MODELO OSEMOSYS
A42: DRIVERS | E42: GRÁFICO UTCUTS-3 | F42: TABLA UTCUTS - 3: Coberturas generales - MAG + MAATE
F43: Coberturas generales [ha]
B44: MAG+MAATE | D44: Bosque | F44: Bosque nativo [ha] | G44: 13038367 | M44: 12753387 | O44: 12631198 | Q44: 12514340
F45: Plantación forestal [ha] | G45: 62196.93 | M45: 130072.41 | O45: 123719.94 | Q45: 121995.27
D46: Tierra agropecuaria | F46: Cultivo anual [ha] | G46: 611941.95 | M46: 1094904.6 | O46: 8933864.5 | Q46: 8999553.2
F47: Cultivo semipermanente [ha] | G47: 260389.08 | M47: 480131.91
F48: Cultivo permanente [ha] | G48: 167305.59 | M48: 917407.35
F49: Pastizal [ha] | G49: 1454890.3 | M49: 4959938.7
F50: Mosaico agropecuario [ha] | G50: 6337045.3 | M50: 1266774.3
D51: Vegetación arbustiva | F51: Vegetación arbustiva [ha] | G51: 587499.84 | M51: 810626.94 | O51: 763180.11 | Q51: 768908.61
...

Sheet Drivers_macroeconómicos_USCUSS
C1: Ecuador | D1: 2018 | E1: 2019 | F1: 2020 | G1: 2021 | H1: 2022 | I1: 2023 | J1: 2024 | K1: 2025 | L1: 2026 | M1: 2027 | N1: 2028 | O1: 2029 | P1: 2030 | Q1: 2031 | R1: 2032 | S1: 2033 | T1: 2034 | U1: 2035 | V1: 2036 | W1: 2037 | X1: 2038 | Y1: 2039 | Z1: 2040 | AA1: 2041 | AB1: 2042 | AC1: 2043 | AD1: 2044 | AE1: 2045 | AF1: 2046 | AG1: 2047 | AH1: 2048 | AI1: 2049 | AJ1: 2050 | AK1: 2051 | AL1: 2052 | AM1: 2053 | AN1: 2054 | AO1: 2055 | AP1: 2056 | AQ1: 2057 | AR1: 2058 | AS1: 2059 | AT1: 2060 | AU1: 2061 | AV1: 2062 | AW1: 2063 | AX1: 2064 | AY1: 2065 | AZ1: 2066 | BA1: 2067 | BB1: 2068 | BC1: 2069 | BD1: 2070
C4: Drivers económicos
C6: Población
C7: Población Nacional | D7: 17023408 | E7: 17267986 | F7: 17510643 | G7: 17751277 | H7: 17989912 | I7: 18226512 | J7: 18460936 | K7: 18693140 | L7: 18922864 | M7: 19150021 | N7: 19374448 | O7: 19596113 | P7: 19814767 | Q7: 20030293 | R7: 20242540 | S7: 20451333 | T7: 20656586 | U7: 20858149 | V7: 21055934 | W7: 21249772 | X7: 21439596 | Y7: 21625281 | Z7: 21806740 | AA7: 21983950 | AB7: 22156850 | AC7: 22325333 | AD7: 22489377 | AE7: 22648875 | AF7: 22803800 | AG7: 22954177 | AH7: 23099877 | AI7: 23240939 | AJ7: 23377412 | AK7: 23509204 | AL7: 23636226 | AM7: 23758390 | AN7: 23875615 | AO7: 23987819 | AP7: 24094924 | AQ7: 24196857 | AR7: 24293546 | AS7: 24384925 | AT7: 24470928 | AU7: 24551497 | AV7: 24626572 | AW7: 24696102 | AX7: 24760036 | AY7: 24818330 | AZ7: 24870940 | BA7: 24917829 | BB7: 24958963 | BC7: 24994311 | BD7: 25023848
C8: Tasa de crecimiento Poblacional [%] | E8: 0.014367158 | F8: 0.01405242 | G8: 0.013742157 | H8: 0.013443258 | I8: 0.013151815 | J8: 0.012861704 | K8: 0.012578127 | L8: 0.012289214 | M8: 0.012004367 | N8: 0.011719413 | O8: 0.0114411 | P8: 0.011158029 | Q8: 0.010877039 | R8: 0.0105963 | S8: 0.010314565 | T8: 0.010036167 | U8: 0.009757808 | V8: 0.009482385 | W8: 0.0092058609 | X8: 0.00893299 | Y8: 0.0086608442 | Z8: 0.0083910586 | AA8: 0.0081263866 | AB8: 0.0078648287 | AC8: 0.0076041044 | AD8: 0.0073478859 | AE8: 0.0070921484 | AF8: 0.0068402956 | AG8: 0.0065943834 | AH8: 0.0063474286 | AI8: 0.0061066126 | AJ8: 0.0058720949 | AK8: 0.0056375773 | AL8: 0.0054030596 | AM8: 0.0051685419 | AN8: 0.0049340242 | AO8: 0.0046995066 | AP8: 0.0044649889 | AQ8: 0.0042304712 | AR8: 0.0039959535 | AS8: 0.0037614358 | AT8: 0.0035269182 | AU8: 0.0032924005 | AV8: 0.0030578828 | AW8: 0.0028233651 | AX8: 0.0025888475 | AY8: 0.0023543298 | AZ8: 0.0021198121 | BA8: 0.0018852944 | BB8: 0.0016507768 | BC8: 0.0014162591 | BD8: 0.0011817414
C9: Población Urbana | D9: 10864509 | E9: 11049093 | F9: 11235879 | G9: 11424900 | H9: 11615526 | I9: 11808838 | J9: 12005436 | K9: 12202757 | L9: 12402937 | M9: 12604533 | N9: 12808718 | O9: 13014434 | P9: 13223175 | Q9: 13432538 | R9: 13643430 | S9: 13856389 | T9: 14070704 | U9: 14285910 | V9: 14502306 | W9: 14719086 | X9: 14936890 | Y9: 15155932 | Z9: 15374543 | AA9: 15594304 | AB9: 15812576 | AC9: 16030860 | AD9: 16246560 | AE9: 16459880 | AF9: 16670523 | AG9: 16877776 | AH9: 17081537 | AI9: 17282572 | AJ9: 17479919 | AK9: 17675992 | AL9: 17869280 | AM9: 18059730 | AN9: 18247636 | AO9: 18432571 | AP9: 18614476 | AQ9: 18793290 | AR9: 18968832 | AS9: 19141005 | AT9: 19309699 | AU9: 19474788 | AV9: 19636165 | AW9: 19793719 | AX9: 19947339 | AY9: 20096920 | AZ9: 20242357 | BA9: 20383550 | BB9: 20520399 | BC9: 20652807 | BD9: 20780681
C10: Tasa de urbanización | D10: 0.63820999 | E10: 0.63985997 | F10: 0.64165999 | G10: 0.64361003 | H10: 0.64566886 | I10: 0.64789346 | J10: 0.65031567 | K10: 0.65279332 | L10: 0.65544714 | M10: 0.65819943 | N10: 0.66111396 | O10: 0.66413344 | P10: 0.66733941 | Q10: 0.67061116 | R10: 0.67399793 | S10: 0.67752987 | T10: 0.68117277 | U10: 0.68490785 | V10: 0.68875149 | W10: 0.6926703 | X10: 0.69669643 | Y10: 0.70084324 | Z10: 0.70503629 | AA10: 0.7093495 | AB10: 0.71366535 | AC10: 0.71805693 | AD10: 0.72241041 | AE10: 0.72674162 | AF10: 0.73104145 | AG10: 0.73528125 | AH10: 0.73946441 | AI10: 0.74362624 | AJ10: 0.74772687 | AK10: 0.7518754 | AL10: 0.7560124 | AM10: 0.76014112 | AN10: 0.76427921 | AO10: 0.76841381 | AP10: 0.77254761 | AQ10: 0.77668311 | AR10: 0.78081774 | AS10: 0.78495238 | AT10: 0.78908731 | AU10: 0.79322204 | AV10: 0.79735681 | AW10: 0.80149162 | AX10: 0.80562639 | AY10: 0.80976117 | AZ10: 0.81389596 | BA10: 0.81803074 | BB10: 0.82216552 | BC10: 0.8263003 | BD10: 0.83043508
C11: Población Rural | D11: 6158899 | E11: 6218893 | F11: 6274764 | G11: 6326377 | H11: 6374386 | I11: 6417674 | J11: 6455500 | K11: 6490383 | L11: 6519927 | M11: 6545488 | N11: 6565730 | O11: 6581679 | P11: 6591592 | Q11: 6597755 | R11: 6599110 | S11: 6594944 | T11: 6585882 | U11: 6572239 | V11: 6553628 | W11: 6530686 | X11: 6502706 | Y11: 6469349 | Z11: 6432197 | AA11: 6389646 | AB11: 6344274 | AC11: 6294473 | AD11: 6242817 | AE11: 6188995 | AF11: 6133277 | AG11: 6076401 | AH11: 6018340 | AI11: 5958367 | AJ11: 5897493 | AK11: 5833211.7 | AL11: 5766946 | AM11: 5698660.9 | AN11: 5627978.9 | AO11: 5555247.6 | AP11: 5480448 | AQ11: 5403566.9 | AR11: 5324714.4 | AS11: 5243920 | AT11: 5161229.4 | AU11: 5076708.3 | AV11: 4990407.2 | AW11: 4902383.2 | AX11: 4812697.7 | AY11: 4721410 | AZ11: 4628582.5 | BA11: 4534279 | BB11: 4438564.2 | BC11: 4341504.3 | BD11: 4243166.7
C12: Tasa de ruralización | D12: 0.36179001 | E12: 0.36014003 | F12: 0.35834001 | G12: 0.35638997 | H12: 0.35433114 | I12: 0.35210654 | J12: 0.34968433 | K12: 0.34720668 | L12: 0.34455286 | M12: 0.34180057 | N12: 0.33888604 | O12: 0.33586656 | P12: 0.33266059 | Q12: 0.32938884 | R12: 0.32600207 | S12: 0.32247013 | T12: 0.31882723 | U12: 0.31509215 | V12: 0.31124851 | W12: 0.3073297 | X12: 0.30330357 | Y12: 0.29915676 | Z12: 0.29496371 | AA12: 0.2906505 | AB12: 0.28633465 | AC12: 0.28194307 | AD12: 0.27758959 | AE12: 0.27325838 | AF12: 0.26895855 | AG12: 0.26471875 | AH12: 0.26053559 | AI12: 0.25637376 | AJ12: 0.25227313 | AK12: 0.2481246 | AL12: 0.2439876 | AM12: 0.23985888 | AN12: 0.23572079 | AO12: 0.23158619 | AP12: 0.22745239 | AQ12: 0.22331689 | AR12: 0.21918226 | AS12: 0.21504762 | AT12: 0.21091269 | AU12: 0.20677796 | AV12: 0.20264319 | AW12: 0.19850838 | AX12: 0.19437361 | AY12: 0.19023883 | AZ12: 0.18610404 | BA12: 0.18196926 | BB12: 0.17783448 | BC12: 0.1736997 | BD12: 0.16956492
C13: Población Económicamente Activa | D13: 8164671.9 | E13: 8192768.8 | F13: 8420741.7 | G13: 8582778.7 | H13: 8570550.2 | I13: 8898168 | J13: 8852383.3 | K13: 9072233.5 | L13: 9328486.5 | M13: 9424636.7 | N13: 9694170.1 | O13: 9687259.9 | P13: 9797759.8 | Q13: 10138246 | R13: 10139537 | S13: 10428883 | T13: 10452508 | U13: 10511839 | V13: 10701475 | W13: 10758750 | X13: 10892423 | Y13: 11185978 | Z13: 11302979 | AA13: 11485000 | AB13: 11676283 | AC13: 11553196 | AD13: 11744123 | AE13: 11777190 | AF13: 12098068 | AG13: 12164231 | AH13: 12237431 | AI13: 12351923 | AJ13: 12488207 | AK13: 12459201 | AL13: 12533145 | AM13: 12592775 | AN13: 12670481 | AO13: 12733611 | AP13: 12797206 | AQ13: 12848044 | AR13: 12898288 | AS13: 12947625 | AT13: 12992302 | AU13: 13030507 | AV13: 13070894 | AW13: 13108385 | AX13: 13144106 | AY13: 13175801 | AZ13: 13204201 | BA13: 13228282 | BB13: 13249780 | BC13: 13268406 | BD13: 13283873
C15: PIB Nacional Tendencial
C16: PIB Nacional [Miles USD 2021] | D16: 1.1044052e+08 | E16: 1.1045389e+08 | F16: 1.0185217e+08 | G16: 1.0616587e+08 | H16: 1.0903234e+08 | I16: 1.1241235e+08 | J16: 1.1578472e+08 | K16: 1.189109e+08 | L16: 1.2164586e+08 | M16: 1.2552006e+08 | N16: 1.2909258e+08 | O16: 1.3192742e+08 | P16: 1.3506999e+08 | Q16: 1.3934876e+08 | R16: 1.4278631e+08 | S16: 1.4691488e+08 | T16: 1.5039185e+08 | U16: 1.5394779e+08 | V16: 1.5787929e+08 | W16: 1.6146177e+08 | X16: 1.6524433e+08 | Y16: 1.694103e+08 | Z16: 1.7325839e+08 | AA16: 1.7721315e+08 | AB16: 1.8116162e+08 | AC16: 1.8433065e+08 | AD16: 1.8837051e+08 | AE16: 1.9187245e+08 | AF16: 1.962589e+08 | AG16: 1.9987601e+08 | AH16: 2.0345775e+08 | AI16: 2.0717148e+08 | AJ16: 2.1091297e+08 | AK16: 2.1516061e+08 | AL16: 2.1903011e+08 | AM16: 2.2290161e+08 | AN16: 2.2689756e+08 | AO16: 2.3093073e+08 | AP16: 2.3507519e+08 | AQ16: 2.390897e+08 | AR16: 2.4314279e+08 | AS16: 2.4723288e+08 | AT16: 2.5134133e+08 | AU16: 2.5545079e+08 | AV16: 2.5957199e+08 | AW16: 2.6370907e+08 | AX16: 2.6786265e+08 | AY16: 2.7202083e+08 | AZ16: 2.7618252e+08 | BA16: 2.8034186e+08 | BB16: 2.8450685e+08 | BC16: 2.8867414e+08 | BD16: 2.9284055e+08
C17: Tasa de crecimiento del PIB Nacional [%] | E17: 0.00012105103 | F17: -0.077876071 | G17: 0.042352512 | H17: 0.027 | I17: 0.031 | J17: 0.03 | K17: 0.027 | L17: 0.023 | M17: 0.031848226 | N17: 0.028461725 | O17: 0.021959772 | P17: 0.023820424 | Q17: 0.031678203 | R17: 0.024668623 | S17: 0.028914332 | T17: 0.02366656 | U17: 0.023644563 | V17: 0.025537867 | W17: 0.022691249 | X17: 0.023426989 | Y17: 0.025210938 | Z17: 0.022714646 | AA17: 0.022825748 | AB17: 0.022280909 | AC17: 0.017492827 | AD17: 0.021916426 | AE17: 0.018590676 | AF17: 0.022861287 | AG17: 0.018430279 | AH17: 0.017919822 | AI17: 0.018253093 | AJ17: 0.018059848 | AK17: 0.020139299 | AL17: 0.017984242 | AM17: 0.017675659 | AN17: 0.017926947 | AO17: 0.01777532 | AP17: 0.017946763 | AQ17: 0.017077545 | AR17: 0.016952187 | AS17: 0.016821774 | AT17: 0.016617719 | AU17: 0.016350119 | AV17: 0.01613305 | AW17: 0.015938076 | AX17: 0.015750621 | AY17: 0.015523529 | AZ17: 0.015299193 | BA17: 0.015060105 | BB17: 0.014856822 | BC17: 0.014647421 | BD17: 0.014432888
C19: PIB Nacional Optimista
C20: PIB Nacional [Miles USD 2021] | D20: 1.1044052e+08 | E20: 1.1045389e+08 | F20: 1.0185217e+08 | G20: 1.0616587e+08 | H20: 1.0903234e+08 | I20: 1.1241235e+08 | J20: 1.1578472e+08 | K20: 1.189109e+08 | L20: 1.2164586e+08 | M20: 1.2618356e+08 | N20: 1.3119398e+08 | O20: 1.3506116e+08 | P20: 1.3963439e+08 | Q20: 1.4542588e+08 | R20: 1.5108693e+08 | S20: 1.5842426e+08 | T20: 1.6468855e+08 | U20: 1.7163687e+08 | V20: 1.7940792e+08 | W20: 1.8675464e+08 | X20: 1.949134e+08 | Y20: 2.0401983e+08 | Z20: 2.1260645e+08 | AA20: 2.2205733e+08 | AB20: 2.3184204e+08 | AC20: 2.4086664e+08 | AD20: 2.5165093e+08 | AE20: 2.6181995e+08 | AF20: 2.7442058e+08 | AG20: 2.8555366e+08 | AH20: 2.9758914e+08 | AI20: 3.104137e+08 | AJ20: 3.2383289e+08 | AK20: 3.3783219e+08 | AL20: 3.5255474e+08 | AM20: 3.6794329e+08 | AN20: 3.838701e+08 | AO20: 4.0077811e+08 | AP20: 4.1840025e+08 | AQ20: 4.3701471e+08 | AR20: 4.562429e+08 | AS20: 4.7643646e+08 | AT20: 4.9761046e+08 | AU20: 5.197696e+08 | AV20: 5.4293709e+08 | AW20: 5.6723261e+08 | AX20: 5.9266525e+08 | AY20: 6.1931712e+08 | AZ20: 6.4721204e+08 | BA20: 6.7642284e+08 | BB20: 7.0699494e+08 | BC20: 7.3902754e+08 | BD20: 7.7257936e+08
C21: Tasa de crecimiento del PIB Nacional [%] | E21: 0.00012105103 | F21: -0.077876071 | G21: 0.042352512 | H21: 0.027 | I21: 0.031 | J21: 0.03 | K21: 0.027 | L21: 0.023 | M21: 0.037302605 | N21: 0.039707332 | O21: 0.029476823 | P21: 0.03386043 | Q21: 0.041476109 | R21: 0.038927414 | S21: 0.048563643 | T21: 0.039541205 | U21: 0.0421907 | V21: 0.045276099 | W21: 0.040949802 | X21: 0.043687049 | Y21: 0.046720382 | Z21: 0.042087215 | AA21: 0.044452419 | AB21: 0.044063914 | AC21: 0.038925655 | AD21: 0.044772853 | AE21: 0.040409229 | AF21: 0.048127088 | AG21: 0.040569398 | AH21: 0.042147864 | AI21: 0.043094874 | AJ21: 0.04323001 | AK21: 0.04323001 | AL21: 0.043579473 | AM21: 0.043648688 | AN21: 0.043286043 | AO21: 0.044046169 | AP21: 0.043969828 | AQ21: 0.04448959 | AR21: 0.043998954 | AS21: 0.044260547 | AT21: 0.04444244 | AU21: 0.044531097 | AV21: 0.044572613 | AW21: 0.04474832 | AX21: 0.044836349 | AY21: 0.044969527 | AZ21: 0.045041405 | BA21: 0.045133277 | BB21: 0.045196729 | BC21: 0.045308103 | BD21: 0.04539996
C23: PIB Nacional Escenario Negativo
C24: PIB Nacional [Miles USD 2021] | D24: 1.1044052e+08 | E24: 1.1045389e+08 | F24: 1.0185217e+08 | G24: 1.0616587e+08 | H24: 1.0903234e+08 | I24: 1.1241235e+08 | J24: 1.1578472e+08 | K24: 1.189109e+08 | L24: 1.2164586e+08 | M24: 1.2398022e+08 | N24: 1.2628167e+08 | O24: 1.2826239e+08 | P24: 1.3015186e+08 | Q24: 1.3293641e+08 | R24: 1.3547394e+08 | S24: 1.380039e+08 | T24: 1.4043897e+08 | U24: 1.4262325e+08 | V24: 1.4502121e+08 | W24: 1.4734003e+08 | X24: 1.4960131e+08 | Y24: 1.5209086e+08 | Z24: 1.5460176e+08 | AA24: 1.5694566e+08 | AB24: 1.5931023e+08 | AC24: 1.6105022e+08 | AD24: 1.6339398e+08 | AE24: 1.654843e+08 | AF24: 1.6785104e+08 | AG24: 1.7010112e+08 | AH24: 1.7204024e+08 | AI24: 1.740421e+08 | AJ24: 1.7606956e+08 | AK24: 1.7863001e+08 | AL24: 1.8073167e+08 | AM24: 1.8286392e+08 | AN24: 1.8504881e+08 | AO24: 1.8728437e+08 | AP24: 1.895735e+08 | AQ24: 1.9176363e+08 | AR24: 1.9395671e+08 | AS24: 1.9616623e+08 | AT24: 1.9838068e+08 | AU24: 2.0058591e+08 | AV24: 2.0277829e+08 | AW24: 2.0497725e+08 | AX24: 2.0717606e+08 | AY24: 2.0936996e+08 | AZ24: 2.1155518e+08 | BA24: 2.1372957e+08 | BB24: 2.1589648e+08 | BC24: 2.1805594e+08 | BD24: 2.20206e+08
C25: Tasa de crecimiento del PIB Nacional [%] | E25: 0.00012105103 | F25: -0.077876071 | G25: 0.042352512 | H25: 0.027 | I25: 0.031 | J25: 0.03 | K25: 0.027 | L25: 0.023 | M25: 0.019189799 | N25: 0.0185631 | O25: 0.015684905 | P25: 0.014731318 | Q25: 0.021394642 | R25: 0.019088298 | S25: 0.018674849 | T25: 0.017644928 | U25: 0.015553206 | V25: 0.016813279 | W25: 0.015989505 | X25: 0.01534738 | Y25: 0.016641214 | Z25: 0.01650923 | AA25: 0.015160889 | AB25: 0.015066138 | AC25: 0.010922049 | AD25: 0.014552988 | AE25: 0.012793097 | AF25: 0.014301948 | AG25: 0.013405175 | AH25: 0.011399796 | AI25: 0.011636043 | AJ25: 0.01164922 | AK25: 0.014542263 | AL25: 0.011765423 | AM25: 0.011797887 | AN25: 0.011948199 | AO25: 0.012080923 | AP25: 0.012222755 | AQ25: 0.011552933 | AR25: 0.01143636 | AS25: 0.011391832 | AT25: 0.011288604 | AU25: 0.011116163 | AV25: 0.010929889 | AW25: 0.010844183 | AX25: 0.010727066 | AY25: 0.010589524 | AZ25: 0.010437131 | BA25: 0.010278154 | BB25: 0.010138561 | BC25: 0.010002267 | BD25: 0.0098601413
C27: PIB Sectorial Tendencial
C29: Sector agricultura, silvicultura y pesca
C30: PIB Sector agricultura, silvicultura y pesca [Miles USD 2021] | D30: 10459664 | E30: 10628847 | F30: 10666853 | G30: 11028075 | H30: 11407864 | I30: 11743435 | J30: 12109217 | K30: 12395282 | L30: 12636982 | M30: 12958077 | N30: 13237105 | O30: 13402558 | P30: 13597211 | Q30: 13881504 | R30: 14068748 | S30: 14310693 | T30: 14481999 | U30: 14661880 | V30: 14879624 | W30: 15076447 | X30: 15302557 | Y30: 15584162 | Z30: 15852246 | AA30: 16154988 | AB30: 16475218 | AC30: 16750070 | AD30: 17121125 | AE30: 17465869 | AF30: 17904576 | AG30: 18290578 | AH30: 18681161 | AI30: 19094516 | AJ30: 19511992 | AK30: 19879079 | AL30: 20261015 | AM30: 20655812 | AN30: 21066381 | AO30: 21491535 | AP30: 21927658 | AQ30: 22376868 | AR30: 22837221 | AS30: 23308116 | AT30: 23794456 | AU30: 24289030 | AV30: 24794871 | AW30: 25304594 | AX30: 25823213 | AY30: 26351074 | AZ30: 26886949 | BA30: 27431155 | BB30: 27988822 | BC30: 28559780 | BD30: 29144017
C31: Tasa de crecimiento del PIB Nacional [%] | E31: 0.016174817 | F31: 0.0035757596 | G31: 0.033864024 | H31: 0.03443832 | I31: 0.029415819 | J31: 0.031147751 | K31: 0.023623758 | L31: 0.019499324 | M31: 0.025409155 | N31: 0.021533113 | O31: 0.012499168 | P31: 0.014523639 | Q31: 0.020908162 | R31: 0.013488719 | S31: 0.017197377 | T31: 0.011970435 | U31: 0.012421047 | V31: 0.014850993 | W31: 0.013227721 | X31: 0.014997548 | Y31: 0.018402462 | Z31: 0.017202389 | AA31: 0.01909772 | AB31: 0.019822354 | AC31: 0.016682758 | AD31: 0.022152455 | AE31: 0.020135555 | AF31: 0.025117958 | AG31: 0.021558839 | AH31: 0.021354363 | AI31: 0.022126832 | AJ31: 0.021863659 | AK31: 0.018813416 | AL31: 0.019212939 | AM31: 0.01948556 | AN31: 0.019876675 | AO31: 0.020181621 | AP31: 0.020292818 | AQ31: 0.02048597 | AR31: 0.020572736 | AS31: 0.020619635 | AT31: 0.020865689 | AU31: 0.020785267 | AV31: 0.020825874 | AW31: 0.020557618 | AX31: 0.020495042 | AY31: 0.020441334 | AZ31: 0.020335991 | BA31: 0.020240512 | BB31: 0.020329705 | BC31: 0.020399503 | BD31: 0.020456624
C33: Sector explotación de minas y canteras
C34: PIB Sector explotación de minas y canteras [Miles USD 2021] | D34: 10619740 | E34: 10743749 | F34: 9864685.9 | G34: 10102375 | H34: 10441573 | I34: 10665717 | J34: 11062141 | K34: 11260682 | L34: 11593335 | M34: 11868301 | N34: 12269142 | O34: 12454378 | P34: 12809347 | Q34: 13134036 | R34: 13509102 | S34: 13824040 | T34: 14194898 | U34: 14461150 | V34: 14866847 | W34: 15140781 | X34: 15525019 | Y34: 15858303 | Z34: 16241972 | AA34: 16559468 | AB34: 16946242 | AC34: 17193951 | AD34: 17583425 | AE34: 17865440 | AF34: 18281930 | AG34: 18577259 | AH34: 18914141 | AI34: 19220723 | AJ34: 19568240 | AK34: 19945901 | AL34: 20321976 | AM34: 20703861 | AN34: 21084331 | AO34: 21478999 | AP34: 21873374 | AQ34: 22279608 | AR34: 22683784 | AS34: 23099391 | AT34: 23523006 | AU34: 23958944 | AV34: 24403946 | AW34: 24855601 | AX34: 25314832 | AY34: 25781820 | AZ34: 26257587 | BA34: 26741502 | BB34: 27234502 | BC34: 27736254 | BD34: 28247961
C35: Tasa de crecimiento del PIB Nacional [%] | E35: 0.011677162 | F35: -0.081820881 | G35: 0.024094935 | H35: 0.033576057 | I35: 0.021466527 | J35: 0.037168025 | K35: 0.017947821 | L35: 0.029541062 | M35: 0.023717631 | N35: 0.033774049 | O35: 0.015097768 | P35: 0.028501562 | Q35: 0.025347811 | R35: 0.028556772 | S35: 0.023313025 | T35: 0.026827002 | U35: 0.018756882 | V35: 0.028054276 | W35: 0.018425862 | X35: 0.025377654 | Y35: 0.021467537 | Z35: 0.024193611 | AA35: 0.019547851 | AB35: 0.023356682 | AC35: 0.014617352 | AD35: 0.022651763 | AE35: 0.016038716 | AF35: 0.023312614 | AG35: 0.016154121 | AH35: 0.018134145 | AI35: 0.016209103 | AJ35: 0.018080359 | AK35: 0.019299665 | AL35: 0.018854761 | AM35: 0.018791753 | AN35: 0.018376759 | AO35: 0.018718524 | AP35: 0.018360956 | AQ35: 0.018572069 | AR35: 0.018141111 | AS35: 0.018321746 | AT35: 0.0183388 | AU35: 0.018532409 | AV35: 0.018573505 | AW35: 0.01850749 | AX35: 0.01847592 | AY35: 0.018447208 | AZ35: 0.018453613 | BA35: 0.01842953 | BB35: 0.018435764 | BC35: 0.018423372 | BD35: 0.018449033
C37: Sector D Y E - Generación, captación y distribución de energía eléctrica. Captación, depuración y distribución de agua; y saneamiento
C38: PIB Sector X [Miles USD 2021] | D38: 3138868.4 | E38: 3445471.9 | F38: 3269184.8 | G38: 3294063.3 | H38: 3555861.7 | I38: 3617250.9 | J38: 3918049.3 | K38: 3974907.3 | L38: 4258788.8 | M38: 4353139.4 | N38: 4665919.7 | O38: 4736227.4 | P38: 5031785.5 | Q38: 5167013.6 | R38: 5467260.9 | S38: 5613108.5 | T38: 5908044.9 | U38: 6048487.5 | V38: 6354658.6 | W38: 6512158.3 | X38: 6806903.1 | Y38: 7003424.9 | Z38: 7296765.4 | AA38: 7498696.7 | AB38: 7792956 | AC38: 7973698.9 | AD38: 8269153.2 | AE38: 8475254.2 | AF38: 8784740.5 | AG38: 9006042.9 | AH38: 9278775.6 | AI38: 9513418.1 | AJ38: 9793216.8 | AK38: 10096506 | AL38: 10399168 | AM38: 10713080 | AN38: 11027649 | AO38: 11357640 | AP38: 11690144 | AQ38: 12037007 | AR38: 12386672 | AS38: 12750838 | AT38: 13124687 | AU38: 13514307 | AV38: 13915830 | AW38: 14327692 | AX38: 14751249 | AY38: 15186489 | AZ38: 15634768 | BA38: 16095702 | BB38: 16570526 | BC38: 17059100 | BD38: 17562753
C39: Tasa de crecimiento del PIB Nacional [%] | E39: 0.09767964 | F39: -0.051164869 | G39: 0.0076100067 | H39: 0.079475833 | I39: 0.017264204 | J39: 0.083156649 | K39: 0.014511806 | L39: 0.071418388 | M39: 0.02215434 | N39: 0.071851658 | O39: 0.015068342 | P39: 0.062403699 | Q39: 0.026874785 | R39: 0.058108469 | S39: 0.026676535 | T39: 0.052544217 | U39: 0.023771431 | V39: 0.050619448 | W39: 0.024784905 | X39: 0.0452607 | Y39: 0.028870951 | Z39: 0.041885296 | AA39: 0.027674083 | AB39: 0.039241389 | AC39: 0.023193116 | AD39: 0.03705361 | AE39: 0.024924077 | AF39: 0.036516462 | AG39: 0.02519168 | AH39: 0.030283304 | AI39: 0.025288081 | AJ39: 0.029410954 | AK39: 0.030969277 | AL39: 0.029976912 | AM39: 0.03018626 | AN39: 0.029363067 | AO39: 0.029923971 | AP39: 0.029275822 | AQ39: 0.029671436 | AR39: 0.029049161 | AS39: 0.029399841 | AT39: 0.029319526 | AU39: 0.029686021 | AV39: 0.029711027 | AW39: 0.02959664 | AX39: 0.02956207 | AY39: 0.029505325 | AZ39: 0.029518258 | BA39: 0.029481375 | BB39: 0.029500062 | BC39: 0.029484482 | BD39: 0.029524057
C41: Sector C - Industrias Manufactureras
C42: PIB Sector Y [Miles USD 2021] | D42: 12853031 | E42: 12930007 | F42: 12191089 | G42: 12568272 | H42: 13043258 | I42: 13325429 | J42: 13855046 | K42: 14089477 | L42: 14536382 | M42: 14855781 | N42: 15395233 | O42: 15576803 | P42: 16060951 | Q42: 16425141 | R42: 16936158 | S42: 17292844 | T42: 17796821 | U42: 18096407 | V42: 18640912 | W42: 18953076 | X42: 19467026 | Y42: 19856302 | Z42: 20365186 | AA42: 20737732 | AB42: 21246519 | AC42: 21534828 | AD42: 22043312 | AE42: 22377588 | AF42: 22916652 | AG42: 23270157 | AH42: 23706471 | AI42: 24076272 | AJ42: 24523162 | AK42: 24998528 | AL42: 25468918 | AM42: 25949372 | AN42: 26425513 | AO42: 26921872 | AP42: 27415736 | AQ42: 27926585 | AR42: 28433101 | AS42: 28955814 | AT42: 29487172 | AU42: 30035657 | AV42: 30594452 | AW42: 31161473 | AX42: 31738201 | AY42: 32324574 | AZ42: 32922152 | BA42: 33529890 | BB42: 34149198 | BC42: 34779439 | BD42: 35422317
C43: Tasa de crecimiento del PIB Nacional [%] | E43: 0.0059889289 | F43: -0.057147543 | G43: 0.030939308 | H43: 0.037792405 | I43: 0.021633515 | J43: 0.039744818 | K43: 0.016920245 | L43: 0.031719063 | M43: 0.02197239 | N43: 0.03631261 | O43: 0.011793936 | P43: 0.031081357 | Q43: 0.022675461 | R43: 0.03111187 | S43: 0.021060661 | T43: 0.029143675 | U43: 0.016833639 | V43: 0.030089133 | W43: 0.016746176 | X43: 0.027116973 | Y43: 0.019996668 | Z43: 0.025628382 | AA43: 0.018293273 | AB43: 0.02453436 | AC43: 0.013569678 | AD43: 0.023612193 | AE43: 0.015164479 | AF43: 0.024089463 | AG43: 0.015425674 | AH43: 0.018749936 | AI43: 0.015599196 | AJ43: 0.018561403 | AK43: 0.019384367 | AL43: 0.018816729 | AM43: 0.018864316 | AN43: 0.018348858 | AO43: 0.018783329 | AP43: 0.018344341 | AQ43: 0.018633419 | AR43: 0.018137415 | AS43: 0.018383937 | AT43: 0.018350665 | AU43: 0.018600798 | AV43: 0.01860438 | AW43: 0.018533472 | AX43: 0.018507721 | AY43: 0.018475303 | AZ43: 0.018486798 | BA43: 0.018459841 | BB43: 0.018470341 | BC43: 0.018455516 | BD43: 0.018484434
C45: Sector F - Construcción
C46: PIB Sector Z [Miles USD 2021] | D46: 9518754.6 | E46: 9070046.9 | F46: 7251965.1 | G46: 6770880 | H46: 7367985.4 | I46: 7153337.3 | J46: 7918553.8 | K46: 7599295.2 | L46: 8390540 | M46: 8096840.6 | N46: 8952006 | O46: 8583815.8 | P46: 9375631.3 | Q46: 9128107.4 | R46: 9874161.4 | S46: 9678381.5 | T46: 10358051 | U46: 10190294 | V46: 10835160 | W46: 10730474 | X46: 11308633 | Y46: 11296105 | Z46: 11830553 | AA46: 11848398 | AB46: 12347573 | AC46: 12351038 | AD46: 12819650 | AE46: 12878791 | AF46: 13340234 | AG46: 13434923 | AH46: 13816085 | AI46: 13941345 | AJ46: 14311304 | AK46: 14624446 | AL46: 14910627 | AM46: 15226891 | AN46: 15520903 | AO46: 15847442 | AP46: 16156500 | AQ46: 16493453 | AR46: 16814981 | AS46: 17161726 | AT46: 17503531 | AU46: 17869409 | AV46: 18233783 | AW46: 18603118 | AX46: 18981095 | AY46: 19365212 | AZ46: 19758735 | BA46: 20158967 | BB46: 20568687 | BC46: 20985742 | BD46: 21412744
C47: Tasa de crecimiento del PIB Nacional [%] | E47: -0.047139324 | F47: -0.200449 | G47: -0.066338582 | H47: 0.088187259 | I47: -0.02913253 | J47: 0.10697335 | K47: -0.040317796 | L47: 0.10412083 | M47: -0.035003642 | N47: 0.10561718 | O47: -0.04112935 | P47: 0.092245165 | Q47: -0.026400779 | R47: 0.081731519 | S47: -0.019827501 | T47: 0.070225521 | U47: -0.016195822 | V47: 0.063282416 | W47: -0.0096617131 | X47: 0.053880066 | Y47: -0.0011077495 | Z47: 0.047312509 | AA47: 0.0015083936 | AB47: 0.042130216 | AC47: 0.00028056934 | AD47: 0.037941153 | AE47: 0.0046132637 | AF47: 0.03582971 | AG47: 0.0070979703 | AH47: 0.028371023 | AI47: 0.0090662243 | AJ47: 0.026536838 | AK47: 0.021880715 | AL47: 0.019568734 | AM47: 0.021210583 | AN47: 0.019308799 | AO47: 0.021038638 | AP47: 0.019502045 | AQ47: 0.020855571 | AR47: 0.019494286 | AS47: 0.020621223 | AT47: 0.019916696 | AU47: 0.020903103 | AV47: 0.020390945 | AW47: 0.020255511 | AX47: 0.020317945 | AY47: 0.020236797 | AZ47: 0.02032116 | BA47: 0.020255935 | BB47: 0.02032447 | BC47: 0.020276188 | BD47: 0.02034727
C49: Sector G - Comercio al por mayor y al por menor; reparación de los vehículos de motor y de las motocicletas
C50: PIB Sector M [Miles USD 2021] | D50: 11328940 | E50: 11241422 | F50: 10358244 | G50: 11502513 | H50: 11361983 | I50: 12043246 | J50: 11911061 | K50: 12559294 | L50: 12370057 | M50: 13056237 | N50: 12982711 | O50: 13526194 | P50: 13432690 | Q50: 14086371 | R50: 14045427 | S50: 14640450 | T50: 14625271 | U50: 15119889 | V50: 15171019 | W50: 15626829 | X50: 15682985 | Y50: 16156256 | Z50: 16234709 | AA50: 16652527 | AB50: 16754067 | AC50: 17066720 | AD50: 17188338 | AE50: 17502728 | AF50: 17663791 | AG50: 17961988 | AH50: 18056495 | AI50: 18338956 | AJ50: 18451985 | AK50: 18676629 | AL50: 18916434 | AM50: 19137141 | AN50: 19370113 | AO50: 19594498 | AP50: 19829422 | AQ50: 20055804 | AR50: 20288808 | AS50: 20514809 | AT50: 20754289 | AU50: 20989076 | AV50: 21236344 | AW50: 21485765 | AX50: 21735976 | AY50: 21989058 | AZ50: 22244027 | BA50: 22501974 | BB50: 22762109 | BC50: 23025549 | BD50: 23291946
C51: Tasa de crecimiento del PIB Nacional [%] | E51: -0.0077251159 | F51: -0.07856463 | G51: 0.11046939 | H51: -0.01221735 | I51: 0.059959875 | J51: -0.010975871 | K51: 0.054422784 | L51: -0.015067482 | M51: 0.055471049 | N51: -0.0056314741 | O51: 0.041862053 | P51: -0.0069127689 | Q51: 0.048663441 | R51: -0.0029066481 | S51: 0.042364147 | T51: -0.0010367634 | U51: 0.03381942 | V51: 0.0033815986 | W51: 0.030044803 | X51: 0.0035935501 | Y51: 0.030177377 | Z51: 0.0048558983 | AA51: 0.025736092 | AB51: 0.006097554 | AC51: 0.018661335 | AD51: 0.0071260039 | AE51: 0.018290905 | AF51: 0.0092021605 | AG51: 0.01688184 | AH51: 0.0052614865 | AI51: 0.015643168 | AJ51: 0.0061633309 | AK51: 0.012174525 | AL51: 0.012839855 | AM51: 0.011667469 | AN51: 0.012173825 | AO51: 0.011584052 | AP51: 0.011989329 | AQ51: 0.011416458 | AR51: 0.011617758 | AS51: 0.011139205 | AT51: 0.011673543 | AU51: 0.011312668 | AV51: 0.01178079 | AW51: 0.011744996 | AX51: 0.011645463 | AY51: 0.011643463 | AZ51: 0.011595248 | BA51: 0.011596266 | BB51: 0.011560533 | BC51: 0.01157363 | BD51: 0.011569619
C53: Sector H - Transporte y almacenamiento
C54: PIB Sector N [Miles USD 2021] | D54: 8027157.6 | E54: 8120225.4 | F54: 6927977.3 | G54: 7835677.5 | H54: 7699029 | I54: 8287017.9 | J54: 8193333.6 | K54: 8756320.8 | L54: 8644358.1 | M54: 9240044.1 | N54: 9207860.2 | O54: 9707414.8 | P54: 9663790.1 | Q54: 10237036 | R54: 10241450 | S54: 10773069 | T54: 10809777 | U54: 11270024 | V54: 11368570 | W54: 11804027 | X54: 11917572 | Y54: 12371564 | Z54: 12512289 | AA54: 12929805 | AB54: 13097671 | AC54: 13439198 | AD54: 13631463 | AE54: 13980623 | AF54: 14213200 | AG54: 14556718 | AH54: 14743974 | AI54: 15082226 | AJ54: 15292450 | AK54: 15590334 | AL54: 15905507 | AM54: 16208034 | AN54: 16525211 | AO54: 16838820 | AP54: 17165531 | AQ54: 17488888 | AR54: 17821836 | AS54: 18152810 | AT54: 18499349 | AU54: 18846026 | AV54: 19207425 | AW54: 19575227 | AX54: 19948173 | AY54: 20328281 | AZ54: 20714682 | BA54: 21108485 | BB54: 21509024 | BC54: 21917432 | BD54: 22333495
...

Sheet Calibración_BAU_USCUSS
B1: Referencia | F1: Ecuador | G1: 2008 | H1: 2009 | I1: 2010 | J1: 2011 | K1: 2012 | L1: 2013 | M1: 2014 | N1: 2015 | O1: 2016 | P1: 2017 | Q1: 2018 | R1: 2019 | S1: 2020 | T1: 2021 | U1: 2022 | V1: 2023 | W1: 2024 | X1: 2025 | Y1: 2026 | Z1: 2027 | AA1: 2028 | AB1: 2029 | AC1: 2030 | AD1: 2031 | AE1: 2032 | AF1: 2033 | AG1: 2034 | AH1: 2035 | AI1: 2036 | AJ1: 2037 | AK1: 2038 | AL1: 2039 | AM1: 2040 | AN1: 2041 | AO1: 2042 | AP1: 2043 | AQ1: 2044 | AR1: 2045 | AS1: 2046 | AT1: 2047 | AU1: 2048 | AV1: 2049 | AW1: 2050 | AX1: 2051 | AY1: 2052 | AZ1: 2053 | BA1: 2054 | BB1: 2055 | BC1: 2056 | BD1: 2057 | BE1: 2058 | BF1: 2059 | BG1: 2060 | BH1: 2061 | BI1: 2062 | BJ1: 2063 | BK1: 2064 | BL1: 2065 | BM1: 2066 | BN1: 2067 | BO1: 2068 | BP1: 2069 | BQ1: 2070
D3: DATOS PARA CALIBRAR PROYECCIONES
E6: GRÁFICO UTCUTS-1 | F6: TABLA UTCUTS - 1: Cobertura uso de suelos
F7: Uso de suelos [ha]
B8: ESPAC | F8: Montes y bosques [ha] | I8: 3504127 | J8: 3536454 | K8: 3583056 | L8: 3538424 | M8: 5758859 | N8: 5729799 | O8: 5773290 | P8: 5675402 | Q8: 5740641 | R8: 6040896 | S8: 6112324 | T8: 5900560 | U8: 5900560 | V8: 5900560 | W8: 5900560 | X8: 5900560 | Y8: 5900560 | Z8: 5900560 | AA8: 5900560 | AB8: 5900560 | AC8: 5900560 | AD8: 5900560 | AE8: 5900560 | AF8: 5900560 | AG8: 5900560 | AH8: 5900560 | AI8: 5900560 | AJ8: 5900560 | AK8: 5900560 | AL8: 5900560 | AM8: 5900560 | AN8: 5900560 | AO8: 5900560 | AP8: 5900560 | AQ8: 5900560 | AR8: 5900560 | AS8: 5900560 | AT8: 5900560 | AU8: 5900560 | AV8: 5900560 | AW8: 5900560
F9: Cultivos permanentes [ha] | I9: 1391379 | J9: 1379473 | K9: 1382918 | L9: 1469363 | M9: 1417104 | N9: 1483366 | O9: 1439117 | P9: 1430497 | Q9: 1385805 | R9: 1439504 | S9: 1442973 | T9: 1423372 | U9: 1423372 | V9: 1423372 | W9: 1423372 | X9: 1423372 | Y9: 1423372 | Z9: 1423372 | AA9: 1423372 | AB9: 1423372 | AC9: 1423372 | AD9: 1423372 | AE9: 1423372 | AF9: 1423372 | AG9: 1423372 | AH9: 1423372 | AI9: 1423372 | AJ9: 1423372 | AK9: 1423372 | AL9: 1423372 | AM9: 1423372 | AN9: 1423372 | AO9: 1423372 | AP9: 1423372 | AQ9: 1423372 | AR9: 1423372 | AS9: 1423372 | AT9: 1423372 | AU9: 1423372 | AV9: 1423372 | AW9: 1423372
F10: Cultivos transitorios y barbechos [ha] | I10: 992369 | J10: 982312 | K10: 1020870 | L10: 1003271 | M10: 876498 | N10: 950649 | O10: 849685 | P10: 904224 | Q10: 799494 | R10: 769708 | S10: 822516 | T10: 841994 | U10: 841994 | V10: 841994 | W10: 841994 | X10: 841994 | Y10: 841994 | Z10: 841994 | AA10: 841994 | AB10: 841994 | AC10: 841994 | AD10: 841994 | AE10: 841994 | AF10: 841994 | AG10: 841994 | AH10: 841994 | AI10: 841994 | AJ10: 841994 | AK10: 841994 | AL10: 841994 | AM10: 841994 | AN10: 841994 | AO10: 841994 | AP10: 841994 | AQ10: 841994 | AR10: 841994 | AS10: 841994 | AT10: 841994 | AU10: 841994 | AV10: 841994 | AW10: 841994
F11: Descanso [ha] | I11: 193957 | J11: 173442 | K11: 126982 | L11: 191159 | M11: 93574 | N11: 117390 | O11: 125946 | P11: 129268 | Q11: 168446 | R11: 219492 | S11: 215014 | T11: 163017 | U11: 163017 | V11: 163017 | W11: 163017 | X11: 163017 | Y11: 163017 | Z11: 163017 | AA11: 163017 | AB11: 163017 | AC11: 163017 | AD11: 163017 | AE11: 163017 | AF11: 163017 | AG11: 163017 | AH11: 163017 | AI11: 163017 | AJ11: 163017 | AK11: 163017 | AL11: 163017 | AM11: 163017 | AN11: 163017 | AO11: 163017 | AP11: 163017 | AQ11: 163017 | AR11: 163017 | AS11: 163017 | AT11: 163017 | AU11: 163017 | AV11: 163017 | AW11: 163017
F12: Otros usos [ha] | I12: 217058 | J12: 210584 | K12: 205657 | L12: 216225 | M12: 468180 | N12: 612090 | O12: 719109 | P12: 757791 | Q12: 796518 | R12: 662305 | S12: 681476 | T12: 712757 | U12: 712757 | V12: 712757 | W12: 712757 | X12: 712757 | Y12: 712757 | Z12: 712757 | AA12: 712757 | AB12: 712757 | AC12: 712757 | AD12: 712757 | AE12: 712757 | AF12: 712757 | AG12: 712757 | AH12: 712757 | AI12: 712757 | AJ12: 712757 | AK12: 712757 | AL12: 712757 | AM12: 712757 | AN12: 712757 | AO12: 712757 | AP12: 712757 | AQ12: 712757 | AR12: 712757 | AS12: 712757 | AT12: 712757 | AU12: 712757 | AV12: 712757 | AW12: 712757
F13: Páramos [ha] | I13: 539475 | J13: 565857 | K13: 608272 | L13: 491891 | M13: 499258 | N13: 454347 | O13: 377791 | P13: 332418 | Q13: 252612 | R13: 270986 | S13: 249139 | T13: 233074 | U13: 233074 | V13: 233074 | W13: 233074 | X13: 233074 | Y13: 233074 | Z13: 233074 | AA13: 233074 | AB13: 233074 | AC13: 233074 | AD13: 233074 | AE13: 233074 | AF13: 233074 | AG13: 233074 | AH13: 233074 | AI13: 233074 | AJ13: 233074 | AK13: 233074 | AL13: 233074 | AM13: 233074 | AN13: 233074 | AO13: 233074 | AP13: 233074 | AQ13: 233074 | AR13: 233074 | AS13: 233074 | AT13: 233074 | AU13: 233074 | AV13: 233074 | AW13: 233074
F14: Pastos cultivados [ha] | I14: 3409952 | J14: 3425412 | K14: 3553008 | L14: 3227321 | M14: 2259447 | N14: 2531442 | O14: 2300539 | P14: 2447634 | Q14: 2379042 | R14: 1985494 | S14: 2067795 | T14: 2376551 | U14: 2376551 | V14: 2376551 | W14: 2376551 | X14: 2376551 | Y14: 2376551 | Z14: 2376551 | AA14: 2376551 | AB14: 2376551 | AC14: 2376551 | AD14: 2376551 | AE14: 2376551 | AF14: 2376551 | AG14: 2376551 | AH14: 2376551 | AI14: 2376551 | AJ14: 2376551 | AK14: 2376551 | AL14: 2376551 | AM14: 2376551 | AN14: 2376551 | AO14: 2376551 | AP14: 2376551 | AQ14: 2376551 | AR14: 2376551 | AS14: 2376551 | AT14: 2376551 | AU14: 2376551 | AV14: 2376551 | AW14: 2376551
F15: Pastos permanentes [ha] | I15: 1509972 | J15: 1385547 | K15: 1423114 | L15: 1623359 | M15: 828333 | N15: 706777 | O15: 800496 | P15: 677911 | Q15: 715273 | R15: 915843 | S15: 841320 | T15: 646139 | U15: 646139 | V15: 646139 | W15: 646139 | X15: 646139 | Y15: 646139 | Z15: 646139 | AA15: 646139 | AB15: 646139 | AC15: 646139 | AD15: 646139 | AE15: 646139 | AF15: 646139 | AG15: 646139 | AH15: 646139 | AI15: 646139 | AJ15: 646139 | AK15: 646139 | AL15: 646139 | AM15: 646139 | AN15: 646139 | AO15: 646139 | AP15: 646139 | AQ15: 646139 | AR15: 646139 | AS15: 646139 | AT15: 646139 | AU15: 646139 | AV15: 646139 | AW15: 646139
F16: Uso de suelos [Mha]
B17: ESPAC | F17: Montes y bosques [Mha] | I17: =I8/1000000 -> 3.504127 | J17: =J8/1000000 -> 3.536454 | K17: =K8/1000000 -> 3.583056 | L17: =L8/1000000 -> 3.538424 | M17: =M8/1000000 -> 5.758859 | N17: =N8/1000000 -> 5.729799 | O17: =O8/1000000 -> 5.77329 | P17: =P8/1000000 -> 5.675402 | ... AW17: =AW8/1000000 -> 5.90056
F18: Cultivos permanentes [Mha] | I18: =I9/1000000 -> 1.391379 | J18: =J9/1000000 -> 1.379473 | K18: =K9/1000000 -> 1.382918 | L18: =L9/1000000 -> 1.469363 | M18: =M9/1000000 -> 1.417104 | N18: =N9/1000000 -> 1.483366 | O18: =O9/1000000 -> 1.439117 | P18: =P9/1000000 -> 1.430497 | ... AW18: =AW9/1000000 -> 1.423372
F19: Cultivos transitorios y barbechos [Mha] | I19: =I10/1000000 -> 0.992369 | J19: =J10/1000000 -> 0.982312 | K19: =K10/1000000 -> 1.02087 | L19: =L10/1000000 -> 1.003271 | M19: =M10/1000000 -> 0.876498 | N19: =N10/1000000 -> 0.950649 | O19: =O10/1000000 -> 0.849685 | P19: =P10/1000000 -> 0.904224 | ... AW19: =AW10/1000000 -> 0.841994
F20: Descanso [Mha] | I20: =I11/1000000 -> 0.193957 | J20: =J11/1000000 -> 0.173442 | K20: =K11/1000000 -> 0.126982 | L20: =L11/1000000 -> 0.191159 | M20: =M11/1000000 -> 0.093574 | N20: =N11/1000000 -> 0.11739 | O20: =O11/1000000 -> 0.125946 | P20: =P11/1000000 -> 0.129268 | ... AW20: =AW11/1000000 -> 0.163017
