Workbook
Name empty: #REF!
Name gwp.ch4: #REF!
Name gwp.n2o: #REF!

Sheet Detalles
B2: Laplantillaesunaguíapararecopilardatosnecesariosparalamodelación,nosedetallannecesariamentetodaslastecnologías.Incorporamosalgunasdeellasyescuestióndeagregarmáslíneasparacaracterizarcadatecnología.
B6: Puedendejarcomentariosenlasplantillasconformelasvanllenando,vamosaentrarperiódicamentearevisarycontestarcualquierinquitud.Tambiénpodemosagendarreunionesvirtualescuandosehayanacumuladovariaspreguntas.
B10: Enunaprimeraetapavamosamodelarhastalademandafinaldelossectores:residencial,comercial,industrial,agricultura,construcciónyotros.Altenerfuncionalelmodeloañadimosespecificidadacadasectoreincluimosusosfinales.
B14: Sialgunatecnologíanoseutilizaenelpaíspuedeneliminarlafila
B18: Sifaltaalgúntipodeinformaciónquecreanqueesimportantenosavisan.NosotrosvamosairtrabajandoenelRRSyconformeloarmemospuedenhabersolicitudesdeotrosdatos.
B23: ComentarioEquipoUSFQ:Cadaplantilla(excepto"CostosEnergía")poseeunacopialocalizadaalfinaldeldocumento.Lacopiaseutilizóparacolocar:(i)losvaloresenlasunidadesoficialesdelosreporteseinformes,(ii)comentariosrelevantes,y(iii)fuentesbibliográficas.Mientrasquelasplantillasoriginalesseutilizaronparatransformarlosvaloresalasunidadessolicitadasinicialmente.

Sheet Bitácora
A1: Persona que realizó el cambio | B1: Fecha | C1: Hoja del Cambio | D1: Descripción del Cambio
A2: Lissete Dávila | B2: 45075 | C2: Copia de Emisiones Energía | D2: Cambio de unidades de la celda C12 cambió de "Gg de contaminante/10^3 m3" a "Gg de contaminante/Mm^3"
C3: Emisiones Energía V2 | D3: Modificación de la celda D137 para tener un factor de conversión GgCO2/Mm^3 a MtonCO2/PJ. Esta modificación afectó las siguientes celdas:

Sheet Mejoras pendientes al modelo
A1: # | B1: Sector
A2: 1 | B2: Energía | C2: Mejorar la cadena de gas natural, desde importaciones hasta consumo. Considerando la componente de regasificación.

Sheet Combustibles
C1: Ecuador
D4: Combustibles fósiles
D5: Reservas probadas (puedeserunvalorparatodoelperiodo) | E5: 2018 | F5: 2019 | G5: 2020 | H5: 2021
A6: 1 | D6: Petróleo[PJ] | E6: ='Copia de Combustibles'!D6*$E$299*$E$305 -> 9490.5128 | F6: ='Copia de Combustibles'!E6*$E$299*$E$305 -> 7577.2906 | G6: ='Copia de Combustibles'!F6*$E$299*$E$305 -> 7780.8249 | H6: ='Copia de Combustibles'!G6*$E$299*$E$305 -> 7966.9133
A7: 1.2 | D7: Gas Natural [PJ] | E7: ='Copia de Combustibles'!D7*$E$302*$E$305 -> 162.95573 | F7: ='Copia de Combustibles'!E7*$E$302*$E$305 -> 151.75636 | G7: ='Copia de Combustibles'!F7*$E$302*$E$305 -> 137.36406 | H7: ='Copia de Combustibles'!G7*$E$302*$E$305 -> 146.63016
D8: Carbón [PJ]
D10: Total [PJ] | E10: =SUM(E6:E8) -> 9653.4686 | F10: =SUM(F6:F8) -> 7729.0469 | G10: =SUM(G6:G8) -> 7918.1889 | H10: =SUM(H6:H7) -> 8113.5435
D12: Potencial Hidrocarburifero (Petróleo) | E12: 2018 | F12: 2019 | G12: 2020 | H12: 2021
A13: 1 | D13: Reservas totales (3P) [PJ] | E13: ='Copia de Combustibles'!D13*$E$299*$E$305 -> 15672.14 | F13: ='Copia de Combustibles'!E13*$E$299*$E$305 -> 13020.379 | G13: ='Copia de Combustibles'!F13*$E$299*$E$305 -> 13125.054 | H13: ='Copia de Combustibles'!G13*$E$299*$E$305 -> 11985.262
A14: 1 | D14: Recursos contingentes (3C) [PJ] | E14: ='Copia de Combustibles'!D14*$E$299*$E$305 -> 8594.962 | F14: ='Copia de Combustibles'!E14*$E$299*$E$305 -> 9891.7661 | G14: ='Copia de Combustibles'!F14*$E$299*$E$305 -> 10258.128 | H14: ='Copia de Combustibles'!G14*$E$299*$E$305 -> 7100.4388
A15: 1 | D15: Recursos prospectivos [PJ] | E15: ='Copia de Combustibles'!D15*$E$299*$E$305 -> 4425.4168 | F15: ='Copia de Combustibles'!E15*$E$299*$E$305 -> 4483.5695 | G15: ='Copia de Combustibles'!F15*$E$299*$E$305 -> 4425.4168 | H15: ='Copia de Combustibles'!G15*$E$299*$E$305 -> 4855.7465
D17: Potencial Hidrocarburifero (Gas Natural) | E17: 2018 | F17: 2019 | G17: 2020 | H17: 2021
A18: 1,2 | D18: Reservas totales (3P) [PJ] | E18: ='Copia de Combustibles'!D18*$E$302*$E$305 -> 448.87338 | F18: ='Copia de Combustibles'!E18*$E$302*$E$305 -> 424.24835 | G18: ='Copia de Combustibles'!F18*$E$302*$E$305 -> 409.43911 | H18: ='Copia de Combustibles'!G18*$E$302*$E$305 -> 418.70423
A19: 1,2 | D19: Recursos contingentes (3C) [PJ] | E19: ='Copia de Combustibles'!D19*$E$302*$E$305 -> 0 | F19: ='Copia de Combustibles'!E19*$E$302*$E$305 -> 0 | G19: ='Copia de Combustibles'!F19*$E$302*$E$305 -> 0 | H19: ='Copia de Combustibles'!G19*$E$302*$E$305 -> 0
A20: 1,2 | D20: Recursos prospectivos [PJ] | E20: ='Copia de Combustibles'!D20*$E$302*$E$305 -> 0 | F20: ='Copia de Combustibles'!E20*$E$302*$E$305 -> 0 | G20: ='Copia de Combustibles'!F20*$E$302*$E$305 -> 0 | H20: ='Copia de Combustibles'!G20*$E$302*$E$305 -> 0
D22: Extracción anual | E22: 2018 | F22: 2019 | G22: 2020 | H22: 2021
A23: 1 | D23: Petróleo [PJ] | E23: ='Copia de Combustibles'!D23*$E$305 -> 1097.8784 | F23: ='Copia de Combustibles'!E23*$E$305 -> 1127.0919 | G23: ='Copia de Combustibles'!F23*$E$305 -> 1020.2949 | H23: ='Copia de Combustibles'!G23*$E$305 -> 1003.7065
A24: 1 | D24: Gas Natural [PJ] | E24: ='Copia de Combustibles'!D24*$E$305 -> 52.855462 | F24: ='Copia de Combustibles'!E24*$E$305 -> 50.385083 | G24: ='Copia de Combustibles'!F24*$E$305 -> 44.910759 | H24: ='Copia de Combustibles'!G24*$E$305 -> 45.345474
A25: 1 | D25: Carbón [PJ]
D27: Total [PJ] | E27: =SUM(E23:E24) -> 1150.7339 | F27: =SUM(F23:F24) -> 1177.477 | G27: =SUM(G23:G24) -> 1065.2056 | H27: =SUM(H23:H24) -> 1049.052
D29: **Pérdidas por extracción anual | E29: 2018 | F29: 2019 | G29: 2020 | H29: 2021
D30: Petróleo [PJ] Extrae + Importa - Entradas de refinación - Exportaciones | E30: =E23+E44+E57+E60+E65+E68-E145 -> -14.297741 | F30: =F23+F44+F57+F60+F65+F68-F145 -> 4.3826104 | G30: =G23+G44+G57+G60+G65+G68-G145 -> 17.123449 | H30: =H23+H44+H57+H60+H65+H68-H145 -> -9.9901907
D31: Gas Natural [PJ] | E31: =E24+E61+E69+E124+E125-E255 -> 20.964402 | F31: =F24+F61+F69+F124+F125-F255 -> 21.180982 | G31: =G24+G61+G69+G124+G125-G255 -> 18.895591 | H31: =H24+H61+H69+H124+H125-H255 -> 18.46924
D32: Carbón [PJ] | E32: =E61+E69+E124+E125 -> -12.015221
D34: Total [PJ] | E34: =SUM(E30:E31) -> 6.6666616 | F34: =SUM(F30:F31) -> 25.563592 | G34: =SUM(G30:G31) -> 36.01904 | H34: =SUM(H30:H31) -> 8.4790493
D36: InputActivityRatio Extracción | E36: 2018 | F36: 2019 | G36: 2020 | H36: 2021 | I36: 2022-2070
D37: Petróleo [PJ] | E37: =(E23-E30)/E23 -> 1.0130231 | F37: =(F23-F30)/F23 -> 0.99611158 | G37: =(G23-G30)/G23 -> 0.98321716 | H37: =(H23-H30)/H23 -> 1.0099533 | I37: =AVERAGE(E37:H37) -> 1.0005763
D38: Gas Natural [PJ] | E38: =(E24)/(E24-E31) -> 1.6573755 | F38: =(F24)/(F24-F31) -> 1.7252742 | G38: =(G24)/(G24-G31) -> 1.7263298 | H38: =(H24)/(H24-H31) -> 1.687196 | I38: =AVERAGE(E38:H38) -> 1.6990439
D40: No aprovechado | E40: 2018 | F40: 2019 | G40: 2020 | H40: 2021
A41: 1 | D41: Gas Natural [PJ] | E41: ='Copia de Combustibles'!D39*$E$305 -> 25.245742 | F41: ='Copia de Combustibles'!E39*$E$305 -> 25.73117 | G41: ='Copia de Combustibles'!F39*$E$305 -> 23.967719 | H41: ='Copia de Combustibles'!G39*$E$305 -> 23.255254
I42: * Esto no se introduce directamente al modelo, se usa para corroborar el comportamiento
D43: Importación | E43: 2018 | F43: 2019 | G43: 2020 | H43: 2021 | I43: 2022 | J43: 2023 | K43: 2024 | L43: 2025 | M43: 2026 | N43: 2027 | O43: 2028 | P43: 2029 | Q43: 2030 | R43: 2031 | S43: 2032 | T43: 2033 | U43: 2034 | V43: 2035 | W43: 2036 | X43: 2037 | Y43: 2038 | Z43: 2039 | AA43: 2040 | AB43: 2041 | AC43: 2042 | AD43: 2043 | AE43: 2044 | AF43: 2045 | AG43: 2046 | AH43: 2047 | AI43: 2048 | AJ43: 2049 | AK43: 2050 | AL43: 2051 | AM43: 2052 | AN43: 2053 | AO43: 2054 | AP43: 2055 | AQ43: 2056 | AR43: 2057 | AS43: 2058 | AT43: 2059 | AU43: 2060 | AV43: 2061 | AW43: 2062 | AX43: 2063 | AY43: 2064 | AZ43: 2065 | BA43: 2066 | BB43: 2067 | BC43: 2068 | BD43: 2069 | BE43: 2070
D44: Petróleo crudo [PJ] | I44: 0 | J44: 0 | K44: 0 | L44: 0 | M44: 0 | N44: 0 | O44: 0 | P44: 0 | Q44: 107.34 | R44: 152.09 | S44: 188.59 | T44: 232.28 | U44: 273.43 | V44: 345.84 | W44: 379.09 | X44: 379.09 | Y44: 379.11 | Z44: 379.11 | AA44: 379.11 | AB44: 379.11 | AC44: 379.11 | AD44: 379.11 | AE44: 379.11 | AF44: 379.11 | AG44: 379.11 | AH44: 379.11 | AI44: 379.11 | AJ44: 379.11 | AK44: 379.11 | AL44: 379.11 | AM44: 379.11 | AN44: 379.11 | AO44: 379.11 | AP44: 379.11 | AQ44: 379.11 | AR44: 379.11 | AS44: 379.11 | AT44: 379.11 | AU44: 379.11 | AV44: 379.11 | AW44: 379.11 | AX44: 379.11 | AY44: 379.11 | AZ44: 379.11 | BA44: 379.11 | BB44: 379.11 | BC44: 379.11 | BD44: 379.11 | BE44: 379.11
A45: 1 | D45: Diésel oil [PJ] | E45: ='Copia de Combustibles'!D43*$E$305 -> 117.76053 | F45: ='Copia de Combustibles'!E43*$E$305 -> 124.42923 | G45: ='Copia de Combustibles'!F43*$E$305 -> 108.25918 | H45: ='Copia de Combustibles'!G43*$E$305 -> 136.77356 | I45: 134.39 | J45: 144.65 | K45: 143.02 | L45: 152.84 | M45: 150.89 | N45: 161.29 | O45: 160.73 | P45: 169.45 | Q45: 168.68 | R45: 178.69 | S45: 178.77 | T45: 188.05 | U45: 188.69 | V45: 196.72 | W45: 198.44 | X45: 206.04 | Y45: 208.02 | Z45: 215.95 | AA45: 218.4 | AB45: 225.69 | AC45: 228.62 | AD45: 234.58 | AE45: 237.94 | AF45: 244.03 | AG45: 248.09 | AH45: 254.09 | AI45: 257.36 | AJ45: 263.26 | AK45: 266.93 | AL45: 272.14 | AM45: 277.64 | AN45: 282.91 | AO45: 288.46 | AP45: 293.94 | AQ45: 299.64 | AR45: 305.27 | AS45: 311.07 | AT45: 316.86 | AU45: 322.91 | AV45: 328.95 | AW45: 335.26 | AX45: 341.67 | AY45: 348.19 | AZ45: 354.84 | BA45: 361.59 | BB45: 368.46 | BC45: 375.46 | BD45: 382.59 | BE45: 389.86
A46: 1 | D46: Gasolina [PJ] | E46: ='Copia de Combustibles'!D44*$E$305 -> 91.607975 | F46: ='Copia de Combustibles'!E44*$E$305 -> 105.93169 | G46: ='Copia de Combustibles'!F44*$E$305 -> 78.997084 | H46: ='Copia de Combustibles'!G44*$E$305 -> 93.045175 | I46: 90.01 | J46: 114.02 | K46: 78.1 | L46: 99.44 | M46: 88.86 | N46: 121.88 | O46: 77.83 | P46: 104.83 | Q46: 88.46 | R46: 129.11 | S46: 77.87 | T46: 110.28 | U46: 88.76 | V46: 134.61 | W46: 78.55 | X46: 114.5 | Y46: 89.62 | Z46: 139.73 | AA46: 79.44 | AB46: 118.32 | AC46: 90.78 | AD46: 143.38 | AE46: 80.58 | AF46: 121.35 | AG46: 92.29 | AH46: 146.84 | AI46: 81.61 | AJ46: 124.13 | AK46: 93.58 | AL46: 149.71 | AM46: 83.26 | AN46: 126.49 | AO46: 95.41 | AP46: 152.55 | AQ46: 84.88 | AR46: 128.87 | AS46: 97.22 | AT46: 155.39 | AU46: 86.5 | AV46: 131.28 | AW46: 99.09 | AX46: 158.36 | AY46: 88.15 | AZ46: 133.79 | BA46: 100.97 | BB46: 161.36 | BC46: 89.82 | BD46: 136.33 | BE46: 102.89
A47: 1 | D47: GLP [PJ] | E47: ='Copia de Combustibles'!D45*$E$305 -> 43.389807 | F47: ='Copia de Combustibles'!E45*$E$305 -> 47.274512 | G47: ='Copia de Combustibles'!F45*$E$305 -> 48.313115 | H47: ='Copia de Combustibles'!G45*$E$305 -> 49.878195 | I47: 50.85 | J47: 51.85 | K47: 52.88 | L47: 53.86 | M47: 54.75 | N47: 55.89 | O47: 56.91 | P47: 57.87 | Q47: 58.81 | R47: 60.03 | S47: 61.02 | T47: 62.2 | U47: 63.19 | V47: 64.24 | W47: 65.3 | X47: 66.33 | Y47: 67.34 | Z47: 68.42 | AA47: 69.41 | AB47: 70.42 | AC47: 71.4 | AD47: 72.25 | AE47: 73.21 | AF47: 74.07 | AG47: 75.05 | AH47: 75.91 | AI47: 76.74 | AJ47: 77.58 | AK47: 78.41 | AL47: 79.32 | AM47: 80.12 | AN47: 80.89 | AO47: 81.68 | AP47: 82.46 | AQ47: 83.24 | AR47: 83.96 | AS47: 84.68 | AT47: 85.38 | AU47: 86.05 | AV47: 86.7 | AW47: 87.33 | AX47: 87.93 | AY47: 88.52 | AZ47: 89.08 | BA47: 89.62 | BB47: 90.13 | BC47: 90.61 | BD47: 91.07 | BE47: 91.49
A48: 1 | D48: Fuel oil [PJ] | E48: ='Copia de Combustibles'!D46*$E$305 -> 24.078346 | F48: ='Copia de Combustibles'!E46*$E$305 -> 25.523332 | G48: ='Copia de Combustibles'!F46*$E$305 -> 17.832535 | H48: ='Copia de Combustibles'!G46*$E$305 -> 13.861503 | I48: 14.39 | J48: 14.7 | K48: 15.28 | L48: 15.54 | M48: 16.03 | N48: 16.38 | O48: 16.98 | P48: 17.18 | Q48: 17.71 | R48: 18.12 | S48: 18.68 | T48: 19.07 | U48: 19.63 | V48: 19.96 | W48: 20.56 | X48: 20.9 | Y48: 21.47 | Z48: 21.9 | AA48: 22.46 | AB48: 22.87 | AC48: 23.43 | AD48: 23.75 | AE48: 24.31 | AF48: 24.68 | AG48: 25.27 | AH48: 25.66 | AI48: 26.15 | AJ48: 26.55 | AK48: 27.05 | AL48: 27.57 | AM48: 28.09 | AN48: 28.62 | AO48: 29.14 | AP48: 29.69 | AQ48: 30.24 | AR48: 30.8 | AS48: 31.36 | AT48: 31.93 | AU48: 32.52 | AV48: 33.12 | AW48: 33.74 | AX48: 34.36 | AY48: 35 | AZ48: 35.65 | BA48: 36.31 | BB48: 36.98 | BC48: 37.66 | BD48: 38.36 | BE48: 39.07
A49: 1 | D49: Jet Fuel [PJ] | G49: ='Copia de Combustibles'!F47*$E$305 -> 0.93795161 | I49: 1 | J49: 1.04 | K49: 1.07 | L49: 1.1 | M49: 1.12 | N49: 1.16 | O49: 1.19 | P49: 1.21 | Q49: 1.24 | R49: 1.28 | S49: 1.31 | T49: 1.35 | U49: 1.38 | V49: 1.42 | W49: 1.45 | X49: 1.49 | Y49: 1.52 | Z49: 1.56 | AA49: 1.6 | AB49: 1.63 | AC49: 1.67 | AD49: 1.7 | AE49: 1.73 | AF49: 1.77 | AG49: 1.81 | AH49: 1.84 | AI49: 1.87 | AJ49: 1.91 | AK49: 1.94 | AL49: 1.98 | AM49: 2.02 | AN49: 2.05 | AO49: 2.09 | AP49: 2.13 | AQ49: 2.16 | AR49: 2.2 | AS49: 2.24 | AT49: 2.28 | AU49: 2.31 | AV49: 2.35 | AW49: 2.39 | AX49: 2.43 | AY49: 2.47 | AZ49: 2.51 | BA49: 2.54 | BB49: 2.58 | BC49: 2.62 | BD49: 2.66 | BE49: 2.7
A50: 1 | D50: Coque de Petróleo [PJ] | E50: ='Copia de Combustibles'!D48*$E$305 -> 5.5666818 | F50: ='Copia de Combustibles'!E48*$E$305 -> 4.4513001 | G50: ='Copia de Combustibles'!F48*$E$305 -> 5.1349055 | H50: ='Copia de Combustibles'!G48*$E$305 -> 5.6722964 | I50: 6.17 | J50: 5.99 | K50: 6.63 | L50: 6.37 | M50: 7.03 | N50: 6.78 | O50: 7.5 | P50: 7.19 | Q50: 7.85 | R50: 7.65 | S50: 8.27 | T50: 8.11 | U50: 8.68 | V50: 8.54 | W50: 9.08 | X50: 8.99 | Y50: 9.47 | Z50: 9.46 | AA50: 9.91 | AB50: 9.93 | AC50: 10.34 | AD50: 10.35 | AE50: 10.74 | AF50: 10.79 | AG50: 11.18 | AH50: 11.26 | AI50: 11.57 | AJ50: 11.68 | AK50: 11.99 | AL50: 12.25 | AM50: 12.49 | AN50: 12.76 | AO50: 13 | AP50: 13.28 | AQ50: 13.53 | AR50: 13.82 | AS50: 14.09 | AT50: 14.38 | AU50: 14.66 | AV50: 14.97 | AW50: 15.28 | AX50: 15.59 | AY50: 15.9 | AZ50: 16.22 | BA50: 16.55 | BB50: 16.89 | BC50: 17.23 | BD50: 17.58 | BE50: 17.94
D52: Total [PJ] | E52: =SUM(E44:E50) -> 282.40334 | F52: =SUM(F44:F50) -> 307.61006 | G52: =SUM(G44:G50) -> 259.47477 | H52: =SUM(H44:H50) -> 299.23073 | I52: =SUM(I44:I50) -> 296.81 | J52: =SUM(J44:J50) -> 332.25 | K52: =SUM(K44:K50) -> 296.98 | L52: =SUM(L44:L50) -> 329.15 | ... BE52: =SUM(BE44:BE50) -> 1023.06
...

Sheet Electricidad
B1: Ecuador
D4: Generación eléctrica
D5: Capacidad instalada (SNI) [GW] | E5: 2018 | F5: 2019 | G5: 2020 | H5: 2021
D6: Biomasa | E6: ='Copia de Electricidad'!D7/1000 -> 0.1443 | F6: ='Copia de Electricidad'!E7/1000 -> 0.1443 | G6: ='Copia de Electricidad'!F7/1000 -> 0.1443 | H6: ='Copia de Electricidad'!G7/1000 -> 0.1443
D7: Turbovapor
C8: PP_SUG | D8: Bagazo de caña | E8: ='Copia de Electricidad'!D9/1000 -> 0.1443 | F8: ='Copia de Electricidad'!E9/1000 -> 0.1443 | G8: ='Copia de Electricidad'!F9/1000 -> 0.1443 | H8: ='Copia de Electricidad'!G9/1000 -> 0.1443
C9: PP_WND_US | D9: Eólica | E9: ='Copia de Electricidad'!D10/1000 -> 0.0165 | F9: ='Copia de Electricidad'!E10/1000 -> 0.0165 | G9: ='Copia de Electricidad'!F10/1000 -> 0.0165 | H9: ='Copia de Electricidad'!G10/1000 -> 0.0165
D10: Hidraúlica | E10: ='Copia de Electricidad'!D11/1000 -> 5.060344 | F10: ='Copia de Electricidad'!E11/1000 -> 5.070344 | G10: ='Copia de Electricidad'!F11/1000 -> 5.092686 | H10: ='Copia de Electricidad'!G11/1000 -> 5.100786
D11: Embalse | E11: ='Copia de Electricidad'!D12/1000 -> 1.7332 | F11: ='Copia de Electricidad'!E12/1000 -> 1.7332 | G11: ='Copia de Electricidad'!F12/1000 -> 1.7332 | H11: ='Copia de Electricidad'!G12/1000 -> 1.7332
D12: Amazonas | E12: ='Copia de Electricidad'!D13/1000 -> 1.478 | F12: ='Copia de Electricidad'!E13/1000 -> 1.478 | G12: ='Copia de Electricidad'!F13/1000 -> 1.478 | H12: ='Copia de Electricidad'!G13/1000 -> 1.478
D13: Pacífico | E13: ='Copia de Electricidad'!D14/1000 -> 0.2552 | F13: ='Copia de Electricidad'!E14/1000 -> 0.2552 | G13: ='Copia de Electricidad'!F14/1000 -> 0.2552 | H13: ='Copia de Electricidad'!G14/1000 -> 0.2552
D14: Pasada | E14: ='Copia de Electricidad'!D15/1000 -> 3.327144 | F14: ='Copia de Electricidad'!E15/1000 -> 3.337144 | G14: ='Copia de Electricidad'!F15/1000 -> 3.359486 | H14: ='Copia de Electricidad'!G15/1000 -> 3.367586
D15: Amazonas | E15: ='Copia de Electricidad'!D16/1000 -> 2.93939 | F15: ='Copia de Electricidad'!E16/1000 -> 2.94939 | G15: ='Copia de Electricidad'!F16/1000 -> 2.961586 | H15: ='Copia de Electricidad'!G16/1000 -> 2.969686
D16: Pacífico | E16: ='Copia de Electricidad'!D17/1000 -> 0.387754 | F16: ='Copia de Electricidad'!E17/1000 -> 0.387754 | G16: ='Copia de Electricidad'!F17/1000 -> 0.3979 | H16: ='Copia de Electricidad'!G17/1000 -> 0.3979
C17: PP_SPV_US | D17: Solar | E17: ='Copia de Electricidad'!D18/1000 -> 0.02446082 | F17: ='Copia de Electricidad'!E18/1000 -> 0.02446082 | G17: ='Copia de Electricidad'!F18/1000 -> 0.02446082 | H17: ='Copia de Electricidad'!G18/1000 -> 0.02446082
D18: Térmica | E18: ='Copia de Electricidad'!D19/1000 -> 2.1026506 | F18: ='Copia de Electricidad'!E19/1000 -> 2.0550506 | G18: ='Copia de Electricidad'!F19/1000 -> 2.0550506 | H18: ='Copia de Electricidad'!G19/1000 -> 2.0634706
D19: MCI | E19: ='Copia de Electricidad'!D20/1000 -> 0.8360556 | F19: ='Copia de Electricidad'!E20/1000 -> 0.7884556 | G19: ='Copia de Electricidad'!F20/1000 -> 0.7884556 | H19: ='Copia de Electricidad'!G20/1000 -> 0.7976756
C20: PP_DSLICE | D20: Diesel MCI | E20: ='Copia de Electricidad'!D21/1000 -> 0.3099856 | F20: ='Copia de Electricidad'!E21/1000 -> 0.2623856 | G20: ='Copia de Electricidad'!F21/1000 -> 0.2623856 | H20: ='Copia de Electricidad'!G21/1000 -> 0.2623856
C21: PP_FOIICE | D21: Fuel Oil MCI | E21: ='Copia de Electricidad'!D22/1000 -> 0.43722 | F21: ='Copia de Electricidad'!E22/1000 -> 0.43722 | G21: ='Copia de Electricidad'!F22/1000 -> 0.43722 | H21: ='Copia de Electricidad'!G22/1000 -> 0.44644
D22: Otro MCI | E22: ='Copia de Electricidad'!D23/1000 -> 0.00225 | F22: ='Copia de Electricidad'!E23/1000 -> 0.00225 | G22: ='Copia de Electricidad'!F23/1000 -> 0.00225 | H22: ='Copia de Electricidad'!G23/1000 -> 0.00225
C23: PP_WASICE | D23: Residuo MCI | E23: ='Copia de Electricidad'!D24/1000 -> 0.0866 | F23: ='Copia de Electricidad'!E24/1000 -> 0.0866 | G23: ='Copia de Electricidad'!F24/1000 -> 0.0866 | H23: ='Copia de Electricidad'!G24/1000 -> 0.0866
D24: Turbogas | E24: ='Copia de Electricidad'!D25/1000 -> 0.820595 | F24: ='Copia de Electricidad'!E25/1000 -> 0.820595 | G24: ='Copia de Electricidad'!F25/1000 -> 0.820595 | H24: ='Copia de Electricidad'!G25/1000 -> 0.819795
C25: PP_DSLTGS | D25: Diesel | E25: ='Copia de Electricidad'!D26/1000 -> 0.545235 | F25: ='Copia de Electricidad'!E26/1000 -> 0.545235 | G25: ='Copia de Electricidad'!F26/1000 -> 0.545235 | H25: ='Copia de Electricidad'!G26/1000 -> 0.544435
C26: PP_NGSTGS | D26: OC Gas Natural | E26: ='Copia de Electricidad'!D27/1000 -> 0.27536 | F26: ='Copia de Electricidad'!E27/1000 -> 0.27536 | G26: ='Copia de Electricidad'!F27/1000 -> 0.27536 | H26: ='Copia de Electricidad'!G27/1000 -> 0.27536
D27: Turbovapor | E27: ='Copia de Electricidad'!D28/1000 -> 0.446 | F27: ='Copia de Electricidad'!E28/1000 -> 0.446 | G27: ='Copia de Electricidad'!F28/1000 -> 0.446 | H27: ='Copia de Electricidad'!G28/1000 -> 0.446
C28: PP_FOITST | D28: Fuel Oil | E28: ='Copia de Electricidad'!D29/1000 -> 0.446 | F28: ='Copia de Electricidad'!E29/1000 -> 0.446 | G28: ='Copia de Electricidad'!F29/1000 -> 0.446 | H28: ='Copia de Electricidad'!G29/1000 -> 0.446
D29: Biogás | E29: ='Copia de Electricidad'!D30/1000 -> 0.00726 | F29: ='Copia de Electricidad'!E30/1000 -> 0.00726 | G29: ='Copia de Electricidad'!F30/1000 -> 0.00726 | H29: ='Copia de Electricidad'!G30/1000 -> 0.00832
D30: MCI
C31: PP_BGSICE | D31: Biogás | E31: ='Copia de Electricidad'!D32/1000 -> 0.00726 | F31: ='Copia de Electricidad'!E32/1000 -> 0.00726 | G31: ='Copia de Electricidad'!F32/1000 -> 0.00726 | H31: ='Copia de Electricidad'!G32/1000 -> 0.00832
D32: Hidroeléctrico represa [GW]
C33: PP_HYDPACDAMSMA | D33: Pacífico (pequeñas) | E33: ='Copia de Electricidad'!D34/1000 -> 0.0422 | F33: ='Copia de Electricidad'!E34/1000 -> 0.0422 | G33: ='Copia de Electricidad'!F34/1000 -> 0.0422 | H33: ='Copia de Electricidad'!G34/1000 -> 0.0422
C34: PP_HYDPACDAMMED | D34: Pacífico (medianas) | E34: ='Copia de Electricidad'!D35/1000 -> 0.213 | F34: ='Copia de Electricidad'!E35/1000 -> 0.213 | G34: ='Copia de Electricidad'!F35/1000 -> 0.213 | H34: ='Copia de Electricidad'!G35/1000 -> 0.213
C35: PP_HYDPACDAMLAR | D35: Pacífico (grandes)
C36: PP_HYDAMADAMSMA | D36: Amazonas (pequeñas)
C37: PP_HYDAMADAMMED | D37: Amazonas (medianas) | E37: ='Copia de Electricidad'!D38/1000 -> 0.403 | F37: ='Copia de Electricidad'!E38/1000 -> 0.403 | G37: ='Copia de Electricidad'!F38/1000 -> 0.403 | H37: ='Copia de Electricidad'!G38/1000 -> 0.403
C38: PP_HYDAMADAMLAR | D38: Amazonas (grandes) | E38: ='Copia de Electricidad'!D39/1000 -> 1.075 | F38: ='Copia de Electricidad'!E39/1000 -> 1.075 | G38: ='Copia de Electricidad'!F39/1000 -> 1.075 | H38: ='Copia de Electricidad'!G39/1000 -> 1.075
D39: Hidroeléctrico filo de agua [GW]
C40: PP_HYDPACRORSMA | D40: Pacífico (pequeñas) | E40: ='Copia de Electricidad'!D41/1000 -> 0.054394 | F40: ='Copia de Electricidad'!E41/1000 -> 0.054394 | G40: ='Copia de Electricidad'!F41/1000 -> 0.06454 | H40: ='Copia de Electricidad'!G41/1000 -> 0.06454
C41: PP_HYDPACRORMED | D41: Pacífico (medianas) | E41: ='Copia de Electricidad'!D42/1000 -> 0.33336 | F41: ='Copia de Electricidad'!E42/1000 -> 0.33336 | G41: ='Copia de Electricidad'!F42/1000 -> 0.33336 | H41: ='Copia de Electricidad'!G42/1000 -> 0.33336
C42: PP_HYDPACRORLAR | D42: Pacífico (grandes)
...

Sheet Hidrógeno
D1: Ecuador | E1: 2018 | F1: 2019 | G1: 2020 | H1: 2021 | I1: 2022 | J1: 2023 | K1: 2024 | L1: 2025 | M1: 2026 | N1: 2027 | O1: 2028 | P1: 2029 | Q1: 2030 | R1: 2031 | S1: 2032 | T1: 2033 | U1: 2034 | V1: 2035 | W1: 2036 | X1: 2037 | Y1: 2038 | Z1: 2039 | AA1: 2040 | AB1: 2041 | AC1: 2042 | AD1: 2043 | AE1: 2044 | AF1: 2045 | AG1: 2046 | AH1: 2047 | AI1: 2048 | AJ1: 2049 | AK1: 2050 | AL1: 2051 | AM1: 2052 | AN1: 2053 | AO1: 2054 | AP1: 2055 | AQ1: 2056 | AR1: 2057 | AS1: 2058 | AT1: 2059 | AU1: 2060 | AV1: 2061 | AW1: 2062 | AX1: 2063 | AY1: 2064 | AZ1: 2065 | BA1: 2066 | BB1: 2067 | BC1: 2068 | BD1: 2069 | BE1: 2070
D3: [PJ]
C4: Electrolyzer | D4: Efficiency electricidad (PJ) para producir un PJ de hidrógeno | E4: 0.7 | F4: 0.7 | G4: 0.7 | H4: 0.7 | I4: 0.7 | J4: 0.7 | K4: 0.7 | L4: 0.7 | M4: 0.7 | N4: 0.7 | O4: 0.7 | P4: 0.7 | Q4: 0.7 | R4: 0.7 | S4: 0.7 | T4: 0.7 | U4: 0.7 | V4: 0.7 | W4: 0.7 | X4: 0.7 | Y4: 0.7 | Z4: 0.7 | AA4: 0.7 | AB4: 0.7 | AC4: 0.7 | AD4: 0.7 | AE4: 0.7 | AF4: 0.7 | AG4: 0.7 | AH4: 0.7 | AI4: 0.7 | AJ4: 0.7 | AK4: 0.7 | AL4: 0.7 | AM4: 0.7 | AN4: 0.7 | AO4: 0.7 | AP4: 0.7 | AQ4: 0.7 | AR4: 0.7 | AS4: 0.7 | AT4: 0.7 | AU4: 0.7 | AV4: 0.7 | AW4: 0.7 | AX4: 0.7 | AY4: 0.7 | AZ4: 0.7 | BA4: 0.7 | BB4: 0.7 | BC4: 0.7 | BD4: 0.7 | BE4: 0.7
D5: Lifetime | E5: 30 | F5: 30 | G5: 30 | H5: 30 | I5: 30 | J5: 30 | K5: 30 | L5: 30 | M5: 30 | N5: 30 | O5: 30 | P5: 30 | Q5: 30 | R5: 30 | S5: 30 | T5: 30 | U5: 30 | V5: 30 | W5: 30 | X5: 30 | Y5: 30 | Z5: 30 | AA5: 30 | AB5: 30 | AC5: 30 | AD5: 30 | AE5: 30 | AF5: 30 | AG5: 30 | AH5: 30 | AI5: 30 | AJ5: 30 | AK5: 30 | AL5: 30 | AM5: 30 | AN5: 30 | AO5: 30 | AP5: 30 | AQ5: 30 | AR5: 30 | AS5: 30 | AT5: 30 | AU5: 30 | AV5: 30 | AW5: 30 | AX5: 30 | AY5: 30 | AZ5: 30 | BA5: 30 | BB5: 30 | BC5: 30 | BD5: 30 | BE5: 30
C8: Parameter_Category | D8: Parameter | E8: Set | F8: Source | G8: Info_Type | H8: Value_Type | I8: Units | J8: Projection Mode | K8: Value
C9: Transport | D9: Levelized cost of transport | E9: Pipeline Cost at 1000 km | F9: IRENA 2022 - Part 2 | G9: Numerical | H9: Min | I9: $/kg | J9: Flat | K9: 0.1
C10: Transport | D10: Levelized cost of transport | E10: Pipeline Cost at 1000 km | F10: IRENA 2022 - Part 2 | G10: Numerical | H10: Max | I10: $/kg | J10: Flat | K10: 2
C11: General | D11: Specific energy | E11: Hydrogeno | F11: Ammonia for power (Science Direct) | G11: Numerical | H11: LHV | I11: MJ/kg | J11: Flat | K11: 120
I13: M$/PJ | J13: Flat | K13: =K9/120*1000 -> 0.83333333 | L13: M$/PJ | M13: =AVERAGE(K13:K14) -> 8.75
I14: M$/PJ | J14: Flat | K14: =K10/120*1000 -> 16.666667

Sheet Calculos electricidad
D1: Ecuador | E1: 2018 | F1: 2019 | G1: 2020 | H1: 2021 | I1: 2022 | J1: 2023 | K1: 2024 | L1: 2025 | M1: 2026 | N1: 2027 | O1: 2028 | P1: 2029 | Q1: 2030 | R1: 2031 | S1: 2032 | T1: 2033 | U1: 2034 | V1: 2035 | W1: 2036 | X1: 2037 | Y1: 2038 | Z1: 2039 | AA1: 2040 | AB1: 2041 | AC1: 2042 | AD1: 2043 | AE1: 2044 | AF1: 2045 | AG1: 2046 | AH1: 2047 | AI1: 2048 | AJ1: 2049 | AK1: 2050 | AL1: 2051 | AM1: 2052 | AN1: 2053 | AO1: 2054 | AP1: 2055 | AQ1: 2056 | AR1: 2057 | AS1: 2058 | AT1: 2059 | AU1: 2060 | AV1: 2061 | AW1: 2062 | AX1: 2063 | AY1: 2064 | AZ1: 2065 | BA1: 2066 | BB1: 2067 | BC1: 2068 | BD1: 2069 | BE1: 2070
D4: Generación eléctrica
D6: Capacidad instalada (SNI)
D7: Biomasa [GW] | E7: =Electricidad!E6 -> 0.1443 | F7: =Electricidad!F6 -> 0.1443 | G7: =Electricidad!G6 -> 0.1443 | H7: =Electricidad!H6 -> 0.1443
D8: Eólica [GW] | E8: =Electricidad!E9 -> 0.0165 | F8: =Electricidad!F9 -> 0.0165 | G8: =Electricidad!G9 -> 0.0165 | H8: =Electricidad!H9 -> 0.0165
D9: Hidroeléctrico represa [GW] | E9: =SUM(E10:E15) -> 1.7332 | F9: =SUM(F10:F15) -> 1.7332 | G9: =SUM(G10:G15) -> 1.7332 | H9: =SUM(H10:H15) -> 1.7332
D10: Pacífico (pequeñas) | E10: =Electricidad!E33 -> 0.0422 | F10: =Electricidad!F33 -> 0.0422 | G10: =Electricidad!G33 -> 0.0422 | H10: =Electricidad!H33 -> 0.0422
D11: Pacífico (medianas) | E11: =Electricidad!E34 -> 0.213 | F11: =Electricidad!F34 -> 0.213 | G11: =Electricidad!G34 -> 0.213 | H11: =Electricidad!H34 -> 0.213
D12: Pacífico (grandes) | E12: =Electricidad!E35 -> 0 | F12: =Electricidad!F35 -> 0 | G12: =Electricidad!G35 -> 0 | H12: =Electricidad!H35 -> 0
D13: Amazonas (pequeñas) | E13: =Electricidad!E36 -> 0 | F13: =Electricidad!F36 -> 0 | G13: =Electricidad!G36 -> 0 | H13: =Electricidad!H36 -> 0
D14: Amazonas (medianas) | E14: =Electricidad!E37 -> 0.403 | F14: =Electricidad!F37 -> 0.403 | G14: =Electricidad!G37 -> 0.403 | H14: =Electricidad!H37 -> 0.403
D15: Amazonas (grandes) | E15: =Electricidad!E38 -> 1.075 | F15: =Electricidad!F38 -> 1.075 | G15: =Electricidad!G38 -> 1.075 | H15: =Electricidad!H38 -> 1.075
D16: Hidroeléctrico filo de agua [GW] | E16: =SUM(E17:E22) -> 3.327144 | F16: =SUM(F17:F22) -> 3.337144 | G16: =SUM(G17:G22) -> 3.359486 | H16: =SUM(H17:H22) -> 3.367586
D17: Pacífico (pequeñas) | E17: =Electricidad!E40 -> 0.054394 | F17: =Electricidad!F40 -> 0.054394 | G17: =Electricidad!G40 -> 0.06454 | H17: =Electricidad!H40 -> 0.06454
D18: Pacífico (medianas) | E18: =Electricidad!E41 -> 0.33336 | F18: =Electricidad!F41 -> 0.33336 | G18: =Electricidad!G41 -> 0.33336 | H18: =Electricidad!H41 -> 0.33336
D19: Pacífico (grandes) | E19: =Electricidad!E42 -> 0 | F19: =Electricidad!F42 -> 0 | G19: =Electricidad!G42 -> 0 | H19: =Electricidad!H42 -> 0
D20: Amazonas (pequeñas) | E20: =Electricidad!E43 -> 0.54239 | F20: =Electricidad!F43 -> 0.55239 | G20: =Electricidad!G43 -> 0.500282 | H20: =Electricidad!H43 -> 0.508382
D21: Amazonas (medianas) | E21: =Electricidad!E44 -> 0.41 | F21: =Electricidad!F44 -> 0.41 | G21: =Electricidad!G44 -> 0.474304 | H21: =Electricidad!H44 -> 0.474304
D22: Amazonas (grandes) | E22: =Electricidad!E45 -> 1.987 | F22: =Electricidad!F45 -> 1.987 | G22: =Electricidad!G45 -> 1.987 | H22: =Electricidad!H45 -> 1.987
D23: Solar [GW] | E23: 0.02446082 | F23: 0.02446082 | G23: 0.02446082 | H23: 0.02446082
D24: Otro
D25: MCI
D26: Diesel | E26: =Electricidad!E20 -> 0.3099856 | F26: =Electricidad!F20 -> 0.2623856 | G26: =Electricidad!G20 -> 0.2623856 | H26: =Electricidad!H20 -> 0.2623856
D27: Fuel Oil | E27: =Electricidad!E21 -> 0.43722 | F27: =Electricidad!F21 -> 0.43722 | G27: =Electricidad!G21 -> 0.43722 | H27: =Electricidad!H21 -> 0.44644
D28: Otro | E28: =Electricidad!E22 -> 0.00225 | F28: =Electricidad!F22 -> 0.00225 | G28: =Electricidad!G22 -> 0.00225 | H28: =Electricidad!H22 -> 0.00225
D29: Residuo | E29: =Electricidad!E23 -> 0.0866 | F29: =Electricidad!F23 -> 0.0866 | G29: =Electricidad!G23 -> 0.0866 | H29: =Electricidad!H23 -> 0.0866
D30: Turbogas
D31: Diesel | E31: =Electricidad!E25 -> 0.545235 | F31: =Electricidad!F25 -> 0.545235 | G31: =Electricidad!G25 -> 0.545235 | H31: =Electricidad!H25 -> 0.544435
D32: Gas Natural | E32: =Electricidad!E26 -> 0.27536 | F32: =Electricidad!F26 -> 0.27536 | G32: =Electricidad!G26 -> 0.27536 | H32: =Electricidad!H26 -> 0.27536
D33: Turbovapor
D34: Fuel Oil | E34: =Electricidad!E28 -> 0.446 | F34: =Electricidad!F28 -> 0.446 | G34: =Electricidad!G28 -> 0.446 | H34: =Electricidad!H28 -> 0.446
D35: Biogás [GW] | E35: =Electricidad!E29 -> 0.00726 | F35: =Electricidad!F29 -> 0.00726 | G35: =Electricidad!G29 -> 0.00726 | H35: =Electricidad!H29 -> 0.00832
D36: Total | E36: =SUM(E7:E35)-E9-E16 -> 7.3555154 | F36: =SUM(F7:F35)-F9-F16 -> 7.3179154 | G36: =SUM(G7:G35)-G9-G16 -> 7.3402574 | H36: =SUM(H7:H35)-H9-H16 -> 7.3578374
D38: Capacidad instalada (Aislados) Reordenado
D39: GALÁPAGOS
D40: Eólica | E40: =Electricidad!E51 -> 0.00465 | F40: =Electricidad!F51 -> 0.00465 | G40: =Electricidad!G51 -> 0.00465 | H40: =Electricidad!H51 -> 0.00465
D41: Diesel MCI | E41: =Electricidad!E68 -> 0.027582 | F41: =Electricidad!F68 -> 0.024147 | G41: =Electricidad!G68 -> 0.024285 | H41: =Electricidad!H68 -> 0.024285
D42: Solar | E42: =Electricidad!E61 -> 0.00259642 | F42: =Electricidad!F61 -> 0.00259642 | G42: =Electricidad!G61 -> 0.00259642 | H42: =Electricidad!H61 -> 0.00261976
D44: ELÉCTRIFICACIÓN RURAL
D45: Hidro Amazonas | E45: =Electricidad!E55 -> 0.00116 | F45: =Electricidad!F55 -> 0.00116 | G45: =Electricidad!G55 -> 0.00116 | H45: =Electricidad!H55 -> 0.00116
...

Sheet Demanda_energia
D1: Ecuador | E1: 2018 | F1: 2019 | G1: 2020 | H1: 2021 | I1: 2022 | J1: 2023 | K1: 2024 | L1: 2025 | M1: 2026 | N1: 2027 | O1: 2028 | P1: 2029 | Q1: 2030 | R1: 2031 | S1: 2032 | T1: 2033 | U1: 2034 | V1: 2035 | W1: 2036 | X1: 2037 | Y1: 2038 | Z1: 2039 | AA1: 2040 | AB1: 2041 | AC1: 2042 | AD1: 2043 | AE1: 2044 | AF1: 2045 | AG1: 2046 | AH1: 2047 | AI1: 2048 | AJ1: 2049 | AK1: 2050 | AL1: 2051 | AM1: 2052 | AN1: 2053 | AO1: 2054 | AP1: 2055 | AQ1: 2056 | AR1: 2057 | AS1: 2058 | AT1: 2059 | AU1: 2060 | AV1: 2061 | AW1: 2062 | AX1: 2063 | AY1: 2064 | AZ1: 2065 | BA1: 2066 | BB1: 2067 | BC1: 2068 | BD1: 2069 | BE1: 2070
D4: Demandas de combustibles
D5: Demandas de Gasolina
A6: 1 | D6: Demanda residencial [PJ] | E6: - | F6: - | G6: - | H6: - | I6: - | J6: - | K6: - | L6: - | M6: - | N6: - | O6: - | P6: - | Q6: - | R6: - | S6: - | T6: - | U6: - | V6: - | W6: - | X6: - | Y6: - | Z6: - | AA6: - | AB6: - | AC6: - | AD6: - | AE6: - | AF6: - | AG6: - | AH6: - | AI6: - | AJ6: - | AK6: - | AL6: - | AM6: - | AN6: - | AO6: - | AP6: - | AQ6: - | AR6: - | AS6: - | AT6: - | AU6: - | AV6: - | AW6: - | AX6: - | AY6: - | AZ6: - | BA6: - | BB6: - | BC6: - | BD6: - | BE6: -
A7: 1 | C7: E5_COMPURGSL | D7: Demanda comercial y servicios públicos [PJ] | E7: ='Copia de Demandas de energía '!D7*$E$89 -> 0.099128536 | F7: ='Copia de Demandas de energía '!E7*$E$89 -> 0.12304462 | G7: ='Copia de Demandas de energía '!F7*$E$89 -> 0.034599036 | H7: ='Copia de Demandas de energía '!G7*$E$89 -> 0.23700358 | I7: 0 | J7: 0.25 | K7: 0.25 | L7: 0.26 | M7: 0.26 | N7: 0.28 | O7: 0.28 | P7: 0.29 | Q7: 0.29 | R7: 0.3 | S7: 0.31 | T7: 0.32 | U7: 0.32 | V7: 0.33 | W7: 0.34 | X7: 0.35 | Y7: 0.35 | Z7: 0.36 | AA7: 0.37 | AB7: 0.38 | AC7: 0.38 | AD7: 0.39 | AE7: 0.39 | AF7: 0.4 | AG7: 0.41 | AH7: 0.42 | AI7: 0.42 | AJ7: 0.43 | AK7: 0.43 | AL7: 0.44 | AM7: 0.45 | AN7: 0.45 | AO7: 0.46 | AP7: 0.47 | AQ7: 0.47 | AR7: 0.48 | AS7: 0.48 | AT7: 0.49 | AU7: 0.5 | AV7: 0.5 | AW7: 0.51 | AX7: 0.51 | AY7: 0.52 | AZ7: 0.53 | BA7: 0.53 | BB7: 0.54 | BC7: 0.54 | BD7: 0.55 | BE7: 0.55
A8: 1,2 | C8: E5_INDPURGSL | D8: Demanda Industrial [PJ] | E8: ='Copia de Demandas de energía '!D8*$E$89 -> 0.61379802 | F8: ='Copia de Demandas de energía '!E8*$E$89 -> 0.85415239 | G8: ='Copia de Demandas de energía '!F8*$E$89 -> 0.7482621 | H8: ='Copia de Demandas de energía '!G8*$E$89 -> 1.0382512 | I8: 0.90639122 | J8: 1.1 | K8: 1.14 | L8: 1.16 | M8: 1.2 | N8: 1.23 | O8: 1.27 | P8: 1.29 | Q8: 1.33 | R8: 1.36 | S8: 1.4 | T8: 1.43 | U8: 1.47 | V8: 1.49 | W8: 1.54 | X8: 1.57 | Y8: 1.61 | Z8: 1.64 | AA8: 1.68 | AB8: 1.71 | AC8: 1.76 | AD8: 1.78 | AE8: 1.82 | AF8: 1.85 | AG8: 1.89 | AH8: 1.92 | AI8: 1.96 | AJ8: 1.99 | AK8: 2.03 | AL8: 2.07 | AM8: 2.1 | AN8: 2.14 | AO8: 2.18 | AP8: 2.22 | AQ8: 2.26 | AR8: 2.31 | AS8: 2.35 | AT8: 2.39 | AU8: 2.44 | AV8: 2.48 | AW8: 2.53 | AX8: 2.57 | AY8: 2.62 | AZ8: 2.67 | BA8: 2.72 | BB8: 2.77 | BC8: 2.82 | BD8: 2.87 | BE8: 2.93
A9: 1 | C9: E5_CONPURGSL | D9: Demanda construcción y otros [PJ] | E9: ='Copia de Demandas de energía '!D9*$E$89 -> 34.952289 | F9: ='Copia de Demandas de energía '!E9*$E$89 -> 32.606013 | G9: ='Copia de Demandas de energía '!F9*$E$89 -> 25.107181 | H9: ='Copia de Demandas de energía '!G9*$E$89 -> 20.302985 | I9: 17.793157 | J9: 22.1825 | K9: 22.93 | L9: 23.62 | M9: 24.3475 | N9: 25.14 | O9: 25.925 | P9: 26.6075 | Q9: 27.3325 | R9: 28.115 | S9: 28.9025 | T9: 29.6775 | U9: 30.425 | V9: 31.1675 | W9: 31.93 | X9: 32.69 | Y9: 33.4675 | Z9: 34.28 | AA9: 35.085 | AB9: 35.89 | AC9: 36.6575 | AD9: 37.3875 | AE9: 38.135 | AF9: 38.92 | AG9: 39.7275 | AH9: 40.5025 | AI9: 41.2375 | AJ9: 41.985 | AK9: 42.8675 | AL9: 43.83 | AM9: 44.7325 | AN9: 45.6425 | AO9: 46.565 | AP9: 47.5075 | AQ9: 48.47 | AR9: 49.4475 | AS9: 50.44 | AT9: 51.4575 | AU9: 52.505 | AV9: 53.5825 | AW9: 54.6825 | AX9: 55.795 | AY9: 56.925 | AZ9: 58.0775 | BA9: 59.255 | BB9: 60.4575 | BC9: 61.685 | BD9: 62.9375 | BE9: 64.21
A10: 1 | C10: E5_AGRPURGSL | D10: Demanda Agro, pesca y minería [PJ] | E10: ='Copia de Demandas de energía '!D10*$E$89 -> 4.7630758 | F10: ='Copia de Demandas de energía '!E10*$E$89 -> 5.2140193 | G10: ='Copia de Demandas de energía '!F10*$E$89 -> 4.8432446 | H10: ='Copia de Demandas de energía '!G10*$E$89 -> 5.4102096 | I10: 5.3645578 | J10: 5.76 | K10: 5.94 | L10: 6.08 | M10: 6.2 | N10: 6.36 | O10: 6.49 | P10: 6.58 | Q10: 6.67 | R10: 6.81 | S10: 6.9 | T10: 7.02 | U10: 7.1 | V10: 7.19 | W10: 7.3 | X10: 7.4 | Y10: 7.51 | Z10: 7.65 | AA10: 7.78 | AB10: 7.93 | AC10: 8.08 | AD10: 8.22 | AE10: 8.4 | AF10: 8.57 | AG10: 8.78 | AH10: 8.97 | AI10: 9.16 | AJ10: 9.37 | AK10: 9.57 | AL10: 9.75 | AM10: 9.94 | AN10: 10.13 | AO10: 10.33 | AP10: 10.54 | AQ10: 10.76 | AR10: 10.98 | AS10: 11.2 | AT10: 11.44 | AU10: 11.67 | AV10: 11.92 | AW10: 12.16 | AX10: 12.42 | AY10: 12.67 | AZ10: 12.93 | BA10: 13.19 | BB10: 13.46 | BC10: 13.73 | BD10: 14.01 | BE10: 14.3
A11: 1 | D11: Demanda transporte [PJ]
A12: 1 | D12: Terrestre carga | E12: ='Copia de Demandas de energía '!D12*$E$89 -> 62.130723 | F12: ='Copia de Demandas de energía '!E12*$E$89 -> 63.134677 | G12: ='Copia de Demandas de energía '!F12*$E$89 -> 49.270364 | H12: ='Copia de Demandas de energía '!G12*$E$89 -> 64.154308 | I12: 63.04 | J12: 67.85 | K12: 67.08 | L12: 71.69 | M12: 70.78 | N12: 75.65 | O12: 75.39 | P12: 79.48 | Q12: 79.12 | R12: 83.82 | S12: 83.85 | T12: 88.2 | U12: 88.5 | V12: 92.27 | W12: 93.08 | X12: 96.65 | Y12: 97.57 | Z12: 101.29 | AA12: 102.44 | AB12: 105.86 | AC12: 107.24 | AD12: 110.03 | AE12: 111.61 | AF12: 114.47 | AG12: 116.37 | AH12: 119.18 | AI12: 120.72 | AJ12: 123.49 | AK12: 125.21 | AL12: 127.65 | AM12: 130.23 | AN12: 132.7 | AO12: 135.3 | AP12: 137.87 | AQ12: 140.55 | AR12: 143.19 | AS12: 145.91 | AT12: 148.62 | AU12: 151.46 | AV12: 154.29 | AW12: 157.26 | AX12: 160.26 | AY12: 163.32 | AZ12: 166.44 | BA12: 169.6 | BB12: 172.83 | BC12: 176.11 | BD12: 179.46 | BE12: 182.87
A13: 1,2 | D13: Terrestre pasajeros | E13: ='Copia de Demandas de energía '!D13*$E$89 -> 58.736211 | F13: ='Copia de Demandas de energía '!E13*$E$89 -> 59.685002 | G13: ='Copia de Demandas de energía '!F13*$E$89 -> 46.916968 | H13: ='Copia de Demandas de energía '!G13*$E$89 -> 61.090189 | I13: 61.91 | J13: 62.73 | K13: 63.53 | L13: 64.33 | M13: 65.12 | N13: 65.9 | O13: 66.68 | P13: 67.44 | Q13: 68.19 | R13: 68.93 | S13: 69.66 | T13: 70.38 | U13: 71.09 | V13: 71.78 | W13: 72.46 | X13: 73.13 | Y13: 73.78 | Z13: 74.42 | AA13: 75.05 | AB13: 75.66 | AC13: 76.25 | AD13: 76.83 | AE13: 77.4 | AF13: 77.95 | AG13: 78.48 | AH13: 79 | AI13: 79.5 | AJ13: 79.98 | AK13: 80.45 | AL13: 80.91 | AM13: 81.34 | AN13: 81.76 | AO13: 82.17 | AP13: 82.55 | AQ13: 82.92 | AR13: 83.27 | AS13: 83.61 | AT13: 83.92 | AU13: 84.22 | AV13: 84.49 | AW13: 84.75 | AX13: 84.99 | AY13: 85.21 | AZ13: 85.41 | BA13: 85.59 | BB13: 85.75 | BC13: 85.9 | BD13: 86.02 | BE13: 86.12
A14: 1 | C14: E5_SHITRNPURGSL | D14: Marítimo | E14: ='Copia de Demandas de energía '!D14*$E$89 -> 0.030774744 | F14: ='Copia de Demandas de energía '!E14*$E$89 -> 0.0034839332 | G14: ='Copia de Demandas de energía '!F14*$E$89 -> 0.0098711442 | H14: ='Copia de Demandas de energía '!G14*$E$89 -> 0.019742288 | I14: 0.02 | J14: 0.02 | K14: 0.02 | L14: 0.02 | M14: 0.02 | N14: 0.02 | O14: 0.02 | P14: 0.02 | Q14: 0.03 | R14: 0.03 | S14: 0.03 | T14: 0.03 | U14: 0.03 | V14: 0.03 | W14: 0.03 | X14: 0.03 | Y14: 0.03 | Z14: 0.03 | AA14: 0.03 | AB14: 0.03 | AC14: 0.03 | AD14: 0.03 | AE14: 0.04 | AF14: 0.04 | AG14: 0.04 | AH14: 0.04 | AI14: 0.04 | AJ14: 0.04 | AK14: 0.04 | AL14: 0.04 | AM14: 0.04 | AN14: 0.04 | AO14: 0.04 | AP14: 0.04 | AQ14: 0.04 | AR14: 0.04 | AS14: 0.05 | AT14: 0.05 | AU14: 0.05 | AV14: 0.05 | AW14: 0.05 | AX14: 0.05 | AY14: 0.05 | AZ14: 0.05 | BA14: 0.05 | BB14: 0.05 | BC14: 0.05 | BD14: 0.05 | BE14: 0.05
A15: 1 | C15: E5_AERTRNPURGSL | D15: Aéreo | E15: 4.7630758 | F15: 5.2140193 | G15: 4.8432446 | H15: 5.4102096 | I15: 5.3645578 | J15: 5.76 | K15: 5.94 | L15: 6.08 | M15: 6.2 | N15: 6.36 | O15: 6.49 | P15: 6.58 | Q15: 6.67 | R15: 6.81 | S15: 6.9 | T15: 7.02 | U15: 7.1 | V15: 7.19 | W15: 7.3 | X15: 7.4 | Y15: 7.51 | Z15: 7.65 | AA15: 7.78 | AB15: 7.93 | AC15: 8.08 | AD15: 8.22 | AE15: 8.4 | AF15: 8.57 | AG15: 8.78 | AH15: 8.97 | AI15: 9.16 | AJ15: 9.37 | AK15: 9.57 | AL15: 9.75 | AM15: 9.94 | AN15: 10.13 | AO15: 10.33 | AP15: 10.54 | AQ15: 10.76 | AR15: 10.98 | AS15: 11.2 | AT15: 11.44 | AU15: 11.67 | AV15: 11.92 | AW15: 12.16 | AX15: 12.42 | AY15: 12.67 | AZ15: 12.93 | BA15: 13.19 | BB15: 13.46 | BC15: 13.73 | BD15: 14.01 | BE15: 14.3
D16: Total [PJ] | E16: =SUM(E6:E15) -> 166.08908 | F16: =SUM(F6:F15) -> 166.83441 | G16: =SUM(G6:G15) -> 131.77373 | H16: =SUM(H6:H15) -> 157.6629 | I16: =SUM(I6:I15) -> 154.39866 | J16: =SUM(J6:J15) -> 165.6525 | K16: =SUM(K6:K15) -> 166.83 | L16: =SUM(L6:L15) -> 173.24 | ... BE16: =SUM(BE6:BE15) -> 365.33
D18: Demandas de Diesel
D19: Demanda residencial [PJ] | E19: - | F19: - | G19: - | H19: -
C20: E5_COMPURDSL | D20: Demanda comercial y servicios públicos [PJ] | E20: ='Copia de Demandas de energía '!D20*$E$89 -> 5.736839 | F20: ='Copia de Demandas de energía '!E20*$E$89 -> 4.7138773 | G20: ='Copia de Demandas de energía '!F20*$E$89 -> 4.5998941 | H20: ='Copia de Demandas de energía '!G20*$E$89 -> 4.3899412 | I20: 6.0873467 | J20: 4.58 | K20: 4.7 | L20: 4.8125 | M20: 4.925 | N20: 5.055 | O20: 5.1825 | P20: 5.295 | Q20: 5.42 | R20: 5.565 | S20: 5.71 | T20: 5.8525 | U20: 5.99 | V20: 6.125 | W20: 6.2625 | X20: 6.3975 | Y20: 6.535 | Z20: 6.6775 | AA20: 6.8175 | AB20: 6.9525 | AC20: 7.08 | AD20: 7.2 | AE20: 7.32 | AF20: 7.445 | AG20: 7.575 | AH20: 7.695 | AI20: 7.805 | AJ20: 7.9175 | AK20: 8.0325 | AL20: 8.155 | AM20: 8.2775 | AN20: 8.3925 | AO20: 8.51 | AP20: 8.63 | AQ20: 8.7475 | AR20: 8.8625 | AS20: 8.9775 | AT20: 9.0925 | AU20: 9.205 | AV20: 9.3125 | AW20: 9.42 | AX20: 9.53 | AY20: 9.6375 | AZ20: 9.7425 | BA20: 9.8475 | BB20: 9.95 | BC20: 10.05 | BD20: 10.1475 | BE20: 10.24
A21: 2 | C21: E5_INDPURDSL | D21: Demanda Industrial [PJ] | E21: ='Copia de Demandas de energía '!D21*$E$89 -> 25.584823 | F21: ='Copia de Demandas de energía '!E21*$E$89 -> 22.023941 | G21: ='Copia de Demandas de energía '!F21*$E$89 -> 21.491394 | H21: ='Copia de Demandas de energía '!G21*$E$89 -> 20.510462 | I21: 28.440349 | J21: 21.75 | K21: 22.61 | L21: 22.99 | M21: 23.72 | N21: 24.24 | O21: 25.12 | P21: 25.42 | Q21: 26.21 | R21: 26.8 | S21: 27.64 | T21: 28.22 | U21: 29.04 | V21: 29.53 | W21: 30.42 | X21: 30.93 | Y21: 31.77 | Z21: 32.4 | AA21: 33.23 | AB21: 33.84 | AC21: 34.67 | AD21: 35.14 | AE21: 35.97 | AF21: 36.52 | AG21: 37.4 | AH21: 37.98 | AI21: 38.69 | AJ21: 39.29 | AK21: 40.02 | AL21: 40.8 | AM21: 41.56 | AN21: 42.35 | AO21: 43.12 | AP21: 43.93 | AQ21: 44.74 | AR21: 45.57 | AS21: 46.4 | AT21: 47.25 | AU21: 48.12 | AV21: 49.01 | AW21: 49.93 | AX21: 50.85 | AY21: 51.79 | AZ21: 52.75 | BA21: 53.72 | BB21: 54.72 | BC21: 55.73 | BD21: 56.76 | BE21: 57.81
A22: 2 | C22: E5_CONPURDSL | D22: Demanda construcción y otros [PJ] | E22: ='Copia de Demandas de energía '!D22*$E$89 -> 2.5489151 | F22: ='Copia de Demandas de energía '!E22*$E$89 -> 2.9144162 | G22: ='Copia de Demandas de energía '!F22*$E$89 -> 0.67387279 | H22: ='Copia de Demandas de energía '!G22*$E$89 -> 3.1559712 | I22: 5.8671401 | J22: 3.445 | K22: 3.5625 | L22: 3.67 | M22: 3.7825 | N22: 3.905 | O22: 4.0275 | P22: 4.135 | Q22: 4.2475 | R22: 4.3675 | S22: 4.49 | T22: 4.6125 | U22: 4.73 | V22: 4.845 | W22: 4.9625 | X22: 5.08 | Y22: 5.2025 | Z22: 5.33 | AA22: 5.4525 | AB22: 5.5775 | AC22: 5.7 | AD22: 5.815 | AE22: 5.93 | AF22: 6.05 | AG22: 6.175 | AH22: 6.295 | AI22: 6.41 | AJ22: 6.5275 | AK22: 6.665 | AL22: 6.815 | AM22: 6.955 | AN22: 7.095 | AO22: 7.2375 | AP22: 7.385 | AQ22: 7.535 | AR22: 7.6875 | AS22: 7.8425 | AT22: 8 | AU22: 8.1625 | AV22: 8.33 | AW22: 8.5 | AX22: 8.6725 | AY22: 8.85 | AZ22: 9.03 | BA22: 9.2125 | BB22: 9.4 | BC22: 9.59 | BD22: 9.7825 | BE22: 9.98
A23: 2 | D23: Demanda Agro, pesca y minería [PJ] | E23: - | F23: - | G23: - | H23: -
D24: Demanda transporte [PJ]
A25: 2 | D25: Terrestre carga | E25: ='Copia de Demandas de energía '!D25*$E$89 -> 119.77472 | F25: ='Copia de Demandas de energía '!E25*$E$89 -> 121.70947 | G25: ='Copia de Demandas de energía '!F25*$E$89 -> 103.25101 | H25: ='Copia de Demandas de energía '!G25*$E$89 -> 116.77854 | I25: 114.74 | J25: 123.51 | K25: 122.11 | L25: 130.5 | M25: 128.83 | N25: 137.71 | O25: 137.23 | P25: 144.67 | Q25: 144.02 | R25: 152.57 | S25: 152.63 | T25: 160.56 | U25: 161.1 | V25: 167.96 | W25: 169.43 | X25: 175.92 | Y25: 177.61 | Z25: 184.38 | AA25: 186.48 | AB25: 192.7 | AC25: 195.2 | AD25: 200.29 | AE25: 203.16 | AF25: 208.36 | AG25: 211.83 | AH25: 216.95 | AI25: 219.74 | AJ25: 224.78 | AK25: 227.91 | AL25: 232.35 | AM25: 237.05 | AN25: 241.55 | AO25: 246.29 | AP25: 250.97 | AQ25: 255.83 | AR25: 260.64 | AS25: 265.6 | AT25: 270.54 | AU25: 275.7 | AV25: 280.86 | AW25: 286.25 | AX25: 291.72 | AY25: 297.29 | AZ25: 302.97 | BA25: 308.73 | BB25: 314.59 | BC25: 320.57 | BD25: 326.66 | BE25: 332.87
A26: 2 | D26: Terrestre pasajeros | E26: ='Copia de Demandas de energía '!D26*$E$89 -> 8.5942826 | F26: ='Copia de Demandas de energía '!E26*$E$89 -> 8.7330593 | G26: ='Copia de Demandas de energía '!F26*$E$89 -> 7.408584 | H26: ='Copia de Demandas de energía '!G26*$E$89 -> 8.3794401 | I26: 8.49 | J26: 8.6 | K26: 8.71 | L26: 8.82 | M26: 8.93 | N26: 9.04 | O26: 9.15 | P26: 9.25 | Q26: 9.35 | R26: 9.46 | S26: 9.56 | T26: 9.65 | U26: 9.75 | V26: 9.85 | W26: 9.94 | X26: 10.03 | Y26: 10.12 | Z26: 10.21 | AA26: 10.29 | AB26: 10.38 | AC26: 10.46 | AD26: 10.54 | AE26: 10.62 | AF26: 10.69 | AG26: 10.76 | AH26: 10.84 | AI26: 10.9 | AJ26: 10.97 | AK26: 11.04 | AL26: 11.1 | AM26: 11.16 | AN26: 11.22 | AO26: 11.27 | AP26: 11.32 | AQ26: 11.37 | AR26: 11.42 | AS26: 11.47 | AT26: 11.51 | AU26: 11.55 | AV26: 11.59 | AW26: 11.62 | AX26: 11.66 | AY26: 11.69 | AZ26: 11.72 | BA26: 11.74 | BB26: 11.76 | BC26: 11.78 | BD26: 11.8 | BE26: 11.81
C27: E5_SHITRNPURDSL | D27: Marítimo | E27: ='Copia de Demandas de energía '!D27*$E$89 -> 11.47956 | F27: ='Copia de Demandas de energía '!E27*$E$89 -> 11.546335 | G27: ='Copia de Demandas de energía '!F27*$E$89 -> 9.8560471 | H27: ='Copia de Demandas de energía '!G27*$E$89 -> 11.926665 | I27: 12.25 | J27: 12.63 | K27: 13.01 | L27: 13.36 | M27: 13.67 | N27: 14.1 | O27: 14.5 | P27: 14.82 | Q27: 15.17 | R27: 15.65 | S27: 16.04 | T27: 16.5 | U27: 16.9 | V27: 17.29 | W27: 17.74 | X27: 18.14 | Y27: 18.56 | Z27: 19.03 | AA27: 19.46 | AB27: 19.91 | AC27: 20.35 | AD27: 20.71 | AE27: 21.16 | AF27: 21.55 | AG27: 22.05 | AH27: 22.45 | AI27: 22.86 | AJ27: 23.27 | AK27: 23.69 | AL27: 24.17 | AM27: 24.61 | AN27: 25.04 | AO27: 25.49 | AP27: 25.94 | AQ27: 26.41 | AR27: 26.86 | AS27: 27.31 | AT27: 27.77 | AU27: 28.24 | AV27: 28.7 | AW27: 29.16 | AX27: 29.63 | AY27: 30.09 | AZ27: 30.56 | BA27: 31.03 | BB27: 31.49 | BC27: 31.96 | BD27: 32.43 | BE27: 32.9
D28: Aéreo | E28: - | F28: - | G28: - | H28: - | I28: - | J28: - | K28: - | L28: - | M28: - | N28: - | O28: - | P28: - | Q28: - | R28: - | S28: - | T28: - | U28: - | V28: - | W28: - | X28: - | Y28: - | Z28: - | AA28: - | AB28: - | AC28: - | AD28: - | AE28: - | AF28: - | AG28: - | AH28: - | AI28: - | AJ28: - | AK28: - | AL28: - | AM28: - | AN28: - | AO28: - | AP28: - | AQ28: - | AR28: - | AS28: - | AT28: - | AU28: - | AV28: - | AW28: - | AX28: - | AY28: - | AZ28: - | BA28: - | BB28: - | BC28: - | BD28: - | BE28: -
D29: Total [PJ] | E29: =SUM(E19:E28) -> 173.71914 | F29: =SUM(F19:F28) -> 171.64109 | G29: =SUM(G19:G28) -> 147.2808 | H29: =SUM(H19:H28) -> 165.14102 | I29: =SUM(I19:I28) -> 175.87484 | J29: =SUM(J19:J28) -> 174.515 | K29: =SUM(K19:K28) -> 174.7025 | L29: =SUM(L19:L28) -> 184.1525 | ... BE29: =SUM(BE19:BE28) -> 455.61
D31: Demandas de GLP
A32: 2 | C32: E5_RESLPG | D32: Demanda residencial [PJ] | E32: ='Copia de Demandas de energía '!D32*$E$89 -> 37.188178 | F32: ='Copia de Demandas de energía '!E32*$E$89 -> 38.367604 | G32: ='Copia de Demandas de energía '!F32*$E$89 -> 39.136215 | H32: ='Copia de Demandas de energía '!G32*$E$89 -> 39.917656 | I32: 41.30297 | J32: 40.99 | K32: 41.51 | L32: 42.04 | M32: 42.55 | N32: 43.06 | O32: 43.57 | P32: 44.07 | Q32: 44.56 | R32: 45.04 | S32: 45.52 | T32: 45.99 | U32: 46.45 | V32: 46.9 | W32: 47.35 | X32: 47.78 | Y32: 48.21 | Z32: 48.63 | AA32: 49.04 | AB32: 49.44 | AC32: 49.82 | AD32: 50.2 | AE32: 50.57 | AF32: 50.93 | AG32: 51.28 | AH32: 51.62 | AI32: 51.95 | AJ32: 52.26 | AK32: 52.57 | AL32: 52.87 | AM32: 53.15 | AN32: 53.43 | AO32: 53.69 | AP32: 53.94 | AQ32: 54.18 | AR32: 54.41 | AS32: 54.63 | AT32: 54.83 | AU32: 55.03 | AV32: 55.21 | AW32: 55.38 | AX32: 55.53 | AY32: 55.68 | AZ32: 55.81 | BA32: 55.93 | BB32: 56.03 | BC32: 56.13 | BD32: 56.21 | BE32: 56.27
C33: E5_COMLPG | D33: Demanda comercial y servicios públicos [PJ] | E33: ='Copia de Demandas de energía '!D33*$E$89 -> 2.3911178 | F33: ='Copia de Demandas de energía '!E33*$E$89 -> 2.3977572 | G33: ='Copia de Demandas de energía '!F33*$E$89 -> 2.2406901 | H33: ='Copia de Demandas de energía '!G33*$E$89 -> 2.3810968 | I33: 2.6552615 | J33: 2.4875 | K33: 2.5525 | L33: 2.6125 | M33: 2.6725 | N33: 2.7425 | O33: 2.81 | P33: 2.87 | Q33: 2.9375 | R33: 3.015 | S33: 3.0925 | T33: 3.17 | U33: 3.245 | V33: 3.3175 | W33: 3.3925 | X33: 3.4675 | Y33: 3.545 | Z33: 3.625 | AA33: 3.7 | AB33: 3.7725 | AC33: 3.8425 | AD33: 3.9075 | AE33: 3.9725 | AF33: 4.04 | AG33: 4.11 | AH33: 4.175 | AI33: 4.235 | AJ33: 4.295 | AK33: 4.3575 | AL33: 4.425 | AM33: 4.49 | AN33: 4.5525 | AO33: 4.6175 | AP33: 4.6825 | AQ33: 4.7475 | AR33: 4.81 | AS33: 4.87 | AT33: 4.93 | AU33: 4.99 | AV33: 5.05 | AW33: 5.11 | AX33: 5.17 | AY33: 5.23 | AZ33: 5.2875 | BA33: 5.3425 | BB33: 5.3975 | BC33: 5.45 | BD33: 5.5025 | BE33: 5.56
A34: 2 | C34: E5_INDLPG | D34: Demanda Industrial [PJ] | E34: ='Copia de Demandas de energía '!D34*$E$89 -> 3.9680445 | F34: ='Copia de Demandas de energía '!E34*$E$89 -> 4.1453384 | G34: ='Copia de Demandas de energía '!F34*$E$89 -> 3.6902606 | H34: ='Copia de Demandas de energía '!G34*$E$89 -> 4.1259798 | I34: 4.2501614 | J34: 4.37 | K34: 4.55 | L34: 4.63 | M34: 4.77 | N34: 4.88 | O34: 5.05 | P34: 5.11 | Q34: 5.27 | R34: 5.39 | S34: 5.56 | T34: 5.68 | U34: 5.84 | V34: 5.94 | W34: 6.12 | X34: 6.22 | Y34: 6.39 | Z34: 6.52 | AA34: 6.69 | AB34: 6.81 | AC34: 6.97 | AD34: 7.07 | AE34: 7.24 | AF34: 7.35 | AG34: 7.52 | AH34: 7.64 | AI34: 7.78 | AJ34: 7.9 | AK34: 8.05 | AL34: 8.21 | AM34: 8.36 | AN34: 8.52 | AO34: 8.67 | AP34: 8.84 | AQ34: 9 | AR34: 9.17 | AS34: 9.33 | AT34: 9.5 | AU34: 9.68 | AV34: 9.86 | AW34: 10.04 | AX34: 10.23 | AY34: 10.42 | AZ34: 10.61 | BA34: 10.81 | BB34: 11.01 | BC34: 11.21 | BD34: 11.42 | BE34: 11.63
C35: E5_CONLPG | D35: Demanda construcción y otros [PJ] | E35: ='Copia de Demandas de energía '!D35*$E$89 -> 5.77117 | F35: ='Copia de Demandas de energía '!E35*$E$89 -> 7.8918634 | G35: ='Copia de Demandas de energía '!F35*$E$89 -> 8.4675547 | H35: ='Copia de Demandas de energía '!G35*$E$89 -> 8.6230478 | I35: 9.8256294 | J35: 9.42 | K35: 9.7375 | L35: 10.0325 | M35: 10.3425 | N35: 10.6775 | O35: 11.01 | P35: 11.3 | Q35: 11.61 | R35: 11.945 | S35: 12.28 | T35: 12.6075 | U35: 12.9225 | V35: 13.2375 | W35: 13.5625 | X35: 13.885 | Y35: 14.215 | Z35: 14.5625 | AA35: 14.905 | AB35: 15.245 | AC35: 15.57 | AD35: 15.88 | AE35: 16.1975 | AF35: 16.53 | AG35: 16.8725 | AH35: 17.2025 | AI35: 17.515 | AJ35: 17.8325 | AK35: 18.21 | AL35: 18.62 | AM35: 19 | AN35: 19.385 | AO35: 19.7775 | AP35: 20.1775 | AQ35: 20.5875 | AR35: 21.005 | AS35: 21.4275 | AT35: 21.8575 | AU35: 22.3 | AV35: 22.7575 | AW35: 23.2225 | AX35: 23.6925 | AY35: 24.1725 | AZ35: 24.6625 | BA35: 25.1625 | BB35: 25.675 | BC35: 26.2 | BD35: 26.7325 | BE35: 27.27
A36: 2 | C36: E5_AGRLPG | D36: Demanda Agro, pesca y minería [PJ] | E36: ='Copia de Demandas de energía '!D36*$E$89 -> 1.0525426 | F36: ='Copia de Demandas de energía '!E36*$E$89 -> 1.1384701 | G36: ='Copia de Demandas de energía '!F36*$E$89 -> 0.9331363 | H36: ='Copia de Demandas de energía '!G36*$E$89 -> 1.0966181 | I36: 1.0278244 | J36: 1.17 | K36: 1.2 | L36: 1.23 | M36: 1.26 | N36: 1.29 | O36: 1.32 | P36: 1.33 | Q36: 1.35 | R36: 1.38 | S36: 1.4 | T36: 1.42 | U36: 1.44 | V36: 1.46 | W36: 1.48 | X36: 1.5 | Y36: 1.52 | Z36: 1.55 | AA36: 1.58 | AB36: 1.61 | AC36: 1.64 | AD36: 1.67 | AE36: 1.7 | AF36: 1.74 | AG36: 1.78 | AH36: 1.82 | AI36: 1.86 | AJ36: 1.9 | AK36: 1.94 | AL36: 1.98 | AM36: 2.01 | AN36: 2.05 | AO36: 2.09 | AP36: 2.14 | AQ36: 2.18 | AR36: 2.23 | AS36: 2.27 | AT36: 2.32 | AU36: 2.37 | AV36: 2.42 | AW36: 2.47 | AX36: 2.52 | AY36: 2.57 | AZ36: 2.62 | BA36: 2.67 | BB36: 2.73 | BC36: 2.78 | BD36: 2.84 | BE36: 2.9
D37: Demanda transporte (terrestre pasajeros) [PJ]
D38: Terrestre carga | E38: - | F38: - | G38: - | H38: - | I38: - | J38: - | K38: - | L38: - | M38: - | N38: - | O38: - | P38: - | Q38: - | R38: - | S38: - | T38: - | U38: - | V38: - | W38: - | X38: - | Y38: - | Z38: - | AA38: - | AB38: - | AC38: - | AD38: - | AE38: - | AF38: - | AG38: - | AH38: - | AI38: - | AJ38: - | AK38: - | AL38: - | AM38: - | AN38: - | AO38: - | AP38: - | AQ38: - | AR38: - | AS38: - | AT38: - | AU38: - | AV38: - | AW38: - | AX38: - | AY38: - | AZ38: - | BA38: - | BB38: - | BC38: - | BD38: - | BE38: -
A39: 2 | D39: Terrestre pasajeros | E39: ='Copia de Demandas de energía '!D39*$E$89 -> 0.25392067 | F39: ='Copia de Demandas de energía '!E39*$E$89 -> 0.28806321 | G39: ='Copia de Demandas de energía '!F39*$E$89 -> 0.3147153 | H39: ='Copia de Demandas de energía '!G39*$E$89 -> 0.55202922 | I39: 0.56 | J39: 0.57 | K39: 0.57 | L39: 0.58 | M39: 0.59 | N39: 0.6 | O39: 0.6 | P39: 0.61 | Q39: 0.62 | R39: 0.62 | S39: 0.63 | T39: 0.64 | U39: 0.64 | V39: 0.65 | W39: 0.65 | X39: 0.66 | Y39: 0.67 | Z39: 0.67 | AA39: 0.68 | AB39: 0.68 | AC39: 0.69 | AD39: 0.69 | AE39: 0.7 | AF39: 0.7 | AG39: 0.71 | AH39: 0.71 | AI39: 0.72 | AJ39: 0.72 | AK39: 0.73 | AL39: 0.73 | AM39: 0.74 | AN39: 0.74 | AO39: 0.74 | AP39: 0.75 | AQ39: 0.75 | AR39: 0.75 | AS39: 0.76 | AT39: 0.76 | AU39: 0.76 | AV39: 0.76 | AW39: 0.77 | AX39: 0.77 | AY39: 0.77 | AZ39: 0.77 | BA39: 0.77 | BB39: 0.77 | BC39: 0.78 | BD39: 0.78 | BE39: 0.78
D40: Marítimo | E40: - | F40: - | G40: - | H40: -
D41: Aéreo | E41: - | F41: - | G41: - | H41: -
D42: Total [PJ] | E42: =SUM(E32:E41) -> 50.624973 | F42: =SUM(F32:F41) -> 54.229097 | G42: =SUM(G32:G41) -> 54.782572 | H42: =SUM(H32:H41) -> 56.696428 | I42: =SUM(I32:I41) -> 59.621846 | J42: =SUM(J32:J41) -> 59.0075 | K42: =SUM(K32:K41) -> 60.12 | L42: =SUM(L32:L41) -> 61.125 | ... BE42: =SUM(BE32:BE41) -> 104.41
D44: Demandas de Kerosene/Jet Fuel
D45: Demanda residencial [PJ] | E45: - | F45: - | G45: - | H45: - | I45: - | J45: - | K45: - | L45: - | M45: - | N45: - | O45: - | P45: - | Q45: - | R45: - | S45: - | T45: - | U45: - | V45: - | W45: - | X45: - | Y45: - | Z45: - | AA45: - | AB45: - | AC45: - | AD45: - | AE45: - | AF45: - | AG45: - | AH45: - | AI45: - | AJ45: - | AK45: -
...

Sheet Emisiones Energía V2
C1: Ecuador | D1: 2018 | E1: 2019 | F1: 2020 | G1: 2021 | H1: 2022 | I1: 2023 | J1: 2024 | K1: 2025 | L1: 2026 | M1: 2027 | N1: 2028 | O1: 2029 | P1: 2030 | Q1: 2031 | R1: 2032 | S1: 2033 | T1: 2034 | U1: 2035 | V1: 2036 | W1: 2037 | X1: 2038 | Y1: 2039 | Z1: 2040 | AA1: 2041 | AB1: 2042 | AC1: 2043 | AD1: 2044 | AE1: 2045 | AF1: 2046 | AG1: 2047 | AH1: 2048 | AI1: 2049 | AJ1: 2050
C4: Combustibles
C5: Factores de emisión para emisiones fugitivas
A6: 1 | C6: Petróleo | D6: [Mton CO2 / PJ] | E6: [Mton CH4 / PJ] | F6: [Mton N2O / PJ] | G6: [Mton CO2eq / PJ]
C7: Venteo | D7: ='Copia de Emisiones Energía'!D7*'Emisiones Energía V2'!$D$131 -> 2.6011668e-06 | E7: ='Copia de Emisiones Energía'!E7*'Emisiones Energía V2'!$D$131 -> 1.9714106e-05 | F7: - | G7: =(D7*$D$144)+(E7*$D$145) -> 0.00049545382 | H7: Se incluyen agrupadas | I7: =G7+G8+G10+G11 -> 0.0016451372
C8: Quema en antorcha | D8: ='Copia de Emisiones Energía'!D8*'Emisiones Energía V2'!$D$131 -> 0.0011226088 | E8: ='Copia de Emisiones Energía'!E8*'Emisiones Energía V2'!$D$131 -> 6.8451757e-07 | F8: ='Copia de Emisiones Energía'!F8*'Emisiones Energía V2'!$D$131 -> 1.752365e-08 | G8: =(D8*$D$144)+(E8*$D$145)+(F8*$D$146) -> 0.0011449438
C9: Exploración | D9: ='Copia de Emisiones Energía'!D9*'Emisiones Energía V2'!$D$131 -> 2.7380703e-06 | E9: ='Copia de Emisiones Energía'!E9*'Emisiones Energía V2'!$D$131 -> 9.0356319e-07 | F9: - | G9: =(D9*$D$144)+(E9*$D$145) -> 2.532715e-05
C10: Producción y Refinación | D10: ='Copia de Emisiones Energía'!D10*'Emisiones Energía V2'!$D$131 -> 3.0118773e-09 | E10: ='Copia de Emisiones Energía'!E10*'Emisiones Energía V2'!$D$131 -> 4.1071054e-08 | F10: - | G10: =(D10*$D$144)+(E10*$D$145) -> 1.0297882e-06
C11: Transporte por tuberías | D11: ='Copia de Emisiones Energía'!D11*'Emisiones Energía V2'!$D$131 -> 1.3416544e-08 | E11: ='Copia de Emisiones Energía'!E11*'Emisiones Energía V2'!$D$131 -> 1.478558e-07 | F11: - | G11: =(D11*$D$144)+(E11*$D$145) -> 3.7098114e-06
A12: 2 | C12: Gas Natural | D12: [Mton CO2 / PJ] | E12: [Mton CH4 / PJ] | F12: [Mton N2O / PJ] | G12: [Mton CO2eq / PJ]
C13: Quema en antorcha | D13: ='Copia de Emisiones Energía'!D13*'Emisiones Energía V2'!$D$137 -> 3.4555559e-17 | E13: ='Copia de Emisiones Energía'!E13*'Emisiones Energía V2'!$D$137 -> 2.1885187e-20 | F13: ='Copia de Emisiones Energía'!F13*'Emisiones Energía V2'!$D$137 -> 6.0472227e-22 | G13: =(D13*$D$144)+(E13*$D$145)+(F13*$D$146) -> 3.5282895e-17 | H13: =G13+G15+G16+G17 -> 4.6512179e-16
C14: Exploración | D14: ='Copia de Emisiones Energía'!D14*'Emisiones Energía V2'!$D$137 -> 2.8796299e-18 | E14: ='Copia de Emisiones Energía'!E14*'Emisiones Energía V2'!$D$137 -> 9.5027786e-19 | F14: - | G14: =(D14*$D$144)+(E14*$D$145) -> 2.6636576e-17
C15: Producción | D15: ='Copia de Emisiones Energía'!D15*'Emisiones Energía V2'!$D$137 -> 4.0314818e-19 | E15: ='Copia de Emisiones Energía'!E15*'Emisiones Energía V2'!$D$137 -> 1.0942594e-17 | F15: - | G15: =(D15*$D$144)+(E15*$D$145) -> 2.7396799e-16
C16: Procesamiento | D16: ='Copia de Emisiones Energía'!D16*'Emisiones Energía V2'!$D$137 -> 3.4555559e-19 | E16: ='Copia de Emisiones Energía'!E16*'Emisiones Energía V2'!$D$137 -> 4.3194448e-18 | F16: - | G16: =(D16*$D$144)+(E16*$D$145) -> 1.0833168e-16
C17: Transmisión y almacenamiento | D17: ='Copia de Emisiones Energía'!D17*'Emisiones Energía V2'!$D$137 -> 2.5340743e-20 | E17: ='Copia de Emisiones Energía'!E17*'Emisiones Energía V2'!$D$137 -> 1.9005557e-18 | F17: - | G17: =(D17*$D$144)+(E17*$D$145) -> 4.7539234e-17 | H17: =SUM(G17:G18) -> 8.4090606e-16
C18: Distribución | D18: ='Copia de Emisiones Energía'!D18*'Emisiones Energía V2'!$D$137 -> 1.4686112e-18 | E18: ='Copia de Emisiones Energía'!E18*'Emisiones Energía V2'!$D$137 -> 3.1675929e-17 | F18: - | G18: =(D18*$D$144)+(E18*$D$145) -> 7.9336683e-16
A21: 3 | C21: Factores de emisión por quema de combustible
C23: 1A1a Producción de electricidad y calor como actividad principal
C24: Factores de emisión [Mton CO2/PJ] | D24: [Mton CO2 / PJ] | E24: [Mton CH4 / PJ] | F24: [Mton N2O / PJ] | G24: [Mton CO2eq / PJ]
C25: Gas/Diesel Oil | D25: ='Copia de Emisiones Energía'!D25*'Emisiones Energía V2'!$D$140 -> 0.0741 | E25: ='Copia de Emisiones Energía'!E25*'Emisiones Energía V2'!$D$140 -> 3e-06 | F25: ='Copia de Emisiones Energía'!F25*'Emisiones Energía V2'!$D$140 -> 6e-07 | G25: =(D25*$D$144)+(E25*$D$145)+(F25*$D$146) -> 0.0743538
C26: Fuel oil residual | D26: ='Copia de Emisiones Energía'!D26*'Emisiones Energía V2'!$D$140 -> 0.0774 | E26: ='Copia de Emisiones Energía'!E26*'Emisiones Energía V2'!$D$140 -> 3e-06 | F26: ='Copia de Emisiones Energía'!F26*'Emisiones Energía V2'!$D$140 -> 6e-07 | G26: =(D26*$D$144)+(E26*$D$145) -> 0.077475
C27: Gas Natural (seco) | D27: ='Copia de Emisiones Energía'!D27*'Emisiones Energía V2'!$D$140 -> 0.0561 | E27: ='Copia de Emisiones Energía'!E27*'Emisiones Energía V2'!$D$140 -> 1e-06 | F27: ='Copia de Emisiones Energía'!F27*'Emisiones Energía V2'!$D$140 -> 1e-07 | G27: =(D27*$D$144)+(E27*$D$145) -> 0.056125
C28: Desechos municipales | D28: ='Copia de Emisiones Energía'!D28*'Emisiones Energía V2'!$D$140 -> 0.1 | E28: ='Copia de Emisiones Energía'!E28*'Emisiones Energía V2'!$D$140 -> 3e-05 | F28: ='Copia de Emisiones Energía'!F28*'Emisiones Energía V2'!$D$140 -> 4e-06 | G28: =(D28*$D$144)+(E28*$D$145) -> 0.10075
C30: 1A1b Refinación del Petróleo
C31: Factores de emisión [Mton CO2/PJ] | D31: [Mton CO2 / PJ] | E31: [Mton CH4 / PJ] | F31: [Mton N2O / PJ] | G31: [Mton CO2eq / PJ]
A32: 65.4 | C32: Gasolina | D32: ='Copia de Emisiones Energía'!D32*'Emisiones Energía V2'!$D$140 -> 0.0693 | E32: ='Copia de Emisiones Energía'!E32*'Emisiones Energía V2'!$D$140 -> 3e-06 | F32: ='Copia de Emisiones Energía'!F32*'Emisiones Energía V2'!$D$140 -> 6e-07 | G32: =(D32*$D$144)+(E32*$D$145)+(F32*$D$146) -> 0.0695538
A33: 5.3 | C33: Queroseno | D33: ='Copia de Emisiones Energía'!D33*'Emisiones Energía V2'!$D$140 -> 0.0715 | E33: ='Copia de Emisiones Energía'!E33*'Emisiones Energía V2'!$D$140 -> 3e-06 | F33: ='Copia de Emisiones Energía'!F33*'Emisiones Energía V2'!$D$140 -> 6e-07 | G33: =(D33*$D$144)+(E33*$D$145) -> 0.071575
A34: 79.7 | C34: Gas/Diesel Oil | D34: ='Copia de Emisiones Energía'!D34*'Emisiones Energía V2'!$D$140 -> 0.0741 | E34: ='Copia de Emisiones Energía'!E34*'Emisiones Energía V2'!$D$140 -> 3e-06 | F34: ='Copia de Emisiones Energía'!F34*'Emisiones Energía V2'!$D$140 -> 6e-07 | G34: =(D34*$D$144)+(E34*$D$145) -> 0.074175
A35: 134 | C35: Fuel oil residual | D35: ='Copia de Emisiones Energía'!D35*'Emisiones Energía V2'!$D$140 -> 0.0774 | E35: ='Copia de Emisiones Energía'!E35*'Emisiones Energía V2'!$D$140 -> 3e-06 | F35: ='Copia de Emisiones Energía'!F35*'Emisiones Energía V2'!$D$140 -> 6e-07 | G35: =(D35*$D$144)+(E35*$D$145) -> 0.077475
A36: 2.85 | C36: Gas licuado de petróleo | D36: ='Copia de Emisiones Energía'!D36*'Emisiones Energía V2'!$D$140 -> 0.0631 | E36: ='Copia de Emisiones Energía'!E36*'Emisiones Energía V2'!$D$140 -> 1e-06 | F36: ='Copia de Emisiones Energía'!F36*'Emisiones Energía V2'!$D$140 -> 1e-07 | G36: =(D36*$D$144)+(E36*$D$145) -> 0.063125
