Workbook
Name ____W.O.R.K.B.O.O.K..C.O.N.T.E.N.T.S____: #REF!
Name ____W.O.R.K.B.O.O.K..C.O.N.T.E.N.T.S____: #REF!
Name CRF_4_KP_I_A.1.1_Doc: #REF!
Name CRF_4_KP_I_A.1.1_Doc: #REF!
Name CRF_4_KP_I_A.2.1_Doc: #REF!
Name CRF_4_KP_I_A.2.1_Doc: #REF!
Name CRF_4_KP_I_A.2_Doc: #REF!
Name CRF_4_KP_I_A.2_Doc: #REF!
Name CRF_4_KP_I_B.1.1_Doc: #REF!
Name CRF_4_KP_I_B.1.1_Doc: #REF!
Name CRF_4_KP_I_B.1.3_Doc: #REF!
Name CRF_4_KP_I_B.1.3_Doc: #REF!
Name CRF_Address: #REF!
Name CRF_Address: #REF!
Name CRF_Address1: #REF!
Name CRF_Address1: #REF!
Name CRF_Comment: #REF!
Name CRF_Comment: #REF!
Name CRF_ContactName: #REF!
Name CRF_ContactName: #REF!
Name CRF_CountryName: [1]Sheet1!$C$4
Name CRF_Email: #REF!
Name CRF_Email: #REF!
Name CRF_Fax: #REF!
Name CRF_Fax: #REF!
Name CRF_InventoryYear: [1]Sheet1!$C$6
Name CRF_Organisation: #REF!
Name CRF_Organisation: #REF!
Name CRF_Phone: #REF!
Name CRF_Phone: #REF!
Name CRF_Sheet1_Main: #REF!
Name CRF_Sheet1_Main: #REF!
Name CRF_Status: #REF!
Name CRF_Status: #REF!
Name CRF_Submission: [1]Sheet1!$C$8
Name CRF_Summary1_A_Main: #REF!
Name CRF_Summary1_A_Main: #REF!
Name CRF_Summary1_A_Range1: #REF!
Name CRF_Summary1_A_Range1: #REF!
Name CRF_Summary2_Main: #REF!
Name CRF_Summary2_Main: #REF!
Name CRF_Summary2_Range1: #REF!
Name CRF_Summary2_Range1: #REF!
Name CRF_Table10s1_Dyn10: [1]Table10!#REF!
Name CRF_Table10s1_Dyn10: [1]Table10!#REF!
Name CRF_Table10s1_Dyn11: [1]Table10!#REF!
Name CRF_Table10s1_Dyn12: [1]Table10!#REF!
Name CRF_Table10s1_Dyn13: [1]Table10!#REF!
Name CRF_Table10s1_Dyn14: [1]Table10!#REF!
Name CRF_Table10s1_Dyn15: [1]Table10!#REF!
Name CRF_Table10s1_Dyn16: [1]Table10!#REF!
Name CRF_Table10s1_Dyn17: [1]Table10!#REF!
Name CRF_Table10s1_Dyn18: [1]Table10!#REF!
Name CRF_Table10s1_Dyn19: [1]Table10!#REF!
Name CRF_Table10s1_Dyn20: [1]Table10!#REF!
Name CRF_Table10s1_Dyn21: [1]Table10!#REF!
Name CRF_Table10s1_Dyn22: [1]Table10!#REF!
Name CRF_Table2_II__Doc: #REF!
Name CRF_Table2_II__Doc: #REF!
Name CRF_Table2_II__Main: #REF!

Sheet INDICE
C3: INVENTARIO NACIONAL DE GASES DE EFECTO INVERNADERO 2018 -- LIBRO DE CÁLCULOS
C4: SECTOR AGRICULTURA
C6: INDICE DE CATEGORÍAS
C8: Datos de Actividad | D8: Tabla Compilatoria de los Datos de Actividad
B9: 3A1 | C9: Fermentación Entérica | D9: Tabla de Cálculos para Fermentación Entérica
B10: 3A2 | C10: Gestión de Estiércol CH4 | D10: Tabla de Cálculos para Gestión de Estércol CH4
B11: 3A2 | C11: Gestión de Estércol N2O Directo | D11: Tabla de Cálculos para Gestión de Estércol N2O - Directo
B12: 3C6 | C12: Gestión de Estércol N2O Indirecto | D12: Tabla de Cálculos para Gestión de Estércol N2O - Indirecto
B13: 3C7 | C13: Cultivo de Arroz CH4 | D13: Tabla de Cálculos para Cultivo de arroz CH4
B14: 3C4 | C14: Suelos Agricolas N2O Directo | D14: Tabla de Cálculos para Suelos Agricolas N2O - Directo
C15: Anexo 3C4 | D15: Tabla de Cálculos complementarios para Suelos Agricolas N2O - Directo
B16: 3C5 | C16: Suelos Agricolas N2O Indirecto | D16: Tabla de Cálculos para Suelos Agricolas N2O - Indirecto
B17: 3C2 | C17: Emisiones CO2 por Encalado | D17: Tabla de Cálculos para CO2 por Encalado
B18: 3C3 | C18: Emisiones CO2 por Aplicación de Urea | D18: Tabla de Cálculos para CO2 por Aplicación de Urea
B19: 3C1 | C19: Quema de Biomasa | D19: Tabla de Cálculos para N2O, CH4 por quema de biomasa
C20: RESULTADOS | D20: Tabla compilatoria de resultados finales CO2 Eq por categoria
B22: (*) | C22: Las tablas CTR comunes del inventario se integran al final
C23: Categorías Principales Desagregado | D23: Tabla de cálculo de las categorías Principales sectorial
C25: Especialista Sector Agricultura: Roberto Lucero

Sheet Presentación
B2: ÚLTIMA ACTUALIZACIÓN DE LA HERRAMIENTA
B5: Fecha de la última actualización: | C5: 43508
B7: Nombre: | C7: Roberto Daniel Lucero Romero
B9: Unidad del MAE: | C9: Técnico sector Agricultura
B11: Tel Institucional: | C11: 5933987600 etx. 1314
B13: e-mail: | C13: roberto.lucero@ambiente.gob.ec
A17: Proveedores de Información /Datos de Contacto
A21: No | B21: Organización | D21: Contacto | G21: Información Contacto
B22: Nombre de la organización | C22: Tipo | D22: Rol | E22: Cargo | F22: Nombres | G22: Telefono 1 | H22: Ext.1 | I22: mail
A23: 1 | B23: Instituto Nacional de Estadística y Censos (INEC) | C23: Nacional | D23: Punto focal NDC directivo Agricultura y USCUSS | E23: JEFE DE ESTADÍSTICAS AGROPECUARIAS | F23: ARMANDO DAVID SALAZAR MÉNDEZ | G23: 02-2544326 | H23: 1405 | I23: armando_salazar@inec.gob.ec
A24: 3 | B24: Instituto Nacional de Estadística y Censos (INEC) | C24: Nacional | D24: Punto focal NDC directivo Agricultura y USCUSS | E24: ANALISTA DE ESTADISTICAS AGROPECUARIAS Y AMBIENTALES 3 | F24: ARGUELLO RUIZ JENNY ELIZABETH | G24: 02-2544326 - 2238489 - 2555703 | I24: jenny_arguello@inec.gob.ec
A25: 4 | B25: Instituto Nacional de Estadística y Censos (INEC) | C25: Nacional | D25: Punto focal NDC directivo Agricultura y USCUSS | E25: DIRECTORA DE ESTADISTICAS AGROPECUARIAS Y AMBIENTALES | F25: MURGUEITIO TAMAYO MARIA JOSE | G25: 02-2544326 - 2238489 - 2555701 | H25: 1217 | I25: MariaJose_Murgueitio@inec.gob.ec
A26: 5 | B26: Instituto Nacional de Estadística y Censos (INEC) | C26: Nacional | D26: Punto focal NDC directivo Agricultura y USCUSS | E26: ANALISTA DE ESTADISTICAS AGROPECUARIAS Y AMBIENTALES 3 | F26: PILATAXI GUAIRACAJA CARLOS PATRICIO | G26: 02-2544326 - 2238489 - 2555701 | H26: 1405 | I26: carlos_pilataxi@inec.gob.ec
A27: 6 | B27: Agricultura y Ganadería (MAG) | C27: Nacional | D27: Punto focal NDC directivo Agricultura y USCUSS | E27: TÉCNICO, UNIDAD DE PROCESAMIENTO DE LA INFORMACIÓN | F27: RAÚL GAETHE | G27: 02-3960100 | H27: 3257 | I27: rgaethe@magap.gob.ec
A28: 7 | B28: Universidad de Cuenca | C28: Nacional | D28: Punto focal NDC directivo Agricultura y USCUSS | E28: DECANO DE LA FACULTAD DE CIENCIAS AGROPECAUARIAS | F28: DR. GUILLERMO SERPA GARCÍA | I28: guillermo.serpa@ucuenca.edu.ec c
A29: 8 | B29: Instituto Nacional de Investigaciones Agropecuarias INIAP | C29: Nacional | D29: Punto focal NDC directivo Agricultura y USCUSS | E29: INVESTIGADOR PRINCIPAL 4 | F29: DR. VÍCTOR HUGO BARRERA MOSQUERA | G29: 022567645 Ext: 215 | I29: victor.barrera@iniap.gob.ec
A30: 10 | B30: Instituto Nacional de Investigación Agropecuaria (INIAP) | C30: Nacional | D30: Punto focal NDC directivo Agricultura y USCUSS | E30: DIRECTOR DE INVESTIGACIONES , ENCARGADO | F30: DR. JOSÉ LUIS ZAMBRANO | G30: (593 2) 2567645 (MAG) (593 2) 3076004 | 3076002 (Estación Santa Catalina) | I30: jose.zambrano@iniap.gob.ec
A31: 11 | B31: Instituto Nacional de Investigación Agropecuaria (INIAP) | C31: Nacional | D31: Punto focal NDC técnico Agricultura y USCUSS | E31: DIRECTOR DE INVESTIGADORES, ENCARGADO | F31: DR. VÍCTOR HUGO BARRERA | G31: (02)2567645 (Ext) 201 Quito | I31: Victor.barrera@iniap.gob.ec
A32: 12 | B32: Instituto Nacional de Investigación Agropecuaria (INIAP) | C32: Nacional | D32: Punto focal NDC técnico (alterno) Agricultura y USCUSS | E32: INVESTIGAR AGROPECUARIO | F32: ING. LUIS ESCUDERO | G32: (593 2) 2567645 (MAG) (593 2) 3076004 | 3076002 (Estación Santa Catalina) | I32: Luis.escudero@iniap.gob.ec
A33: 13 | B33: Agricultura y Ganadería (MAG) | C33: Nacional | D33: Agricultura y Uso de suelo Cambio de Uso del Suelo y Silvicultura (USCUSS) | E33: GERENTE DEL PROYECTO DE INVERSIÓN DE INCENTIVOS FORESTALES | F33: JAIME MEDINA | G33: 959250781 | I33: jmedina@mag.gob.ec
A34: 14 | B34: Agricultura y Ganadería (MAG) | C34: Nacional | D34: Agricultura y Uso de suelo Cambio de Uso del Suelo y Silvicultura (USCUSS) | E34: TÉCNICO DEL PROYECTO DE INVERSIÓN DE INCENTIVOS FORESTALES | F34: JULIO VEGA | G34: 593-2 396-0100 | I34: jvegal@mag.gob.ec
A35: 15 | B35: Agricultura y Ganadería (MAG) | C35: Nacional | D35: Agricultura y Uso de suelo Cambio de Uso del Suelo y Silvicultura (USCUSS) | E35: DIRECTORA DE PRE INVERSIÓN Y COOPERACIÓN NACIONAL E INTERNACIONAL, ENCARGADA | F35: DENISSE SÁNCHEZ | G35: 593-2 396-0100 | I35: dsanchezt@mag.gob.ec
A36: 16 | B36: Agricultura y Ganadería (MAG) | C36: Nacional | D36: Agricultura y Uso de suelo Cambio de Uso del Suelo y Silvicultura (USCUSS) | E36: ESPECIALISTA EN DESARROLLO FORESTAL | F36: FELIPE ESPINOZA | G36: Telf.: (593 4) 2 599330 ext. 5663 (0999610360) | I36: fespinozaj@mag.gob.ec

Sheet Datos de Actividad
B1: Tabla para recopilación de información sector agricultura
C2: Datos de actividad usados para la construcci[on de inventarios nacionales de gases de efecto invernadero serie 1994-2021 5CN/1BTR, directrices ipcc 2006 refinamiento 2019 | H2: INDICE
G7: GANADO DOMÉSTICO | L7: GANADO DOMÉSTICO | Q7: GANADO DOMÉSTICO | V7: GANADO DOMÉSTICO
C11: Fuentes y Categorías | E11: Número de Animales (Total nacional por año de inventario)
C12: Fermentación Entérica / Gestión del estiércol | E12: 1994 | G12: 2000 | I12: 2006 | K12: 2010 | M12: 2012 | O12: 2014 | Q12: 2016 | S12: 2018 | U12: 2020 | W12: 2021 | Y12: 2022
E13: Fuente | F13: Cabezas | G13: Fuente | H13: Cabezas | I13: Fuente | J13: Cabezas | K13: Fuente | L13: Cabezas | M13: Fuente | N13: Cabezas | O13: Fuente | P13: Cabezas | Q13: Fuente | R13: Cabezas | S13: Fuente | T13: Cabezas | U13: Fuente | V13: Cabezas | W13: Fuente | X13: Cabezas | Y13: Fuente | Z13: Cabezas
B14: GANADO BOVINO | C14: Ganado Lechero | D14: Sierra | E14: ESPAC 1995, Desagregación por región estimada en base a las proporciones de años posteriores | F14: 574414.58 | G14: CNA 2000, tabla 6_00, Desagregación por región estimada en función de datos ESPAC años posteriores | H14: 626104.05 | I14: ESPAC 2006, tabla 51_6 | J14: 594479 | K14: ESPAC 2010, tabla 51_10 | L14: 702076 | M14: ESPAC 2012, tabla 51 | N14: 674076.85 | O14: ESPAC 2014 (version II corregida), tabla 54 | P14: 630175.66 | Q14: ESPAC 2016, tabla 63 | R14: 570270.14 | S14: ESPAC 2018 , tabla 66 | T14: 522643.97 | U14: ESPAC 2020 , tabla 67 | V14: 616168.02 | W14: ESPAC 2021 , tabla 67 | X14: 564165.51 | Y14: ESPAC 2022 , tabla 67 | Z14: 545149.32
D15: Costa | E15: ESPAC 1995, Desagregación por región estimada en base a las proporciones de años posteriores | F15: 263584.92 | G15: CNA 2000, tabla 6_00, Desagregación por región estimada en función de datos ESPAC años posteriores | H15: 241691.92 | I15: ESPAC 2006, tabla 51_7 | J15: 272792 | K15: ESPAC 2010, tabla 51_11 | L15: 271019 | M15: ESPAC 2012, tabla 52 | N15: 280034.87 | O15: ESPAC 2014 (version II corregida), tabla 54 | P15: 280963.69 | Q15: ESPAC 2016, tabla 63 | R15: 271362.48 | S15: ESPAC 2018 , tabla 66 | T15: 262262.61 | U15: ESPAC 2020 , tabla 67 | V15: 291374.79 | W15: ESPAC 2021 , tabla 67 | X15: 236336.44 | Y15: ESPAC 2022 , tabla 67 | Z15: 226251.1
D16: Amazonia | E16: ESPAC 1995, Desagregación por región estimada en base a las proporciones de años posteriores | F16: 119692.13 | G16: CNA 2000, tabla 6_00, Desagregación por región estimada en función de datos ESPAC años posteriores | H16: 103239.8 | I16: ESPAC 2006, tabla 51_8 | J16: 123873 | K16: ESPAC 2010, tabla 51_12 | L16: 115767 | M16: ESPAC 2012, tabla 53 | N16: 99199.328 | O16: ESPAC 2014 (version II corregida), tabla 54 | P16: 68708.593 | Q16: ESPAC 2016, tabla 63 | R16: 54537.495 | S16: ESPAC 2018 , tabla 66 | T16: 47621.019 | U16: ESPAC 2020 , tabla 67 | V16: 54977.432 | W16: ESPAC 2021 , tabla 67 | X16: 46212.781 | Y16: ESPAC 2022 , tabla 67 | Z16: 43664.111
C17: No Lechero Toros | D17: Sierra | E17: ESPAC 1995, Desagregación por región estimada en base a las proporciones de años posteriores | F17: 334787.01 | G17: CNA Provincial 2000, tabla 35, Desagregación por región estimada en función de datos ESPAC años posteriores | H17: 254082.67 | I17: ESPAC 2006, tabla 38_6 | J17: 215034 | K17: ESPAC 2010, tabla 38_10 | L17: 199819 | M17: ESPAC 2012, tabla 38 | N17: 176888.93 | O17: ESPAC 2014 (version II corregida), tabla 41 | P17: 179616.91 | Q17: ESPAC 2016, tabla 50 | R17: 149944.77 | S17: ESPAC 2018, tabla 50 | T17: 153765.65 | U17: ESPAC 2020, tabla 50 | V17: 179622.35 | W17: ESPAC 2021, tabla 50 | X17: 159223 | Y17: ESPAC 2022, tabla 50 | Z17: 157756.54
D18: Costa | E18: ESPAC 1995, Desagregación por región estimada en base a las proporciones de años posteriores | F18: 111373.03 | G18: CNA Provincial 2000, tabla 35, Desagregación por región estimada en función de datos ESPAC años posteriores | H18: 109983.94 | I18: ESPAC 2006, tabla 38_7 | J18: 71535 | K18: ESPAC 2010, tabla 38_11 | L18: 86495 | M18: ESPAC 2012, tabla 39 | N18: 73963.106 | O18: ESPAC 2014 (version II corregida), tabla 41 | P18: 85070.54 | Q18: ESPAC 2016, tabla 50 | R18: 68066.762 | S18: ESPAC 2018, tabla 50 | T18: 73566.158 | U18: ESPAC 2020, tabla 50 | V18: 106116.23 | W18: ESPAC 2021, tabla 50 | X18: 74162.62 | Y18: ESPAC 2022, tabla 50 | Z18: 71653.442
D19: Amazonia | E19: ESPAC 1995, Desagregación por región estimada en base a las proporciones de años posteriores | F19: 98924.039 | G19: CNA Provincial 2000, tabla 35, Desagregación por región estimada en función de datos ESPAC años posteriores | H19: 67666.285 | I19: ESPAC 2006, tabla 38_8 | J19: 63539 | K19: ESPAC 2010, tabla 38_12 | L19: 53215 | M19: ESPAC 2012, tabla 40 | N19: 49692.794 | O19: ESPAC 2014 (version II corregida), tabla 41 | P19: 38932.57 | Q19: ESPAC 2016, tabla 50 | R19: 25916.702 | S19: ESPAC 2018, tabla 50 | T19: 28493.155 | U19: ESPAC 2020, tabla 50 | V19: 39109.133 | W19: ESPAC 2021, tabla 50 | X19: 29865.823 | Y19: ESPAC 2022, tabla 50 | Z19: 27896.897
C20: No Lechero Vacas | D20: Sierra | E20: ESPAC 1995, Desagregación por región estimada en base a las proporciones de años posteriores | F20: 333821.6 | G20: CNA Provincial 2000, tabla 35 | H20: 311611.06 | I20: ESPAC 2006, tabla 38_06 | J20: 376913 | K20: ESPAC 2010, tabla 38_10 | L20: 326517 | M20: ESPAC 2012, tabla 38 | N20: 374957.18 | O20: ESPAC 2014 (version II corregida), tabla 41-54 | P20: 323096.43 | Q20: ESPAC 2016, tabla 50 | R20: 253038.23 | S20: ESPAC 2018, tabla 50 | T20: 250720.67 | U20: ESPAC 2020, tabla 50 | V20: 258773.78 | W20: ESPAC 2021, tabla 50 | X20: 277351.12 | Y20: ESPAC 2022, tabla 50 | Z20: 273816.95
D21: Costa | E21: ESPAC 1995, Desagregación por región estimada en base a las proporciones de años posteriores | F21: 410142.68 | G21: CNA Provincial 2000, tabla 35, Desagregación por región estimada en función de datos ESPAC años posteriores | H21: 468269.3 | I21: ESPAC 2006, tabla 38_07 | J21: 463086 | K21: ESPAC 2010, tabla 38_11 | L21: 490669 | M21: ESPAC 2012, tabla 39 | N21: 417290.71 | O21: ESPAC 2014 (version II corregida), tabla 41-54 | P21: 392883.31 | Q21: ESPAC 2016, tabla 50 | R21: 374969.32 | S21: ESPAC 2018, tabla 50 | T21: 401964.14 | U21: ESPAC 2020, tabla 50 | V21: 426123.25 | W21: ESPAC 2021, tabla 50 | X21: 382587.31 | Y21: ESPAC 2022, tabla 50 | Z21: 353200.41
D22: Amazonia | E22: ESPAC 1995, Desagregación por región estimada en base a las proporciones de años posteriores | F22: 100534.49 | G22: CNA Provincial 2000, tabla 36 | H22: 115162.21 | I22: ESPAC 2006, tabla 38_08 | J22: 113512 | K22: ESPAC 2010, tabla 38_12 | L22: 120671 | M22: ESPAC 2012, tabla 40 | N22: 150135.02 | O22: ESPAC 2014 (version II corregida), tabla 41-54 | P22: 70590.986 | Q22: ESPAC 2016, tabla 50 | R22: 70415.123 | S22: ESPAC 2018, tabla 50 | T22: 74474.301 | U22: ESPAC 2020, tabla 50 | V22: 94501.381 | W22: ESPAC 2021, tabla 50 | X22: 79622.394 | Y22: ESPAC 2022, tabla 50 | Z22: 74308.968
C23: No Lechero En crecimiento | D23: Sierra | E23: ESPAC 1995, Desagregación por región estimada en base a las proporciones de años posteriores | F23: 1177840.2 | G23: CNA Provincial 2000, tabla 35, Desagregación por región estimada en función de datos ESPAC años posteriores | H23: 1218489.8 | I23: ESPAC 2006, tabla 38_06 | J23: 1304372 | K23: ESPAC 2010, tabla 38_10 | L23: 1408615 | M23: ESPAC 2012, tabla 38 | N23: 1425251.8 | O23: ESPAC 2014 (version II corregida), tabla 41 | P23: 1212212.1 | Q23: ESPAC 2016, tabla 50 | R23: 1068890.5 | S23: ESPAC 2018, tabla 50 | T23: 1036600.5 | U23: ESPAC 2020, tabla 50 | V23: 1074848.8 | W23: ESPAC 2021, tabla 50 | X23: 1110233.4 | Y23: ESPAC 2022, tabla 50 | Z23: 1068249.5
D24: Costa | E24: ESPAC 1995, Desagregación por región estimada en base a las proporciones de años posteriores | F24: 975655.33 | G24: CNA Provincial 2000, tabla 37 | H24: 957121.05 | I24: ESPAC 2006, tabla 38_07 | J24: 1080467 | K24: ESPAC 2010, tabla 38_11 | L24: 1106464 | M24: ESPAC 2012, tabla 39 | N24: 1129032.6 | O24: ESPAC 2014 (version II corregida), tabla 41 | P24: 1019540.9 | Q24: ESPAC 2016, tabla 50 | R24: 1019540.9 | S24: ESPAC 2018, tabla 50 | T24: 984149.28 | U24: ESPAC 2020, tabla 50 | V24: 964542.04 | W24: ESPAC 2021, tabla 50 | X24: 898303.47 | Y24: ESPAC 2022, tabla 50 | Z24: 837169.03
D25: Amazonia | E25: ESPAC 1995, Desagregación por región estimada en base a las proporciones de años posteriores | F25: 320608.06 | G25: CNA Provincial 2000, tabla 35, Desagregación por región estimada en función de datos ESPAC años posteriores | H25: 321970.77 | I25: ESPAC 2006, tabla 38_08 | J25: 355050 | K25: ESPAC 2010, tabla 38_12 | L25: 372209 | M25: ESPAC 2012, tabla 40 | N25: 385026.56 | O25: ESPAC 2014 (version II corregida), tabla 41 | P25: 240620.69 | Q25: ESPAC 2016, tabla 50 | R25: 200358.89 | S25: ESPAC 2018, tabla 50 | T25: 220534.27 | U25: ESPAC 2020, tabla 50 | V25: 229766.59 | W25: ESPAC 2021, tabla 50 | X25: 208865.91 | Y25: ESPAC 2022, tabla 50 | Z25: 181377.18
B26: OTROS TIPOS DE GANADO | C26: Búfalo | E26: Retroproyección del dato considerando tasas de crecimiento del registro de agrocalidad - fiebre aftosa periodo 2016-2021 y la tasa de crecimiento el conjunto de bovinos mismo periodo | F26: 989.43 | G26: Retroproyección del dato considerando tasas de crecimiento del registro de agrocalidad - fiebre aftosa periodo 2016-2021 y la tasa de crecimiento el conjunto de bovinos mismo periodo | H26: 1406 | I26: Retroproyección del dato considerando tasas de crecimiento del registro de agrocalidad - fiebre aftosa periodo 2016-2021 y la tasa de crecimiento el conjunto de bovinos mismo periodo | J26: 2051 | K26: Retroproyección del dato considerando tasas de crecimiento del registro de agrocalidad - fiebre aftosa periodo 2016-2021 y la tasa de crecimiento el conjunto de bovinos mismo periodo | L26: 2606 | M26: Retroproyección del dato considerando tasas de crecimiento del registro de agrocalidad - fiebre aftosa periodo 2016-2021 y la tasa de crecimiento el conjunto de bovinos mismo periodo | N26: 2891 | O26: Retroproyección del dato considerando tasas de crecimiento del registro de agrocalidad - fiebre aftosa periodo 2016-2021 y la tasa de crecimiento el conjunto de bovinos mismo periodo | P26: 3049 | Q26: Datos de registro de vacunación por fiebre aftosa de Agrocalidad | R26: 3254 | S26: Datos de registro de vacunación por fiebre aftosa de Agrocalidad | T26: 3839 | U26: Datos de registro de vacunación por fiebre aftosa de Agrocalidad | V26: 4496 | W26: Datos de registro de vacunación por fiebre aftosa de Agrocalidad | X26: 5237 | Y26: Datos de registro de vacunación por fiebre aftosa de Agrocalidad | Z26: 5807
C27: Ovejas | E27: ESPAC 1995 | F27: 1692000 | G27: CNA 2000, tabla 6_00 | H27: 1127407 | I27: ESPAC 2006, tabla 10_06 | J27: 973223 | K27: ESPAC 2010, tabla 10_10 | L27: 792497 | M27: ESPAC 2012, tabla 10 | N27: 767729.5 | O27: ESPAC 2014 (version II corregida), tabla 48 | P27: 696732.28 | Q27: ESPAC 2016 , tabla 57 | R27: 589698.24 | S27: ESPAC 2018 , tabla 59 | T27: 498952.01 | U27: ESPAC 2020 , tabla 60 | V27: 496535.04 | W27: ESPAC 2021 , tabla 60 | X27: 528827.56 | Y27: ESPAC 2022 , tabla 60 | Z27: 551960.11
C28: Cabras | E28: ESPAC 1995 | F28: 317000 | G28: CNA 2000, tabla 6_00 | H28: 178105 | I28: ESPAC 2006, tabla 10_06 | J28: 156422 | K28: ESPAC 2010, tabla 10_10 | L28: 134824 | M28: ESPAC 2012, tabla 10 | N28: 108714.06 | O28: ESPAC 2014 (version II corregida), tabla 49 | P28: 20792.771 | Q28: ESPAC 2016 , tabla 56 | R28: 35761.086 | S28: ESPAC 2018 , tabla 60 | T28: 21745.307 | U28: ESPAC 2020 , tabla 61 | V28: 14092.397 | W28: ESPAC 2021 , tabla 61 | X28: 57849.051 | Y28: ESPAC 2022 , tabla 61 | Z28: 23789.38
C29: Camélidos sudamericanos | E29: Estimación según datos MAG Chimborazo | F29: 23177 | G29: Estimación según datos MAG Chimborazo | H29: 23177 | I29: FAO 2005, Situación de los camélidos sudamericanos en Ecuador | J29: 20043 | K29: MAGAP_Subsecretaría de Ganadería_2013 | L29: 16851.506 | M29: MAGAP_Subsecretaría de Ganadería_2013 | N29: 16851.506 | O29: Ministerio de Agricultura, Regional Chimborazo | P29: 16851.506 | Q29: Ministerio de Agricultura, Agrocalidad, Regional Chimborazo | R29: 17757.383 | S29: Ministerio de Agricultura, Agrocalidad, Regional Chimborazo | T29: 20949.783 | U29: Ministerio de Agricultura, Agrocalidad, Regional Chimborazo | V29: 20782.017 | W29: Ministerio de Agricultura, Agrocalidad, Regional Chimborazo | X29: 20698.806 | Y29: Ministerio de Agricultura, Agrocalidad, Regional Chimborazo | Z29: 20615.928
C30: Caballos | E30: ESPAC 1995 | F30: 524000 | G30: CNA 2000, tabla 6_00 | H30: 371480 | I30: ESPAC 2006, tabla 10_06 | J30: 403144 | K30: ESPAC 2010, tabla 10_10 | L30: 367248 | M30: ESPAC 2012, tabla 10 | N30: 351931.4 | O30: ESPAC 2014 (version II corregida), tabla 49 | P30: 327645.95 | Q30: ESPAC 2016 , tabla 58 | R30: 297860.72 | S30: ESPAC 2018 , tabla 60 | T30: 260479.02 | U30: ESPAC 2020 , tabla 61 | V30: 172574.11 | W30: ESPAC 2021 , tabla 61 | X30: 192187.21 | Y30: ESPAC 2022 , tabla 61 | Z30: 155407.36
C31: Mulas y Asnos | E31: ESPAC 1995 | F31: 405000 | G31: CNA 2000, tabla 6_00 | H31: 301995 | I31: ESPAC 2006, tabla 10_06 | J31: 303509 | K31: ESPAC 2010, tabla 10_10 | L31: 264405 | M31: ESPAC 2012, tabla 10 | N31: 246857.82 | O31: ESPAC 2014 (version II corregida), tabla 49 | P31: 222684.05 | Q31: ESPAC 2016 , tabla 59 | R31: 175261.66 | S31: ESPAC 2018 , tabla 60 | T31: 147168.66 | U31: ESPAC 2020 , tabla 61 | V31: 98938.513 | W31: ESPAC 2021 , tabla 61 | X31: 116082.94 | Y31: ESPAC 2022 , tabla 61 | Z31: 95081.034
C32: Cerdos | E32: ESPAC 1995 | F32: 2670000 | G32: CNA 2000, tabla 6_00 | H32: 1515276 | I32: ESPAC 2006, tabla 10_06 | J32: 1912048 | K32: ESPAC 2010, tabla 10_10 | L32: 1489761 | M32: ESPAC 2012, tabla 10 | N32: 1387203.2 | O32: ESPAC 2014 (version II corregida), tabla 47 | P32: 1672627.1 | Q32: ESPAC 2016 , tabla 60 | R32: 1428161.3 | S32: ESPAC 2018 , tabla 57 | T32: 1682662 | U32: ESPAC 2020 , tabla 57 | V32: 1059841.8 | W32: ESPAC 2021 , tabla 57 | X32: 1053923.1 | Y32: ESPAC 2022 , tabla 57 | Z32: 943249.42
C33: Aves de engorde | E33: Estimación según datos de CONAVE | F33: 17481848 | G33: Estimación según datos de CONAVE | H33: 19990113 | I33: Estimación según datos de CONAVE | J33: 22858259 | K33: Estimación según datos de CONAVE | L33: 24944905 | M33: Estimación según datos de CONAVE | N33: 26033770 | O33: Estimación según datos de CONAVE | P33: 27170165 | Q33: Datos de CONAVE | R33: 28356164 | S33: Datos de CONAVE | T33: 30205479 | U33: Datos de CONAVE | V33: 32424658 | W33: Datos de CONAVE | X33: 31438356 | Y33: Datos de CONAVE | Z33: 32424658
C34: Ponedoras | E34: Estimación según datos de CONAVE | F34: 9486896.5 | G34: Estimación según datos de CONAVE | H34: 10284930 | I34: Estimación según datos de CONAVE | J34: 11150093 | K34: Estimación según datos de CONAVE | L34: 11758331 | M34: Estimación según datos de CONAVE | N34: 12070525 | O34: Estimación según datos de CONAVE | P34: 12391008 | Q34: Datos de CONAVE | R34: 12720000 | S34: Datos de CONAVE | T34: 13510000 | U34: Datos de CONAVE | V34: 12690000 | W34: Datos de CONAVE | X34: 12840000 | Y34: Datos de CONAVE | Z34: 13790000
C35: Patos | E35: ESPAC 1995 | F35: 308162.78 | G35: CNA 2000, tabla 7_00 | H35: 400030 | I35: ESPAC 2006, tabla 47 y 48 | J35: 513644 | K35: ESPAC 2010, tabla 47 y 48 | L35: 553006 | M35: ESPAC 2012, tabla 47 y 48 | N35: 576346.26 | O35: ESPAC 2014 (version II corregida), tabla 50-51 | P35: 105674.95 | Q35: ESPAC 2016 , tabla 63 | R35: 524518.27 | S35: ESPAC 2018 , tabla 61,62 | T35: 70291.656 | U35: ESPAC 2020 , tabla 62,63 | V35: 458275.89 | W35: ESPAC 2021 , tabla 62,63 | X35: 554094.02 | Y35: ESPAC 2022 , tabla 62,63 | Z35: 376745.77
C36: Pavos | E36: ESPAC 1995 | F36: 266839.26 | G36: CNA 2000, tabla 7_00 | H36: 117040 | I36: ESPAC 2006, tabla 48 | J36: 196165 | K36: ESPAC 2010, tabla 48 | L36: 287080 | M36: ESPAC 2012, tabla 48 | N36: 78857.795 | O36: ESPAC 2014 (version II corregida), tabla 50-51 | P36: 446358.94 | Q36: ESPAC 2016 , tabla 64 | R36: 280845.58 | S36: ESPAC 2018 , tabla 61,62 | T36: 198716.81 | U36: ESPAC 2020 , tabla 62,63 | V36: 179336.36 | W36: ESPAC 2021 , tabla 62,63 | X36: 311843.7 | Y36: ESPAC 2022 , tabla 62,63 | Z36: 455071.32
C37: Otros (Especificar)
C38: TOTALES | F38: =SUM(F14:F37) -> 37997291 | H38: =SUM(H14:H37) -> 39106351 | J38: =SUM(J14:J37) -> 43523253 | L38: =SUM(L14:L37) -> 45865051 | N38: =SUM(N14:N37) -> 46877228 | P38: =SUM(P14:P37) -> 47616002 | R38: =SUM(R14:R37) -> 48556594 | T38: =SUM(T14:T37) -> 50677079 | V38: =SUM(V14:V37) -> 51955453 | X38: =SUM(X14:X37) -> 51186029 | Z38: =SUM(Z14:Z37) -> 52702878
B40: CULTIVO DEL ARROZ | G40: CULTIVO DEL ARROZ | L40: CULTIVO DEL ARROZ | Q40: CULTIVO DEL ARROZ | V40: CULTIVO DEL ARROZ | AA40: CULTIVO DEL ARROZ | AF40: CULTIVO DEL ARROZ | AK40: CULTIVO DEL ARROZ | AP40: CULTIVO DEL ARROZ
C43: Fuentes y Categorías | E43: Superficie sembrada Cultivo Arroz
C44: Cultivo del arroz | E44: 1994 | H44: 2000 | K44: 2006 | N44: 2010 | Q44: 2012 | T44: 2014 | W44: 2016 | Z44: 2018 | AC44: 2020 | AF44: 2021 | AI44: 2022
E45: Fuente | F45: Total /(has) | G45: % | H45: Fuente | I45: Total /(has) | J45: Total (miles has) | K45: Fuente | L45: Total /(has) | M45: Total (miles has) | N45: Fuente | O45: Total /(has) | P45: Total (miles has) | Q45: Fuente | R45: Total /(has) | S45: Total (miles has) | T45: Fuente | U45: Total /(has) | V45: % | W45: Fuente | X45: Total /(has) | Y45: % | Z45: Fuente | AA45: Total /(has) | AB45: % | AC45: Fuente | AD45: Total /(has) | AE45: % | AF45: Fuente | AG45: Total /(has) | AH45: % | AI45: Fuente | AJ45: Total /(has) | AK45: %
C46: Total de superficie sembrada | E46: ESPAC 1995 | F46: 400350 | H46: CNA 2000, tabla 20_00 | I46: 349726 | K46: ESPAC 2006, tabla 6_06 | L46: 357558 | N46: ESPAC 2010, tabla 6_10 | O46: 393137 | Q46: ESPAC 2012, tabla 6 | R46: 371170 | T46: ESPAC 2014, tabla 23 | U46: 354136 | W46: ESPAC 2016, tabla 28 | X46: 385039.49 | Z46: ESPAC 2018 | AA46: 301853 | AC46: ESPAC 2020 | AD46: 315023.04 | AF46: ESPAC 2021 | AG46: 342967.08 | AI46: ESPAC 2022 | AJ46: 343061.41
B47: a | C47: Upland /tierras altas | F47: =F$46*G47 -> 0 | G47: 0 | I47: =I$46*J47 -> 0 | J47: 0 | L47: =L$46*M47 -> 0 | M47: 0 | O47: =O$46*P47 -> 0 | P47: 0 | R47: =R$46*S47 -> 0 | S47: 0 | U47: =U$46*V47 -> 0 | V47: 0 | X47: =X$46*Y47 -> 0 | Y47: 0 | AA47: =AA$46*AB47 -> 0 | AB47: 0 | AD47: =AD$46*AE47 -> 0 | AE47: 0 | AG47: =AG$46*AH47 -> 0 | AH47: 0 | AJ47: =AJ$46*AK47 -> 0 | AK47: 0
B48: b | C48: Irrigadas | D48: Inundadas permanentemente | F48: =F$46*G48 -> 0 | G48: 0 | I48: =I$46*J48 -> 0 | J48: 0 | L48: =L$46*M48 -> 0 | M48: 0 | O48: =O$46*P48 -> 0 | P48: 0 | R48: =R$46*S48 -> 0 | S48: 0 | U48: =U$46*V48 -> 0 | V48: 0 | X48: =X$46*Y48 -> 0 | Y48: 0 | AA48: =AA$46*AB48 -> 0 | AB48: 0 | AD48: =AD$46*AE48 -> 0 | AE48: 0 | AG48: =AG$46*AH48 -> 0 | AH48: 0 | AJ48: =AJ$46*AK48 -> 0 | AK48: 0
B49: c | D49: Inundados intermitentemente – aireación simple | F49: =F$46*G49 -> 0 | G49: 0 | I49: =I$46*J49 -> 0 | J49: 0 | L49: =L$46*M49 -> 0 | M49: 0 | O49: =O$46*P49 -> 0 | P49: 0 | R49: =R$46*S49 -> 0 | S49: 0 | U49: =U$46*V49 -> 0 | V49: 0 | X49: =X$46*Y49 -> 0 | Y49: 0 | AA49: =AA$46*AB49 -> 0 | AB49: 0 | AD49: =AD$46*AE49 -> 0 | AE49: 0 | AG49: =AG$46*AH49 -> 0 | AH49: 0 | AJ49: =AJ$46*AK49 -> 0 | AK49: 0
B50: d | D50: Inundados intermitentemente – aireación multiple | F50: =F$46*G50 -> 88077 | G50: 0.22 | I50: =I$46*J50 -> 76939.72 | J50: 0.22 | L50: =L$46*M50 -> 78662.76 | M50: 0.22 | O50: =O$46*P50 -> 86490.14 | P50: 0.22 | R50: =R$46*S50 -> 81657.4 | S50: 0.22 | U50: =U$46*V50 -> 77909.92 | V50: 0.22 | X50: =X$46*Y50 -> 77007.899 | Y50: 0.2 | AA50: =AA$46*AB50 -> 84518.84 | AB50: 0.28 | AD50: =AD$46*AE50 -> 69305.068 | AE50: 0.22 | AG50: =AG$46*AH50 -> 65163.746 | AH50: 0.19 | AJ50: =AJ$46*AK50 -> 68612.282 | AK50: 0.2
...

Sheet 3A1 Fermentación E.
B2: EMISIONES POR FERMENTACIÓN ENTÉRICA Y GESTIÓN DE ESTIÉRCOL | G2: INDICE
B4: Sector | C4: Agricultura
B5: Categoria | C5: Emisiones de Metano por Fermentación Entérica y Gestión de Estiércol
B6: Código de Categoría | C6: 3A1 y 3A2
B7: Hoja | C7: 1 de 1
B8: Ecuación | D8: Ecuación 10.19 | F8: Ec. 10.19 y 10.20
B9: Categoria de Ganado | D9: Número de Animales | E9: Factor de Emisión para Fermentación Entérica | F9: CH4 Emisiones para Fermentación Entérica
D10: (cabezas) | E10: (kg cabeza-1 año-1) | F10: (Gg CH4 año-1)
E11: Tablas 10.10 y 10.11 | F11: CH4 Enterica = N(T) * EF(T) * 10-6
B12: T | D12: N (T) | E12: EF(T) | F12: CH4 Enteric
B13: Ganado Lechero | C13: Sierra | D13: ='Datos de Actividad'!T14 -> 522643.97 | E13: 86.403932 | F13: =D13*E13*(10^-6) -> 45.158494
C14: Costa | D14: ='Datos de Actividad'!T15 -> 262262.61 | E14: 107.26406 | F14: =D14*E14*(10^-6) -> 28.131352
C15: Amazonia | D15: ='Datos de Actividad'!T16 -> 47621.019 | E15: 104.30794 | F15: =D15*E15*(10^-6) -> 4.9672503
B16: No LecheroToros | C16: Sierra | D16: ='Datos de Actividad'!T17 -> 153765.65 | E16: 72.771229 | F16: =D16*E16*(10^-6) -> 11.189715
C17: Costa | D17: ='Datos de Actividad'!T18 -> 73566.158 | E17: 101.72988 | F17: =D17*E17*(10^-6) -> 7.4838761
C18: Amazonia | D18: ='Datos de Actividad'!T19 -> 28493.155 | E18: 83.486331 | F18: =D18*E18*(10^-6) -> 2.378789
B19: No Lechero Vacas | C19: Sierra | D19: ='Datos de Actividad'!T20 -> 250720.67 | E19: 68.638417 | F19: =D19*E19*(10^-6) -> 17.20907
C20: Costa | D20: ='Datos de Actividad'!T21 -> 401964.14 | E20: 95.165192 | F20: =D20*E20*(10^-6) -> 38.252995
C21: Amazonia | D21: ='Datos de Actividad'!T22 -> 74474.301 | E21: 91.432747 | F21: =D21*E21*(10^-6) -> 6.8093899
B22: No Lechero En crecimiento | C22: Sierra | D22: ='Datos de Actividad'!T23 -> 1036600.5 | E22: 40.729428 | F22: =D22*E22*(10^-6) -> 42.220144
C23: Costa | D23: ='Datos de Actividad'!T24 -> 984149.28 | E23: 54.996918 | F23: =D23*E23*(10^-6) -> 54.125177
C24: Amazonia | D24: ='Datos de Actividad'!T25 -> 220534.27 | E24: 59.13981 | F24: =D24*E24*(10^-6) -> 13.042355
B25: Búfalos | D25: ='Datos de Actividad'!T26 -> 3839 | E25: 68 | F25: =D25*E25*(10^-6) -> 0.261052
B26: Ovejas | D26: ='Datos de Actividad'!T27 -> 498952.01 | E26: 5 | F26: =D26*E26*(10^-6) -> 2.4947601
B27: Cabras | D27: ='Datos de Actividad'!T28 -> 21745.307 | E27: 5 | F27: =D27*E27*(10^-6) -> 0.10872653
B28: Camélidos sudamericanos | D28: ='Datos de Actividad'!T29 -> 20949.783 | E28: 8 | F28: =D28*E28*(10^-6) -> 0.16759827
B29: Caballos | D29: ='Datos de Actividad'!T30 -> 260479.02 | E29: 18 | F29: =D29*E29*(10^-6) -> 4.6886223
B30: Mulas & Asnos | D30: ='Datos de Actividad'!T31 -> 147168.66 | E30: 10 | F30: =D30*E30*(10^-6) -> 1.4716866
B31: Cerdos | D31: ='Datos de Actividad'!T32 -> 1682662 | E31: 1 | F31: =D31*E31*(10^-6) -> 1.682662
B32: Aves de engorde | D32: ='Datos de Actividad'!T33 -> 30205479 | E32: NA | F32: NA
B33: Ponedoras | D33: ='Datos de Actividad'!T34 -> 13510000 | E33: NA | F33: NA
B34: Patos | D34: ='Datos de Actividad'!T35 -> 70291.656 | E34: NA | F34: NA
B35: Pavos | D35: ='Datos de Actividad'!T36 -> 198716.81 | E35: NA | F35: NA
B36: Total | F36: =SUM(F13:F35) -> 281.84372
B39: NOTA EXPLICATIVA CATEGORIA FERMENTACIÓN ENTÉRICA
B40: Dato | C40: Tipo | D40: Fuente | E40: Observaciones
B41: Factor de emisión propio para bovinos | C41: FE | D41: Elaboración país | E41: El factor propio es calculado en base a los datos del proyecto GCI del periodo 2014-2018, incluye todas las variables requeridas para el cálculo del mismo de forma regional y por categoría, el Ym es usado por defecto del IPCC | G41: .
B42: Ganado Lechero | C42: Datos de Actividad | D42: ESPAC 2018 (datos ajustados y suavizados, se usan las tasas de variación interanual del registro de agrocalidad de vacunación por fiebre aftosa), tabla 66, | E42: Dato de actividad desagregado por región, dato de existencias población adulta de mas de dos años | G42: .
B43: Ganado Lechero | C43: FE para Fermentación Entérica | D43: FE propio para Ecuador calculado en base a los parametros levantados en campo por el Proyecto Ganadería Climáticamente Inteligente-- NAMA de FAO, cálculos realizados por el equipo INGEI Agricultura, el factor de conversión Ym es tomado de los recomendados por el IPCC | E43: El cálculo del factor de emisión propio utiliza las variables del proyecto GCI levantadas en un muestreo de fincas representivo a nivel nacional | G43: .
B44: No Lechero Toros | C44: Datos de Actividad | D44: ESPAC 2018, tabla 50 | E44: Corresponde al número de toros de 2 o más años de edad | G44: .
...

Sheet 3B Manejo de Estiércol CH4
B2: EMISIONES POR FERMENTACIÓN ENTÉRICA Y GESTIÓN DE ESTIÉRCOL
U3: INDICE
B4: Sector | C4: Agricultura
B5: Categoria | C5: Emisiones de Metano por Gestión de Estiércol
B6: Código de Categoría | C6: 3A2
B7: Hoja | C7: 1 de 1
B8: Ecuación | E8: Ecuación 10.22A | H8: Ecuación 10.22
B9: Categoria de Ganado | D9: Número de Animales | E9: Excresión anual por cabeza VS ratio | F9: Masa tipica del animal por categoría | G9: Excresión anual por cabeza VS | H9: Fracción del total anual de manejo de estiercol por tipo de sistema y tipo de ganado; ANIMAL WASTE MANAGEMENT SYSTEM (AWMS) | N9: Factor de Emisión de Metano por tipo de sistema de manejo y tipo de ganado (FE) | T9: CH4 Emisiones por Gestión del Estiércol
D10: (cabezas) | E10: (kg cabeza-1 año-1) (KG VS (1000 KG ANIMAL MASS) -1 DAY -1 ) | F10: Kg | G10: (kg cabeza-1 año-1) | H10: Sistema manejo estiércol: Almacenaje de sólidos | I10: Sistema manejo estiércol: Compostaje | J10: Sistema manejo estiércol: Distribución diaria en pasturas | K10: Sistema manejo estiércol: Líquido/fango | L10: Otros Sistemas de Manejo | M10: Sistema manejo estiércol: Pasturas, sin manejo | N10: Sistema manejo estiércol: Almacenaje de sólidos | O10: Sistema manejo estiércol: Compostaje | P10: Sistema manejo estiércol: Distribución diaria en pasturas | Q10: Sistema manejo estiércol: Líquido/fango | R10: Otros | S10: Sistema manejo estiércol: Pasturas, sin manejo | T10: (Kg CH4 año-1)
E11: Tabla 10.13 | F11: Tabla 10A.5 | H11: Tablas 10A.6 a 10A.9 | N11: Tabla 10.14 - 10.15 | T11: CH4 Estiércol = (N(T) *Vs*AWMS* EF(T))/(10^3)
B12: T | D12: N (T) | E12: VS(T,p) ratio | F12: TAM(T,p) | G12: VS(T,p) | H12: % | I12: % | J12: % | K12: % | L12: % | M12: % | N12: EF(T) | O12: EF(T) | P12: EF(T) | Q12: EF(T) | R12: EF(T) | S12: EF(T) | T12: CH4 Manure
B13: Ganado Lechero | C13: Sierra | D13: ='3A1 Fermentación E.'!D13 -> 522643.97 | E13: 7.9 | F13: 419.01067 | G13: =(E13*(F13/1000))*365 -> 1208.2173 | H13: 0.63456633 | I13: 7.8409864 | J13: 12.651786 | K13: 0.025510204 | L13: 4.4451531 | M13: 74.401998 | N13: 1.7 | O13: 1.7 | P13: 0.1 | Q13: 22.6 | R13: 0.9 | S13: 0.6 | T13: =((D13*G13*H13%*N13)/(10^3))+((D13*G13*I13%*O13)/(10^3))+((D13*G13*J13%*P13)/(10^3))+((D13*G13*K13%*Q13)/(10^3))+((D13*G13*L13%*R13)/(10^3))+((D13*G13*M13%*S13)/(10^3)) -> 409771.78
C14: Costa | D14: ='3A1 Fermentación E.'!D14 -> 262262.61 | E14: 7.1 | F14: 605.43489 | G14: =(E14*(F14/1000))*365 -> 1568.9845 | H14: 0.032467532 | I14: 0.038961039 | J14: 6.2077922 | K14: 0.64935065 | L14: 0.3125 | M14: 92.758929 | N14: 4.4 | O14: 4.4 | P14: 0.9 | Q14: 63.6 | R14: 1.7 | S14: 0.6 | T14: =((D14*G14*H14%*N14)/(10^3))+((D14*G14*I14%*O14)/(10^3))+((D14*G14*J14%*P14)/(10^3))+((D14*G14*K14%*Q14)/(10^3))+((D14*G14*L14%*R14)/(10^3))+((D14*G14*M14%*S14)/(10^3)) -> 425421.38
C15: Amazonia | D15: ='3A1 Fermentación E.'!D15 -> 47621.019 | E15: 8.6 | F15: 425.22942 | G15: =(E15*(F15/1000))*365 -> 1334.7951 | H15: 0.096153846 | I15: 0.038461538 | J15: 0 | K15: 0 | L15: 0 | M15: 99.865385 | N15: 4.4 | O15: 4.4 | P15: 0.9 | Q15: 66.2 | R15: 1.7 | S15: 0.6 | T15: =((D15*G15*H15%*N15)/(10^3))+((D15*G15*I15%*O15)/(10^3))+((D15*G15*J15%*P15)/(10^3))+((D15*G15*K15%*Q15)/(10^3))+((D15*G15*L15%*R15)/(10^3))+((D15*G15*M15%*S15)/(10^3)) -> 38463.739
B16: No LecheroToros | C16: Sierra | D16: ='3A1 Fermentación E.'!D16 -> 153765.65 | E16: 7.9 | F16: 513.2818 | G16: =(E16*(F16/1000))*365 -> 1480.0481 | H16: 0 | I16: 4.8148148 | J16: 0.12222222 | K16: 0 | L16: 0 | M16: 95.062963 | N16: 1.7 | O16: 1.7 | P16: 0.1 | Q16: 22.6 | R16: 0.9 | S16: 0.6 | T16: =((D16*G16*H16%*N16)/(10^3))+((D16*G16*I16%*O16)/(10^3))+((D16*G16*J16%*P16)/(10^3))+((D16*G16*K16%*Q16)/(10^3))+((D16*G16*L16%*R16)/(10^3))+((D16*G16*M16%*S16)/(10^3)) -> 148462.6
C17: Costa | D17: ='3A1 Fermentación E.'!D17 -> 73566.158 | E17: 7.1 | F17: 535.61652 | G17: =(E17*(F17/1000))*365 -> 1388.0502 | H17: 0 | I17: 0.035714286 | J17: 0.57142857 | K17: 8.3333333 | L17: 0 | M17: 91.059524 | N17: 4.4 | O17: 4.4 | P17: 0.9 | Q17: 66.2 | R17: 1.7 | S17: 0.6 | T17: =((D17*G17*H17%*N17)/(10^3))+((D17*G17*I17%*O17)/(10^3))+((D17*G17*J17%*P17)/(10^3))+((D17*G17*K17%*Q17)/(10^3))+((D17*G17*L17%*R17)/(10^3))+((D17*G17*M17%*S17)/(10^3)) -> 619802.33
C18: Amazonia | D18: ='3A1 Fermentación E.'!D18 -> 28493.155 | E18: 8.6 | F18: 460.03682 | G18: =(E18*(F18/1000))*365 -> 1444.0556 | H18: 0 | I18: 0 | J18: 2.173913 | K18: 0 | L18: 0 | M18: 97.826087 | N18: 4.4 | O18: 4.4 | P18: 0.9 | Q18: 66.2 | R18: 1.7 | S18: 0.6 | T18: =((D18*G18*H18%*N18)/(10^3))+((D18*G18*I18%*O18)/(10^3))+((D18*G18*J18%*P18)/(10^3))+((D18*G18*K18%*Q18)/(10^3))+((D18*G18*L18%*R18)/(10^3))+((D18*G18*M18%*S18)/(10^3)) -> 24955.761
B19: No Lechero Vacas | C19: Sierra | D19: ='3A1 Fermentación E.'!D19 -> 250720.67 | E19: 7.9 | F19: 375.7196 | G19: =(E19*(F19/1000))*365 -> 1083.3875 | H19: 0 | I19: 4.8148148 | J19: 0.12222222 | K19: 0 | L19: 0 | M19: 95.062963 | N19: 1.7 | O19: 1.7 | P19: 0.1 | Q19: 22.6 | R19: 0.9 | S19: 0.6 | T19: =((D19*G19*H19%*N19)/(10^3))+((D19*G19*I19%*O19)/(10^3))+((D19*G19*J19%*P19)/(10^3))+((D19*G19*K19%*Q19)/(10^3))+((D19*G19*L19%*R19)/(10^3))+((D19*G19*M19%*S19)/(10^3)) -> 177196.79
C20: Costa | D20: ='3A1 Fermentación E.'!D20 -> 401964.14 | E20: 7.1 | F20: 430.60864 | G20: =(E20*(F20/1000))*365 -> 1115.9223 | H20: 0 | I20: 0.035714286 | J20: 0.57142857 | K20: 8.3333333 | L20: 0 | M20: 91.059524 | N20: 4.4 | O20: 4.4 | P20: 0.9 | Q20: 66.2 | R20: 1.7 | S20: 0.6 | T20: =((D20*G20*H20%*N20)/(10^3))+((D20*G20*I20%*O20)/(10^3))+((D20*G20*J20%*P20)/(10^3))+((D20*G20*K20%*Q20)/(10^3))+((D20*G20*L20%*R20)/(10^3))+((D20*G20*M20%*S20)/(10^3)) -> 2722646.2
C21: Amazonia | D21: ='3A1 Fermentación E.'!D21 -> 74474.301 | E21: 8.6 | F21: 427.92286 | G21: =(E21*(F21/1000))*365 -> 1343.2499 | H21: 0 | I21: 0 | J21: 2.173913 | K21: 0 | L21: 0 | M21: 97.826087 | N21: 4.4 | O21: 4.4 | P21: 0.9 | Q21: 66.2 | R21: 1.7 | S21: 0.6 | T21: =((D21*G21*H21%*N21)/(10^3))+((D21*G21*I21%*O21)/(10^3))+((D21*G21*J21%*P21)/(10^3))+((D21*G21*K21%*Q21)/(10^3))+((D21*G21*L21%*R21)/(10^3))+((D21*G21*M21%*S21)/(10^3)) -> 60674.975
B22: No Lechero En crecimiento | C22: Sierra | D22: ='3A1 Fermentación E.'!D22 -> 1036600.5 | E22: 7.9 | F22: 165.49943 | G22: =(E22*(F22/1000))*365 -> 477.21761 | H22: 0 | I22: 4.8148148 | J22: 0.12222222 | K22: 0 | L22: 0 | M22: 95.062963 | N22: 1.7 | O22: 1.7 | P22: 0.1 | Q22: 22.6 | R22: 0.9 | S22: 0.6 | T22: =((D22*G22*H22%*N22)/(10^3))+((D22*G22*I22%*O22)/(10^3))+((D22*G22*J22%*P22)/(10^3))+((D22*G22*K22%*Q22)/(10^3))+((D22*G22*L22%*R22)/(10^3))+((D22*G22*M22%*S22)/(10^3)) -> 322708.02
C23: Costa | D23: ='3A1 Fermentación E.'!D23 -> 984149.28 | E23: 7.1 | F23: 174.42759 | G23: =(E23*(F23/1000))*365 -> 452.0291 | H23: 0 | I23: 0.035714286 | J23: 0.57142857 | K23: 8.3333333 | L23: 0 | M23: 91.059524 | N23: 4.4 | O23: 4.4 | P23: 0.9 | Q23: 66.2 | R23: 1.7 | S23: 0.6 | T23: =((D23*G23*H23%*N23)/(10^3))+((D23*G23*I23%*O23)/(10^3))+((D23*G23*J23%*P23)/(10^3))+((D23*G23*K23%*Q23)/(10^3))+((D23*G23*L23%*R23)/(10^3))+((D23*G23*M23%*S23)/(10^3)) -> 2700208.6
C24: Amazonia | D24: ='3A1 Fermentación E.'!D24 -> 220534.27 | E24: 8.6 | F24: 174.58749 | G24: =(E24*(F24/1000))*365 -> 548.03012 | H24: 0 | I24: 0 | J24: 2.173913 | K24: 0 | L24: 0 | M24: 97.826087 | N24: 4.4 | O24: 4.4 | P24: 0.9 | Q24: 66.2 | R24: 1.7 | S24: 0.6 | T24: =((D24*G24*H24%*N24)/(10^3))+((D24*G24*I24%*O24)/(10^3))+((D24*G24*J24%*P24)/(10^3))+((D24*G24*K24%*Q24)/(10^3))+((D24*G24*L24%*R24)/(10^3))+((D24*G24*M24%*S24)/(10^3)) -> 73303.868
B25: Búfalos | D25: ='3A1 Fermentación E.'!D25 -> 3839 | E25: 11.2 | F25: 315 | G25: =(E25*(F25/1000))*365 -> 1287.72 | H25: 2 | I25: 0 | J25: 0 | K25: 0 | L25: 5 | M25: 93 | N25: 4.4 | O25: 4.4 | P25: 0.9 | Q25: 66.2 | R25: 1.7 | S25: 0.6 | T25: =((D25*G25*H25%*N25)/(10^3))+((D25*G25*I25%*O25)/(10^3))+((D25*G25*J25%*P25)/(10^3))+((D25*G25*K25%*Q25)/(10^3))+((D25*G25*L25%*R25)/(10^3))+((D25*G25*M25%*S25)/(10^3)) -> 3613.7402
B26: Ovejas | D26: ='3A1 Fermentación E.'!D26 -> 498952.01 | E26: 8.3 | F26: 31 | G26: =(E26*(F26/1000))*365 -> 93.9145 | H26: 17 | I26: 3 | J26: 0 | K26: 0 | L26: 0 | M26: 80 | N26: 1.7 | O26: 1.7 | P26: 1.7 | Q26: 1.7 | R26: 0.9 | S26: 0.6 | T26: =((D26*G26*H26%*N26)/(10^3))+((D26*G26*I26%*O26)/(10^3))+((D26*G26*J26%*P26)/(10^3))+((D26*G26*K26%*Q26)/(10^3))+((D26*G26*L26%*R26)/(10^3))+((D26*G26*M26%*S26)/(10^3)) -> 38424.24
B27: Cabras | D27: ='3A1 Fermentación E.'!D27 -> 21745.307 | E27: 10.4 | F27: 24 | G27: =(E27*(F27/1000))*365 -> 91.104 | H27: 17 | I27: 3 | J27: 0 | K27: 0 | L27: 0 | M27: 80 | N27: 1.7 | O27: 1.7 | P27: 1.7 | Q27: 1.7 | R27: 0.9 | S27: 0.6 | T27: =((D27*G27*H27%*N27)/(10^3))+((D27*G27*I27%*O27)/(10^3))+((D27*G27*J27%*P27)/(10^3))+((D27*G27*K27%*Q27)/(10^3))+((D27*G27*L27%*R27)/(10^3))+((D27*G27*M27%*S27)/(10^3)) -> 1624.4892
B28: Camélidos sudamericanos | D28: ='3A1 Fermentación E.'!D28 -> 20949.783 | E28: 8.3 | F28: 65 | G28: =(E28*(F28/1000))*365 -> 196.9175 | H28: 17 | I28: 3 | J28: 0 | K28: 0 | L28: 0 | M28: 80 | N28: 1.7 | O28: 1.7 | P28: 1.7 | Q28: 1.7 | R28: 0.9 | S28: 0.6 | T28: =((D28*G28*H28%*N28)/(10^3))+((D28*G28*I28%*O28)/(10^3))+((D28*G28*J28%*P28)/(10^3))+((D28*G28*K28%*Q28)/(10^3))+((D28*G28*L28%*R28)/(10^3))+((D28*G28*M28%*S28)/(10^3)) -> 3382.8107
B29: Caballos | D29: ='3A1 Fermentación E.'!D29 -> 260479.02 | E29: 7.2 | F29: 238 | G29: =(E29*(F29/1000))*365 -> 625.464 | H29: 17 | I29: 3 | J29: 0 | K29: 0 | L29: 0 | M29: 80 | N29: 7 | O29: 7 | P29: 7 | Q29: 7 | R29: 2.6 | S29: 0.6 | T29: =((D29*G29*H29%*N29)/(10^3))+((D29*G29*I29%*O29)/(10^3))+((D29*G29*J29%*P29)/(10^3))+((D29*G29*K29%*Q29)/(10^3))+((D29*G29*L29%*R29)/(10^3))+((D29*G29*M29%*S29)/(10^3)) -> 306290.07
B30: Mulas & Asnos | D30: ='3A1 Fermentación E.'!D30 -> 147168.66 | E30: 7.2 | F30: 130 | G30: =(E30*(F30/1000))*365 -> 341.64 | H30: 17 | I30: 3 | J30: 0 | K30: 0 | L30: 0 | M30: 80 | N30: 7 | O30: 7 | P30: 7 | Q30: 7 | R30: 2.6 | S30: 0.6 | T30: =((D30*G30*H30%*N30)/(10^3))+((D30*G30*I30%*O30)/(10^3))+((D30*G30*J30%*P30)/(10^3))+((D30*G30*K30%*Q30)/(10^3))+((D30*G30*L30%*R30)/(10^3))+((D30*G30*M30%*S30)/(10^3)) -> 94523.961
B31: Cerdos | D31: ='3A1 Fermentación E.'!D31 -> 1682662 | E31: 8.3 | F31: 59 | G31: =(E31*(F31/1000))*365 -> 178.7405 | H31: 15 | I31: 5 | J31: 5 | K31: 30 | L31: 40 | M31: 5 | N31: 7.8 | O31: 7.8 | P31: 1 | Q31: 71.9 | R31: 1 | S31: 0.6 | T31: =((D31*G31*H31%*N31)/(10^3))+((D31*G31*I31%*O31)/(10^3))+((D31*G31*J31%*P31)/(10^3))+((D31*G31*K31%*Q31)/(10^3))+((D31*G31*L31%*R31)/(10^3))+((D31*G31*M31%*S31)/(10^3)) -> 7100940.2
B32: Aves de engorde | D32: ='3A1 Fermentación E.'!D32 -> 30205479 | E32: 15.6 | F32: 0.9 | G32: =(E32*(F32/1000))*365 -> 5.1246 | H32: 0 | I32: 0 | J32: 0 | K32: 0 | L32: 100 | M32: 0 | N32: 2.4 | O32: 2.4 | P32: 2.4 | Q32: 2.4 | R32: 2.4 | S32: 0.6 | T32: =((D32*G32*H32%*N32)/(10^3))+((D32*G32*I32%*O32)/(10^3))+((D32*G32*J32%*P32)/(10^3))+((D32*G32*K32%*Q32)/(10^3))+((D32*G32*L32%*R32)/(10^3))+((D32*G32*M32%*S32)/(10^3)) -> 371498.4
B33: Ponedoras | D33: ='3A1 Fermentación E.'!D33 -> 13510000 | E33: 10.1 | F33: 1.4 | G33: =(E33*(F33/1000))*365 -> 5.1611 | H33: 42 | I33: 0 | J33: 0 | K33: 58 | L33: 0 | M33: 0 | N33: 2.4 | O33: 2.4 | P33: 2.4 | Q33: 2.4 | R33: 2.4 | S33: 0.6 | T33: =((D33*G33*H33%*N33)/(10^3))+((D33*G33*I33%*O33)/(10^3))+((D33*G33*J33%*P33)/(10^3))+((D33*G33*K33%*Q33)/(10^3))+((D33*G33*L33%*R33)/(10^3))+((D33*G33*M33%*S33)/(10^3)) -> 167343.51
B34: Patos | D34: ='3A1 Fermentación E.'!D34 -> 70291.656 | E34: 7.4 | F34: 2.7 | G34: =(E34*(F34/1000))*365 -> 7.2927 | H34: 0 | I34: 0 | J34: 0 | K34: 0 | L34: 100 | M34: 0 | N34: 2.4 | O34: 2.4 | P34: 2.4 | Q34: 2.4 | R34: 2.4 | S34: 0.6 | T34: =((D34*G34*H34%*N34)/(10^3))+((D34*G34*I34%*O34)/(10^3))+((D34*G34*J34%*P34)/(10^3))+((D34*G34*K34%*Q34)/(10^3))+((D34*G34*L34%*R34)/(10^3))+((D34*G34*M34%*S34)/(10^3)) -> 1230.2783
B35: Pavos | D35: ='3A1 Fermentación E.'!D35 -> 198716.81 | E35: 10.3 | F35: 6.8 | G35: =(E35*(F35/1000))*365 -> 25.5646 | H35: 0 | I35: 0 | J35: 0 | K35: 0 | L35: 100 | M35: 0 | N35: 2.4 | O35: 2.4 | P35: 2.4 | Q35: 2.4 | R35: 2.4 | S35: 0.6 | T35: =((D35*G35*H35%*N35)/(10^3))+((D35*G35*I35%*O35)/(10^3))+((D35*G35*J35%*P35)/(10^3))+((D35*G35*K35%*Q35)/(10^3))+((D35*G35*L35%*R35)/(10^3))+((D35*G35*M35%*S35)/(10^3)) -> 12192.278
B36: Total | T36: =SUM(T13:T35) -> 15824680
B39: NOTA EXPLICATIVA DE FUENTES Y OTRAS CONSIDERACIONES DE LOS DATOS
B40: TIPO DE GANADO | D40: DATO DE ACTIVIDAD | E40: Observaciones | F40: VS ratio | G40: TAM | H40: Fracción AWMS | I40: FACTOR DE EMISIÓN
B41: Ganado Lechero | D41: ESPAC 2018 , tabla 67 | E41: Dato de actividad desagregado por región, dato de existencias población adulta de mas de dos años | F41: Se obtiene por defecto de la tabla 10.13 directrices IPCC V4, para ganado de la sierra se considera productividad media, en tanto para las otras regiones se considera productividad baja | G41: Dato propio del país según registros de proyecto GCI por región | H41: Valor propio del país según registros proyecto GCI por región, se promedian modos de producción | I41: Factor de emisión por defecto tablas 10.14 y 10.15 directrices IPCC V4, en algunos casos se asemejan factores según similitud de sistemas de manejo y tipo de clima por región | J41: .
B42: No LecheroToros | D42: ESPAC 2018, tabla 50 | E42: Corresponde al número de toros de 2 o más años de edad | F42: Se obtiene por defecto de la tabla 10.13 directrices IPCC V4, para ganado de la sierra se considera productividad media, en tanto para las otras regiones se considera productividad baja | G42: Dato propio del país según registros de proyecto GCI por región | H42: Valor propio del país según registros proyecto GCI por región, se promedian modos de producción | I42: Factor de emisión por defecto tablas 10.14 y 10.15 directrices IPCC V4, en algunos casos se asemejan factores según similitud de sistemas de manejo y tipo de clima por región | J42: .
B43: No Lechero Vacas | D43: ESPAC 2018, tabla 50 | E43: Corresponde al número de vacas de 2 o más años de edad menos el número de vacas ordeñadas | F43: Se obtiene por defecto de la tabla 10.13 directrices IPCC V4, para ganado de la sierra se considera productividad media, en tanto para las otras regiones se considera productividad baja | G43: Dato propio del país según registros de proyecto GCI por región | H43: Valor propio del país según registros proyecto GCI por región, se promedian modos de producción | I43: Factor de emisión por defecto tablas 10.14 y 10.15 directrices IPCC V4, en algunos casos se asemejan factores según similitud de sistemas de manejo y tipo de clima por región | J43: .
...

Sheet 3B Gestión Estiércol N2O Dir
B2: GESTIÓN DE ESTIÉRCOL : EMISIONES DIRECTAS DE N2O
B4: Sector | F4: Agricultura
B5: Categoría | F5: Gestión de Estiércol: Emisiones Directas de N2O del Gestión de Estiércol
B6: Código de Categoría | F6: 3A2
B7: Hoja | F7: 1 of 1 | W7: suelos agricolas
B8: Ecuación | E8: Eq. 10.25 | F8: Ecuación 10.30 | I8: Ecuación 10.25 | W8: Ecuación 11.15
B9: Sistema de Gestión de Estiércol (MMS)1 (se desagrega a continuación de manera horizontal) | E9: Número de animales | F9: Ratio de excreción de N (default) | G9: Masa tipica del animal por categoría | H9: Excreción anual de N por cabeza de especie / categoría ganadera3 | I9: Fracción del total anual de manejo de estiercol por tipo de sistema y tipo de ganado; ANIMAL WASTE MANAGEMENT SYSTEM (AWMS) | O9: Factor de emisión para emisiones directas de N2O-N por MMS | U9: Emisiones anuales directas de N2O | W9: N EN LA ORINA Y EL ESTIÉRICO DEPOSITADOS POR LOS ANIMALES QUE PASTAN | Z9: N excretado por sistema | AG9: emisiones por sistema
C10: Categoria de Ganado | E10: (Cabezas) | F10: [kg N | G10: (kg) | H10: (kg N animal-1 | I10: (-) | U10: kg N2O yr-1 | W10: kg N2O yr-1 | Z10: (-) | AG10: (-)
F11: (1000 kg animal)-1 día-1] | H11: año-1) | I11: ='3B Manejo de Estiércol CH4'!H10 -> Sistema manejo estiércol: Almacenaje de sólidos | J11: ='3B Manejo de Estiércol CH4'!I10 -> Sistema manejo estiércol: Compostaje | K11: ='3B Manejo de Estiércol CH4'!J10 -> Sistema manejo estiércol: Distribución diaria en pasturas | L11: ='3B Manejo de Estiércol CH4'!K10 -> Sistema manejo estiércol: Líquido/fango | M11: ='3B Manejo de Estiércol CH4'!L10 -> Otros Sistemas de Manejo | N11: ='3B Manejo de Estiércol CH4'!M10 -> Sistema manejo estiércol: Pasturas, sin manejo | O11: =I11 -> Sistema manejo estiércol: Almacenaje de sólidos | P11: =J11 -> Sistema manejo estiércol: Compostaje | Q11: =K11 -> Sistema manejo estiércol: Distribución diaria en pasturas | R11: =L11 -> Sistema manejo estiércol: Líquido/fango | S11: =M11 -> Otros Sistemas de Manejo | T11: =N11 -> Sistema manejo estiércol: Pasturas, sin manejo | U11: Emisiones anuales directas de N2O por Gestión de estiércol | W11: Cantidad anual de N en orina y estiércol depositado en pastos, pastizales y potreros por pastoreo. animales, kg N año | Z11: Sistema manejo estiércol: Almacenaje de sólidos | AA11: Sistema manejo estiércol: Compostaje | AB11: Sistema manejo estiércol: Distribución diaria en pasturas | AC11: Sistema manejo estiércol: Líquido/fango | AD11: Otros Sistemas de Manejo | AE11: Sistema manejo estiércol: Pasturas, sin manejo | AG11: Sistema manejo estiércol: Almacenaje de sólidos | AH11: Sistema manejo estiércol: Compostaje | AI11: Sistema manejo estiércol: Distribución diaria en pasturas | AJ11: Sistema manejo estiércol: Líquido/fango | AK11: Otros Sistemas de Manejo | AL11: Sistema manejo estiércol: Pasturas, sin manejo
F12: Tabla 10.19 | G12: Tablas 10A-4 to 10A-9 | H12: Nex(T) = Nrate(T) * TAM * 10-3 * 365 | I12: Tablas 10A.6 a 10A.9 | U12: N2O(mm) = | Z12: Tablas 10A.6 a 10A.9 | AG12: Tablas 10A.6 a 10A.9
O13: Tabla 10.21 | U13: NEMMS * EF3(S) * 44/28
B14: S | C14: T | E14: N(T) | F14: Nrate(T) | G14: TAM | H14: Nex(T) | I14: AWMS (%) | O14: EF3(S) | U14: N2OD(mm) | W14: Fprp | Z14: KG | AG14: KG
C15: Ganado Lechero | D15: Sierra | E15: ='3A1 Fermentación E.'!D13 -> 522643.97 | F15: 0.39 | G15: ='3B Manejo de Estiércol CH4'!F13 -> 419.01067 | H15: =F15*G15*(10^-3)*365 -> 59.646169 | I15: ='3B Manejo de Estiércol CH4'!H13 -> 0.63456633 | J15: ='3B Manejo de Estiércol CH4'!I13 -> 7.8409864 | K15: ='3B Manejo de Estiércol CH4'!J13 -> 12.651786 | L15: ='3B Manejo de Estiércol CH4'!K13 -> 0.025510204 | M15: ='3B Manejo de Estiércol CH4'!L13 -> 4.4451531 | N15: ='3B Manejo de Estiércol CH4'!M13 -> 74.401998 | O15: 0.01 | P15: 0.01 | Q15: 0 | R15: 0 | S15: 0.02 | T15: 0 | U15: =(E15*H15*J15%*P15*(44/28))+(E15*H15*I15%*O15*(44/28))+(E15*H15*K15%*Q15*(44/28))+(E15*H15*L15%*R15*(44/28))+(E15*H15*M15%*S15*(44/28))+(E15*H15*N15%*T15*(44/28)) -> 85070.583 | W15: =E15*H15*N15% -> 23193864 | Z15: =$E15*$H15*I15% -> 197817.87 | AA15: =$E15*$H15*J15% -> 2444326.4 | AB15: =$E15*$H15*K15% -> 3944031.1 | AC15: =$E15*$H15*L15% -> 7952.4772 | AD15: =$E15*$H15*M15% -> 1385719.2 | AE15: =$E15*$H15*N15% -> 23193864 | AG15: =$E15*$H15*I15%*O15*(44/28) -> 3108.5665 | AH15: =$E15*$H15*J15%*P15*(44/28) -> 38410.844 | AI15: =$E15*$H15*K15%*Q15*(44/28) -> 0 | AJ15: =$E15*$H15*L15%*R15*(44/28) -> 0 | AK15: =$E15*$H15*M15%*S15*(44/28) -> 43551.173 | AL15: =$E15*$H15*N15%*T15*(44/28) -> 0
D16: Costa | E16: ='3A1 Fermentación E.'!D14 -> 262262.61 | F16: 0.39 | G16: ='3B Manejo de Estiércol CH4'!F14 -> 605.43489 | H16: =F16*G16*(10^-3)*365 -> 86.183656 | I16: ='3B Manejo de Estiércol CH4'!H14 -> 0.032467532 | J16: ='3B Manejo de Estiércol CH4'!I14 -> 0.038961039 | K16: ='3B Manejo de Estiércol CH4'!J14 -> 6.2077922 | L16: ='3B Manejo de Estiércol CH4'!K14 -> 0.64935065 | M16: ='3B Manejo de Estiércol CH4'!L14 -> 0.3125 | N16: ='3B Manejo de Estiércol CH4'!M14 -> 92.758929 | O16: 0.01 | P16: 0.01 | Q16: 0 | R16: 0 | S16: 0.02 | T16: 0 | U16: =(E16*H16*J16%*P16*(44/28))+(E16*H16*I16%*O16*(44/28))+(E16*H16*K16%*Q16*(44/28))+(E16*H16*L16%*R16*(44/28))+(E16*H16*M16%*S16*(44/28))+(E16*H16*N16%*T16*(44/28)) -> 2473.6173 | W16: =E16*H16*N16% -> 20966069 | Z16: =$E16*$H16*I16% -> 7338.5553 | AA16: =$E16*$H16*J16% -> 8806.2664 | AB16: =$E16*$H16*K16% -> 1403131.8 | AC16: =$E16*$H16*L16% -> 146771.11 | AD16: =$E16*$H16*M16% -> 70633.595 | AE16: =$E16*$H16*N16% -> 20966069 | AG16: =$E16*$H16*I16%*O16*(44/28) -> 115.32016 | AH16: =$E16*$H16*J16%*P16*(44/28) -> 138.38419 | AI16: =$E16*$H16*K16%*Q16*(44/28) -> 0 | AJ16: =$E16*$H16*L16%*R16*(44/28) -> 0 | AK16: =$E16*$H16*M16%*S16*(44/28) -> 2219.913 | AL16: =$E16*$H16*N16%*T16*(44/28) -> 0
D17: Amazonia | E17: ='3A1 Fermentación E.'!D15 -> 47621.019 | F17: 0.39 | G17: ='3B Manejo de Estiércol CH4'!F15 -> 425.22942 | H17: =F17*G17*(10^-3)*365 -> 60.531408 | I17: ='3B Manejo de Estiércol CH4'!H15 -> 0.096153846 | J17: ='3B Manejo de Estiércol CH4'!I15 -> 0.038461538 | K17: ='3B Manejo de Estiércol CH4'!J15 -> 0 | L17: ='3B Manejo de Estiércol CH4'!K15 -> 0 | M17: ='3B Manejo de Estiércol CH4'!L15 -> 0 | N17: ='3B Manejo de Estiércol CH4'!M15 -> 99.865385 | O17: 0.01 | P17: 0.01 | Q17: 0 | R17: 0 | S17: 0.02 | T17: 0 | U17: =(E17*H17*J17%*P17*(44/28))+(E17*H17*I17%*O17*(44/28))+(E17*H17*K17%*Q17*(44/28))+(E17*H17*L17%*R17*(44/28))+(E17*H17*M17%*S17*(44/28))+(E17*H17*N17%*T17*(44/28)) -> 60.977385 | W17: =E17*H17*N17% -> 2878686.9 | Z17: =$E17*$H17*I17% -> 2771.6993 | AA17: =$E17*$H17*J17% -> 1108.6797 | AB17: =$E17*$H17*K17% -> 0 | AC17: =$E17*$H17*L17% -> 0 | AD17: =$E17*$H17*M17% -> 0 | AE17: =$E17*$H17*N17% -> 2878686.9 | AG17: =$E17*$H17*I17%*O17*(44/28) -> 43.555275 | AH17: =$E17*$H17*J17%*P17*(44/28) -> 17.42211 | AI17: =$E17*$H17*K17%*Q17*(44/28) -> 0 | AJ17: =$E17*$H17*L17%*R17*(44/28) -> 0 | AK17: =$E17*$H17*M17%*S17*(44/28) -> 0 | AL17: =$E17*$H17*N17%*T17*(44/28) -> 0
C18: No LecheroToros | D18: Sierra | E18: ='3A1 Fermentación E.'!D16 -> 153765.65 | F18: 0.29 | G18: ='3B Manejo de Estiércol CH4'!F16 -> 513.2818 | H18: =F18*G18*(10^-3)*365 -> 54.330878 | I18: ='3B Manejo de Estiércol CH4'!H16 -> 0 | J18: ='3B Manejo de Estiércol CH4'!I16 -> 4.8148148 | K18: ='3B Manejo de Estiércol CH4'!J16 -> 0.12222222 | L18: ='3B Manejo de Estiércol CH4'!K16 -> 0 | M18: ='3B Manejo de Estiércol CH4'!L16 -> 0 | N18: ='3B Manejo de Estiércol CH4'!M16 -> 95.062963 | O18: 0.01 | P18: 0.01 | Q18: 0 | R18: 0 | S18: 0.02 | T18: 0 | U18: =(E18*H18*J18%*P18*(44/28))+(E18*H18*I18%*O18*(44/28))+(E18*H18*K18%*Q18*(44/28))+(E18*H18*L18%*R18*(44/28))+(E18*H18*M18%*S18*(44/28))+(E18*H18*N18%*T18*(44/28)) -> 6320.9199 | W18: =E18*H18*N18% -> 7941771.8 | Z18: =$E18*$H18*I18% -> 0 | AA18: =$E18*$H18*J18% -> 402240.36 | AB18: =$E18*$H18*K18% -> 10210.717 | AC18: =$E18*$H18*L18% -> 0 | AD18: =$E18*$H18*M18% -> 0 | AE18: =$E18*$H18*N18% -> 7941771.8 | AG18: =$E18*$H18*I18%*O18*(44/28) -> 0 | AH18: =$E18*$H18*J18%*P18*(44/28) -> 6320.9199 | AI18: =$E18*$H18*K18%*Q18*(44/28) -> 0 | AJ18: =$E18*$H18*L18%*R18*(44/28) -> 0 | AK18: =$E18*$H18*M18%*S18*(44/28) -> 0 | AL18: =$E18*$H18*N18%*T18*(44/28) -> 0
D19: Costa | E19: ='3A1 Fermentación E.'!D17 -> 73566.158 | F19: 0.29 | G19: ='3B Manejo de Estiércol CH4'!F17 -> 535.61652 | H19: =F19*G19*(10^-3)*365 -> 56.695009 | I19: ='3B Manejo de Estiércol CH4'!H17 -> 0 | J19: ='3B Manejo de Estiércol CH4'!I17 -> 0.035714286 | K19: ='3B Manejo de Estiércol CH4'!J17 -> 0.57142857 | L19: ='3B Manejo de Estiércol CH4'!K17 -> 8.3333333 | M19: ='3B Manejo de Estiércol CH4'!L17 -> 0 | N19: ='3B Manejo de Estiércol CH4'!M17 -> 91.059524 | O19: 0.01 | P19: 0.01 | Q19: 0 | R19: 0 | S19: 0.02 | T19: 0 | U19: =(E19*H19*J19%*P19*(44/28))+(E19*H19*I19%*O19*(44/28))+(E19*H19*K19%*Q19*(44/28))+(E19*H19*L19%*R19*(44/28))+(E19*H19*M19%*S19*(44/28))+(E19*H19*N19%*T19*(44/28)) -> 23.407742 | W19: =E19*H19*N19% -> 3797941.6 | Z19: =$E19*$H19*I19% -> 0 | AA19: =$E19*$H19*J19% -> 1489.5836 | AB19: =$E19*$H19*K19% -> 23833.337 | AC19: =$E19*$H19*L19% -> 347569.5 | AD19: =$E19*$H19*M19% -> 0 | AE19: =$E19*$H19*N19% -> 3797941.6 | AG19: =$E19*$H19*I19%*O19*(44/28) -> 0 | AH19: =$E19*$H19*J19%*P19*(44/28) -> 23.407742 | AI19: =$E19*$H19*K19%*Q19*(44/28) -> 0 | AJ19: =$E19*$H19*L19%*R19*(44/28) -> 0 | AK19: =$E19*$H19*M19%*S19*(44/28) -> 0 | AL19: =$E19*$H19*N19%*T19*(44/28) -> 0
D20: Amazonia | E20: ='3A1 Fermentación E.'!D18 -> 28493.155 | F20: 0.29 | G20: ='3B Manejo de Estiércol CH4'!F18 -> 460.03682 | H20: =F20*G20*(10^-3)*365 -> 48.694897 | I20: ='3B Manejo de Estiércol CH4'!H18 -> 0 | J20: ='3B Manejo de Estiércol CH4'!I18 -> 0 | K20: ='3B Manejo de Estiércol CH4'!J18 -> 2.173913 | L20: ='3B Manejo de Estiércol CH4'!K18 -> 0 | M20: ='3B Manejo de Estiércol CH4'!L18 -> 0 | N20: ='3B Manejo de Estiércol CH4'!M18 -> 97.826087 | O20: 0.01 | P20: 0.01 | Q20: 0 | R20: 0 | S20: 0.02 | T20: 0 | U20: =(E20*H20*J20%*P20*(44/28))+(E20*H20*I20%*O20*(44/28))+(E20*H20*K20%*Q20*(44/28))+(E20*H20*L20%*R20*(44/28))+(E20*H20*M20%*S20*(44/28))+(E20*H20*N20%*T20*(44/28)) -> 0 | W20: =E20*H20*N20% -> 1357308.8 | Z20: =$E20*$H20*I20% -> 0 | AA20: =$E20*$H20*J20% -> 0 | AB20: =$E20*$H20*K20% -> 30162.419 | AC20: =$E20*$H20*L20% -> 0 | AD20: =$E20*$H20*M20% -> 0 | AE20: =$E20*$H20*N20% -> 1357308.8 | AG20: =$E20*$H20*I20%*O20*(44/28) -> 0 | AH20: =$E20*$H20*J20%*P20*(44/28) -> 0 | AI20: =$E20*$H20*K20%*Q20*(44/28) -> 0 | AJ20: =$E20*$H20*L20%*R20*(44/28) -> 0 | AK20: =$E20*$H20*M20%*S20*(44/28) -> 0 | AL20: =$E20*$H20*N20%*T20*(44/28) -> 0
C21: No Lechero Vacas | D21: Sierra | E21: ='3A1 Fermentación E.'!D19 -> 250720.67 | F21: 0.29 | G21: ='3B Manejo de Estiércol CH4'!F19 -> 375.7196 | H21: =F21*G21*(10^-3)*365 -> 39.769919 | I21: ='3B Manejo de Estiércol CH4'!H19 -> 0 | J21: ='3B Manejo de Estiércol CH4'!I19 -> 4.8148148 | K21: ='3B Manejo de Estiércol CH4'!J19 -> 0.12222222 | L21: ='3B Manejo de Estiércol CH4'!K19 -> 0 | M21: ='3B Manejo de Estiércol CH4'!L19 -> 0 | N21: ='3B Manejo de Estiércol CH4'!M19 -> 95.062963 | O21: 0.01 | P21: 0.01 | Q21: 0 | R21: 0 | S21: 0.02 | T21: 0 | U21: =(E21*H21*J21%*P21*(44/28))+(E21*H21*I21%*O21*(44/28))+(E21*H21*K21%*Q21*(44/28))+(E21*H21*L21%*R21*(44/28))+(E21*H21*M21%*S21*(44/28))+(E21*H21*N21%*T21*(44/28)) -> 7544.3023 | W21: =E21*H21*N21% -> 9478861.8 | Z21: =$E21*$H21*I21% -> 0 | AA21: =$E21*$H21*J21% -> 480091.96 | AB21: =$E21*$H21*K21% -> 12186.95 | AC21: =$E21*$H21*L21% -> 0 | AD21: =$E21*$H21*M21% -> 0 | AE21: =$E21*$H21*N21% -> 9478861.8 | AG21: =$E21*$H21*I21%*O21*(44/28) -> 0 | AH21: =$E21*$H21*J21%*P21*(44/28) -> 7544.3023 | AI21: =$E21*$H21*K21%*Q21*(44/28) -> 0 | AJ21: =$E21*$H21*L21%*R21*(44/28) -> 0 | AK21: =$E21*$H21*M21%*S21*(44/28) -> 0 | AL21: =$E21*$H21*N21%*T21*(44/28) -> 0
